2024-01-08 00:00:34,071 - app - ERROR - Exception on /api/check/user/busy [POST]
Traceback (most recent call last):
  File "/Users/virender/Desktop/DriveKraft-Backend/venv/lib/python3.11/site-packages/sqlalchemy/orm/relationships.py", line 2419, in _determine_joins
    self.primaryjoin = join_condition(
                       ^^^^^^^^^^^^^^^
  File "/Users/virender/Desktop/DriveKraft-Backend/venv/lib/python3.11/site-packages/sqlalchemy/sql/util.py", line 123, in join_condition
    return Join._join_condition(
           ^^^^^^^^^^^^^^^^^^^^^
  File "/Users/virender/Desktop/DriveKraft-Backend/venv/lib/python3.11/site-packages/sqlalchemy/sql/selectable.py", line 1358, in _join_condition
    raise exc.NoForeignKeysError(
sqlalchemy.exc.NoForeignKeysError: Can't find any foreign key relationships between 'transaction' and 'psychologist'.

The above exception was the direct cause of the following exception:

Traceback (most recent call last):
  File "/Users/virender/Desktop/DriveKraft-Backend/venv/lib/python3.11/site-packages/flask/app.py", line 1455, in wsgi_app
    response = self.full_dispatch_request()
               ^^^^^^^^^^^^^^^^^^^^^^^^^^^^
  File "/Users/virender/Desktop/DriveKraft-Backend/venv/lib/python3.11/site-packages/flask/app.py", line 869, in full_dispatch_request
    rv = self.handle_user_exception(e)
         ^^^^^^^^^^^^^^^^^^^^^^^^^^^^^
  File "/Users/virender/Desktop/DriveKraft-Backend/venv/lib/python3.11/site-packages/flask/app.py", line 867, in full_dispatch_request
    rv = self.dispatch_request()
         ^^^^^^^^^^^^^^^^^^^^^^^
  File "/Users/virender/Desktop/DriveKraft-Backend/venv/lib/python3.11/site-packages/flask/app.py", line 852, in dispatch_request
    return self.ensure_sync(self.view_functions[rule.endpoint])(**view_args)
           ^^^^^^^^^^^^^^^^^^^^^^^^^^^^^^^^^^^^^^^^^^^^^^^^^^^^^^^^^^^^^^^^^
  File "/Users/virender/Desktop/DriveKraft-Backend/app/util.py", line 18, in wrapper
    raise e
  File "/Users/virender/Desktop/DriveKraft-Backend/app/util.py", line 12, in wrapper
    result = func(*args, **kwargs)
             ^^^^^^^^^^^^^^^^^^^^^
  File "/Users/virender/Desktop/DriveKraft-Backend/app/authenticate.py", line 14, in wrapper
    if verify_token(tokenValue):
       ^^^^^^^^^^^^^^^^^^^^^^^^
  File "/Users/virender/Desktop/DriveKraft-Backend/app/authenticate.py", line 25, in verify_token
    token = getToken(tokenValue=tokenValue)
            ^^^^^^^^^^^^^^^^^^^^^^^^^^^^^^^
  File "/Users/virender/Desktop/DriveKraft-Backend/venv/lib/python3.11/site-packages/flask_caching/__init__.py", line 872, in decorated_function
    rv = self._call_fn(f, *args, **kwargs)
         ^^^^^^^^^^^^^^^^^^^^^^^^^^^^^^^^^
  File "/Users/virender/Desktop/DriveKraft-Backend/venv/lib/python3.11/site-packages/flask_caching/__init__.py", line 175, in _call_fn
    return ensure_sync(fn)(*args, **kwargs)
           ^^^^^^^^^^^^^^^^^^^^^^^^^^^^^^^^
  File "/Users/virender/Desktop/DriveKraft-Backend/app/Models/DAO/tokenDAO.py", line 27, in getToken
    token = g.session.query(Token).filter(
            ^^^^^^^^^^^^^^^^^^^^^^
  File "/Users/virender/Desktop/DriveKraft-Backend/venv/lib/python3.11/site-packages/sqlalchemy/orm/session.py", line 2912, in query
    return self._query_cls(entities, self, **kwargs)
           ^^^^^^^^^^^^^^^^^^^^^^^^^^^^^^^^^^^^^^^^^
  File "/Users/virender/Desktop/DriveKraft-Backend/venv/lib/python3.11/site-packages/sqlalchemy/orm/query.py", line 276, in __init__
    self._set_entities(entities)
  File "/Users/virender/Desktop/DriveKraft-Backend/venv/lib/python3.11/site-packages/sqlalchemy/orm/query.py", line 288, in _set_entities
    self._raw_columns = [
                        ^
  File "/Users/virender/Desktop/DriveKraft-Backend/venv/lib/python3.11/site-packages/sqlalchemy/orm/query.py", line 289, in <listcomp>
    coercions.expect(
  File "/Users/virender/Desktop/DriveKraft-Backend/venv/lib/python3.11/site-packages/sqlalchemy/sql/coercions.py", line 406, in expect
    insp._post_inspect
  File "/Users/virender/Desktop/DriveKraft-Backend/venv/lib/python3.11/site-packages/sqlalchemy/util/langhelpers.py", line 1260, in __get__
    obj.__dict__[self.__name__] = result = self.fget(obj)
                                           ^^^^^^^^^^^^^^
  File "/Users/virender/Desktop/DriveKraft-Backend/venv/lib/python3.11/site-packages/sqlalchemy/orm/mapper.py", line 2707, in _post_inspect
    self._check_configure()
  File "/Users/virender/Desktop/DriveKraft-Backend/venv/lib/python3.11/site-packages/sqlalchemy/orm/mapper.py", line 2386, in _check_configure
    _configure_registries({self.registry}, cascade=True)
  File "/Users/virender/Desktop/DriveKraft-Backend/venv/lib/python3.11/site-packages/sqlalchemy/orm/mapper.py", line 4199, in _configure_registries
    _do_configure_registries(registries, cascade)
  File "/Users/virender/Desktop/DriveKraft-Backend/venv/lib/python3.11/site-packages/sqlalchemy/orm/mapper.py", line 4240, in _do_configure_registries
    mapper._post_configure_properties()
  File "/Users/virender/Desktop/DriveKraft-Backend/venv/lib/python3.11/site-packages/sqlalchemy/orm/mapper.py", line 2403, in _post_configure_properties
    prop.init()
  File "/Users/virender/Desktop/DriveKraft-Backend/venv/lib/python3.11/site-packages/sqlalchemy/orm/interfaces.py", line 579, in init
    self.do_init()
  File "/Users/virender/Desktop/DriveKraft-Backend/venv/lib/python3.11/site-packages/sqlalchemy/orm/relationships.py", line 1637, in do_init
    self._setup_join_conditions()
  File "/Users/virender/Desktop/DriveKraft-Backend/venv/lib/python3.11/site-packages/sqlalchemy/orm/relationships.py", line 1882, in _setup_join_conditions
    self._join_condition = jc = JoinCondition(
                                ^^^^^^^^^^^^^^
  File "/Users/virender/Desktop/DriveKraft-Backend/venv/lib/python3.11/site-packages/sqlalchemy/orm/relationships.py", line 2306, in __init__
    self._determine_joins()
  File "/Users/virender/Desktop/DriveKraft-Backend/venv/lib/python3.11/site-packages/sqlalchemy/orm/relationships.py", line 2440, in _determine_joins
    raise sa_exc.NoForeignKeysError(
sqlalchemy.exc.NoForeignKeysError: Could not determine join condition between parent/child tables on relationship Transaction.psychologist - there are no foreign keys linking these tables.  Ensure that referencing columns are associated with a ForeignKey or ForeignKeyConstraint, or specify a 'primaryjoin' expression.
2024-01-08 00:10:45,335 - app - ERROR - Exception on /api/role [GET]
Traceback (most recent call last):
  File "/Users/virender/Desktop/DriveKraft-Backend/venv/lib/python3.11/site-packages/sqlalchemy/orm/relationships.py", line 2419, in _determine_joins
    self.primaryjoin = join_condition(
                       ^^^^^^^^^^^^^^^
  File "/Users/virender/Desktop/DriveKraft-Backend/venv/lib/python3.11/site-packages/sqlalchemy/sql/util.py", line 123, in join_condition
    return Join._join_condition(
           ^^^^^^^^^^^^^^^^^^^^^
  File "/Users/virender/Desktop/DriveKraft-Backend/venv/lib/python3.11/site-packages/sqlalchemy/sql/selectable.py", line 1358, in _join_condition
    raise exc.NoForeignKeysError(
sqlalchemy.exc.NoForeignKeysError: Can't find any foreign key relationships between 'transaction' and 'psychologist'.

The above exception was the direct cause of the following exception:

Traceback (most recent call last):
  File "/Users/virender/Desktop/DriveKraft-Backend/venv/lib/python3.11/site-packages/flask/app.py", line 1455, in wsgi_app
    response = self.full_dispatch_request()
               ^^^^^^^^^^^^^^^^^^^^^^^^^^^^
  File "/Users/virender/Desktop/DriveKraft-Backend/venv/lib/python3.11/site-packages/flask/app.py", line 869, in full_dispatch_request
    rv = self.handle_user_exception(e)
         ^^^^^^^^^^^^^^^^^^^^^^^^^^^^^
  File "/Users/virender/Desktop/DriveKraft-Backend/venv/lib/python3.11/site-packages/flask/app.py", line 867, in full_dispatch_request
    rv = self.dispatch_request()
         ^^^^^^^^^^^^^^^^^^^^^^^
  File "/Users/virender/Desktop/DriveKraft-Backend/venv/lib/python3.11/site-packages/flask/app.py", line 852, in dispatch_request
    return self.ensure_sync(self.view_functions[rule.endpoint])(**view_args)
           ^^^^^^^^^^^^^^^^^^^^^^^^^^^^^^^^^^^^^^^^^^^^^^^^^^^^^^^^^^^^^^^^^
  File "/Users/virender/Desktop/DriveKraft-Backend/app/util.py", line 18, in wrapper
    raise e
  File "/Users/virender/Desktop/DriveKraft-Backend/app/util.py", line 12, in wrapper
    result = func(*args, **kwargs)
             ^^^^^^^^^^^^^^^^^^^^^
  File "/Users/virender/Desktop/DriveKraft-Backend/app/authenticate.py", line 14, in wrapper
    if verify_token(tokenValue):
       ^^^^^^^^^^^^^^^^^^^^^^^^
  File "/Users/virender/Desktop/DriveKraft-Backend/app/authenticate.py", line 25, in verify_token
    token = getToken(tokenValue=tokenValue)
            ^^^^^^^^^^^^^^^^^^^^^^^^^^^^^^^
  File "/Users/virender/Desktop/DriveKraft-Backend/venv/lib/python3.11/site-packages/flask_caching/__init__.py", line 872, in decorated_function
    rv = self._call_fn(f, *args, **kwargs)
         ^^^^^^^^^^^^^^^^^^^^^^^^^^^^^^^^^
  File "/Users/virender/Desktop/DriveKraft-Backend/venv/lib/python3.11/site-packages/flask_caching/__init__.py", line 175, in _call_fn
    return ensure_sync(fn)(*args, **kwargs)
           ^^^^^^^^^^^^^^^^^^^^^^^^^^^^^^^^
  File "/Users/virender/Desktop/DriveKraft-Backend/app/Models/DAO/tokenDAO.py", line 27, in getToken
    token = g.session.query(Token).filter(
            ^^^^^^^^^^^^^^^^^^^^^^
  File "/Users/virender/Desktop/DriveKraft-Backend/venv/lib/python3.11/site-packages/sqlalchemy/orm/session.py", line 2912, in query
    return self._query_cls(entities, self, **kwargs)
           ^^^^^^^^^^^^^^^^^^^^^^^^^^^^^^^^^^^^^^^^^
  File "/Users/virender/Desktop/DriveKraft-Backend/venv/lib/python3.11/site-packages/sqlalchemy/orm/query.py", line 276, in __init__
    self._set_entities(entities)
  File "/Users/virender/Desktop/DriveKraft-Backend/venv/lib/python3.11/site-packages/sqlalchemy/orm/query.py", line 288, in _set_entities
    self._raw_columns = [
                        ^
  File "/Users/virender/Desktop/DriveKraft-Backend/venv/lib/python3.11/site-packages/sqlalchemy/orm/query.py", line 289, in <listcomp>
    coercions.expect(
  File "/Users/virender/Desktop/DriveKraft-Backend/venv/lib/python3.11/site-packages/sqlalchemy/sql/coercions.py", line 406, in expect
    insp._post_inspect
  File "/Users/virender/Desktop/DriveKraft-Backend/venv/lib/python3.11/site-packages/sqlalchemy/util/langhelpers.py", line 1260, in __get__
    obj.__dict__[self.__name__] = result = self.fget(obj)
                                           ^^^^^^^^^^^^^^
  File "/Users/virender/Desktop/DriveKraft-Backend/venv/lib/python3.11/site-packages/sqlalchemy/orm/mapper.py", line 2707, in _post_inspect
    self._check_configure()
  File "/Users/virender/Desktop/DriveKraft-Backend/venv/lib/python3.11/site-packages/sqlalchemy/orm/mapper.py", line 2386, in _check_configure
    _configure_registries({self.registry}, cascade=True)
  File "/Users/virender/Desktop/DriveKraft-Backend/venv/lib/python3.11/site-packages/sqlalchemy/orm/mapper.py", line 4199, in _configure_registries
    _do_configure_registries(registries, cascade)
  File "/Users/virender/Desktop/DriveKraft-Backend/venv/lib/python3.11/site-packages/sqlalchemy/orm/mapper.py", line 4240, in _do_configure_registries
    mapper._post_configure_properties()
  File "/Users/virender/Desktop/DriveKraft-Backend/venv/lib/python3.11/site-packages/sqlalchemy/orm/mapper.py", line 2403, in _post_configure_properties
    prop.init()
  File "/Users/virender/Desktop/DriveKraft-Backend/venv/lib/python3.11/site-packages/sqlalchemy/orm/interfaces.py", line 579, in init
    self.do_init()
  File "/Users/virender/Desktop/DriveKraft-Backend/venv/lib/python3.11/site-packages/sqlalchemy/orm/relationships.py", line 1637, in do_init
    self._setup_join_conditions()
  File "/Users/virender/Desktop/DriveKraft-Backend/venv/lib/python3.11/site-packages/sqlalchemy/orm/relationships.py", line 1882, in _setup_join_conditions
    self._join_condition = jc = JoinCondition(
                                ^^^^^^^^^^^^^^
  File "/Users/virender/Desktop/DriveKraft-Backend/venv/lib/python3.11/site-packages/sqlalchemy/orm/relationships.py", line 2306, in __init__
    self._determine_joins()
  File "/Users/virender/Desktop/DriveKraft-Backend/venv/lib/python3.11/site-packages/sqlalchemy/orm/relationships.py", line 2440, in _determine_joins
    raise sa_exc.NoForeignKeysError(
sqlalchemy.exc.NoForeignKeysError: Could not determine join condition between parent/child tables on relationship Transaction.psychologist - there are no foreign keys linking these tables.  Ensure that referencing columns are associated with a ForeignKey or ForeignKeyConstraint, or specify a 'primaryjoin' expression.
2024-01-08 00:11:51,579 - app - ERROR - Exception on /api/role [GET]
Traceback (most recent call last):
  File "/Users/virender/Desktop/DriveKraft-Backend/venv/lib/python3.11/site-packages/sqlalchemy/orm/relationships.py", line 2419, in _determine_joins
    self.primaryjoin = join_condition(
                       ^^^^^^^^^^^^^^^
  File "/Users/virender/Desktop/DriveKraft-Backend/venv/lib/python3.11/site-packages/sqlalchemy/sql/util.py", line 123, in join_condition
    return Join._join_condition(
           ^^^^^^^^^^^^^^^^^^^^^
  File "/Users/virender/Desktop/DriveKraft-Backend/venv/lib/python3.11/site-packages/sqlalchemy/sql/selectable.py", line 1358, in _join_condition
    raise exc.NoForeignKeysError(
sqlalchemy.exc.NoForeignKeysError: Can't find any foreign key relationships between 'transaction' and 'psychologist'.

The above exception was the direct cause of the following exception:

Traceback (most recent call last):
  File "/Users/virender/Desktop/DriveKraft-Backend/venv/lib/python3.11/site-packages/flask/app.py", line 1455, in wsgi_app
    response = self.full_dispatch_request()
               ^^^^^^^^^^^^^^^^^^^^^^^^^^^^
  File "/Users/virender/Desktop/DriveKraft-Backend/venv/lib/python3.11/site-packages/flask/app.py", line 869, in full_dispatch_request
    rv = self.handle_user_exception(e)
         ^^^^^^^^^^^^^^^^^^^^^^^^^^^^^
  File "/Users/virender/Desktop/DriveKraft-Backend/venv/lib/python3.11/site-packages/flask/app.py", line 867, in full_dispatch_request
    rv = self.dispatch_request()
         ^^^^^^^^^^^^^^^^^^^^^^^
  File "/Users/virender/Desktop/DriveKraft-Backend/venv/lib/python3.11/site-packages/flask/app.py", line 852, in dispatch_request
    return self.ensure_sync(self.view_functions[rule.endpoint])(**view_args)
           ^^^^^^^^^^^^^^^^^^^^^^^^^^^^^^^^^^^^^^^^^^^^^^^^^^^^^^^^^^^^^^^^^
  File "/Users/virender/Desktop/DriveKraft-Backend/app/util.py", line 18, in wrapper
    raise e
  File "/Users/virender/Desktop/DriveKraft-Backend/app/util.py", line 12, in wrapper
    result = func(*args, **kwargs)
             ^^^^^^^^^^^^^^^^^^^^^
  File "/Users/virender/Desktop/DriveKraft-Backend/app/authenticate.py", line 14, in wrapper
    if verify_token(tokenValue):
       ^^^^^^^^^^^^^^^^^^^^^^^^
  File "/Users/virender/Desktop/DriveKraft-Backend/app/authenticate.py", line 25, in verify_token
    token = getToken(tokenValue=tokenValue)
            ^^^^^^^^^^^^^^^^^^^^^^^^^^^^^^^
  File "/Users/virender/Desktop/DriveKraft-Backend/venv/lib/python3.11/site-packages/flask_caching/__init__.py", line 872, in decorated_function
    rv = self._call_fn(f, *args, **kwargs)
         ^^^^^^^^^^^^^^^^^^^^^^^^^^^^^^^^^
  File "/Users/virender/Desktop/DriveKraft-Backend/venv/lib/python3.11/site-packages/flask_caching/__init__.py", line 175, in _call_fn
    return ensure_sync(fn)(*args, **kwargs)
           ^^^^^^^^^^^^^^^^^^^^^^^^^^^^^^^^
  File "/Users/virender/Desktop/DriveKraft-Backend/app/Models/DAO/tokenDAO.py", line 27, in getToken
    token = g.session.query(Token).filter(
            ^^^^^^^^^^^^^^^^^^^^^^
  File "/Users/virender/Desktop/DriveKraft-Backend/venv/lib/python3.11/site-packages/sqlalchemy/orm/session.py", line 2912, in query
    return self._query_cls(entities, self, **kwargs)
           ^^^^^^^^^^^^^^^^^^^^^^^^^^^^^^^^^^^^^^^^^
  File "/Users/virender/Desktop/DriveKraft-Backend/venv/lib/python3.11/site-packages/sqlalchemy/orm/query.py", line 276, in __init__
    self._set_entities(entities)
  File "/Users/virender/Desktop/DriveKraft-Backend/venv/lib/python3.11/site-packages/sqlalchemy/orm/query.py", line 288, in _set_entities
    self._raw_columns = [
                        ^
  File "/Users/virender/Desktop/DriveKraft-Backend/venv/lib/python3.11/site-packages/sqlalchemy/orm/query.py", line 289, in <listcomp>
    coercions.expect(
  File "/Users/virender/Desktop/DriveKraft-Backend/venv/lib/python3.11/site-packages/sqlalchemy/sql/coercions.py", line 406, in expect
    insp._post_inspect
  File "/Users/virender/Desktop/DriveKraft-Backend/venv/lib/python3.11/site-packages/sqlalchemy/util/langhelpers.py", line 1260, in __get__
    obj.__dict__[self.__name__] = result = self.fget(obj)
                                           ^^^^^^^^^^^^^^
  File "/Users/virender/Desktop/DriveKraft-Backend/venv/lib/python3.11/site-packages/sqlalchemy/orm/mapper.py", line 2707, in _post_inspect
    self._check_configure()
  File "/Users/virender/Desktop/DriveKraft-Backend/venv/lib/python3.11/site-packages/sqlalchemy/orm/mapper.py", line 2386, in _check_configure
    _configure_registries({self.registry}, cascade=True)
  File "/Users/virender/Desktop/DriveKraft-Backend/venv/lib/python3.11/site-packages/sqlalchemy/orm/mapper.py", line 4199, in _configure_registries
    _do_configure_registries(registries, cascade)
  File "/Users/virender/Desktop/DriveKraft-Backend/venv/lib/python3.11/site-packages/sqlalchemy/orm/mapper.py", line 4240, in _do_configure_registries
    mapper._post_configure_properties()
  File "/Users/virender/Desktop/DriveKraft-Backend/venv/lib/python3.11/site-packages/sqlalchemy/orm/mapper.py", line 2403, in _post_configure_properties
    prop.init()
  File "/Users/virender/Desktop/DriveKraft-Backend/venv/lib/python3.11/site-packages/sqlalchemy/orm/interfaces.py", line 579, in init
    self.do_init()
  File "/Users/virender/Desktop/DriveKraft-Backend/venv/lib/python3.11/site-packages/sqlalchemy/orm/relationships.py", line 1637, in do_init
    self._setup_join_conditions()
  File "/Users/virender/Desktop/DriveKraft-Backend/venv/lib/python3.11/site-packages/sqlalchemy/orm/relationships.py", line 1882, in _setup_join_conditions
    self._join_condition = jc = JoinCondition(
                                ^^^^^^^^^^^^^^
  File "/Users/virender/Desktop/DriveKraft-Backend/venv/lib/python3.11/site-packages/sqlalchemy/orm/relationships.py", line 2306, in __init__
    self._determine_joins()
  File "/Users/virender/Desktop/DriveKraft-Backend/venv/lib/python3.11/site-packages/sqlalchemy/orm/relationships.py", line 2440, in _determine_joins
    raise sa_exc.NoForeignKeysError(
sqlalchemy.exc.NoForeignKeysError: Could not determine join condition between parent/child tables on relationship Transaction.psychologist - there are no foreign keys linking these tables.  Ensure that referencing columns are associated with a ForeignKey or ForeignKeyConstraint, or specify a 'primaryjoin' expression.
2024-01-08 00:12:45,043 - app - ERROR - Exception on /api/role [GET]
Traceback (most recent call last):
  File "/Users/virender/Desktop/DriveKraft-Backend/venv/lib/python3.11/site-packages/flask/app.py", line 1455, in wsgi_app
    response = self.full_dispatch_request()
               ^^^^^^^^^^^^^^^^^^^^^^^^^^^^
  File "/Users/virender/Desktop/DriveKraft-Backend/venv/lib/python3.11/site-packages/flask/app.py", line 869, in full_dispatch_request
    rv = self.handle_user_exception(e)
         ^^^^^^^^^^^^^^^^^^^^^^^^^^^^^
  File "/Users/virender/Desktop/DriveKraft-Backend/venv/lib/python3.11/site-packages/flask/app.py", line 867, in full_dispatch_request
    rv = self.dispatch_request()
         ^^^^^^^^^^^^^^^^^^^^^^^
  File "/Users/virender/Desktop/DriveKraft-Backend/venv/lib/python3.11/site-packages/flask/app.py", line 852, in dispatch_request
    return self.ensure_sync(self.view_functions[rule.endpoint])(**view_args)
           ^^^^^^^^^^^^^^^^^^^^^^^^^^^^^^^^^^^^^^^^^^^^^^^^^^^^^^^^^^^^^^^^^
  File "/Users/virender/Desktop/DriveKraft-Backend/app/util.py", line 18, in wrapper
    raise e
  File "/Users/virender/Desktop/DriveKraft-Backend/app/util.py", line 12, in wrapper
    result = func(*args, **kwargs)
             ^^^^^^^^^^^^^^^^^^^^^
  File "/Users/virender/Desktop/DriveKraft-Backend/app/authenticate.py", line 16, in wrapper
    return func(*args, **kwargs)
           ^^^^^^^^^^^^^^^^^^^^^
  File "/Users/virender/Desktop/DriveKraft-Backend/app/util.py", line 36, in wrapper
    return func(*args, **kwargs)
           ^^^^^^^^^^^^^^^^^^^^^
  File "/Users/virender/Desktop/DriveKraft-Backend/app/Routes/roleRoutes.py", line 15, in getRole
    response = roleService.getUserRole().__dict__
               ^^^^^^^^^^^^^^^^^^^^^^^^^
  File "/Users/virender/Desktop/DriveKraft-Backend/app/Services/roleService.py", line 14, in getUserRole
    response = Role(user.create, user.id, CUSTOMER_ROLE_LABEL, CUSTOMER_ROLE_NAME, pivot, user.updated)
                    ^^^^^^^^^^^
AttributeError: 'User' object has no attribute 'create'
2024-01-08 00:16:04,287 - app - ERROR - Exception on /api/role [GET]
Traceback (most recent call last):
  File "/Users/virender/Desktop/DriveKraft-Backend/venv/lib/python3.11/site-packages/flask/app.py", line 1455, in wsgi_app
    response = self.full_dispatch_request()
               ^^^^^^^^^^^^^^^^^^^^^^^^^^^^
  File "/Users/virender/Desktop/DriveKraft-Backend/venv/lib/python3.11/site-packages/flask/app.py", line 869, in full_dispatch_request
    rv = self.handle_user_exception(e)
         ^^^^^^^^^^^^^^^^^^^^^^^^^^^^^
  File "/Users/virender/Desktop/DriveKraft-Backend/venv/lib/python3.11/site-packages/flask/app.py", line 867, in full_dispatch_request
    rv = self.dispatch_request()
         ^^^^^^^^^^^^^^^^^^^^^^^
  File "/Users/virender/Desktop/DriveKraft-Backend/venv/lib/python3.11/site-packages/flask/app.py", line 852, in dispatch_request
    return self.ensure_sync(self.view_functions[rule.endpoint])(**view_args)
           ^^^^^^^^^^^^^^^^^^^^^^^^^^^^^^^^^^^^^^^^^^^^^^^^^^^^^^^^^^^^^^^^^
  File "/Users/virender/Desktop/DriveKraft-Backend/app/util.py", line 18, in wrapper
    raise e
  File "/Users/virender/Desktop/DriveKraft-Backend/app/util.py", line 12, in wrapper
    result = func(*args, **kwargs)
             ^^^^^^^^^^^^^^^^^^^^^
  File "/Users/virender/Desktop/DriveKraft-Backend/app/authenticate.py", line 16, in wrapper
    return func(*args, **kwargs)
           ^^^^^^^^^^^^^^^^^^^^^
  File "/Users/virender/Desktop/DriveKraft-Backend/app/util.py", line 36, in wrapper
    return func(*args, **kwargs)
           ^^^^^^^^^^^^^^^^^^^^^
  File "/Users/virender/Desktop/DriveKraft-Backend/app/Routes/roleRoutes.py", line 15, in getRole
    response = roleService.getUserRole().__dict__
               ^^^^^^^^^^^^^^^^^^^^^^^^^
  File "/Users/virender/Desktop/DriveKraft-Backend/app/Services/roleService.py", line 14, in getUserRole
    response = Role(user.created, user.id, CUSTOMER_ROLE_LABEL, CUSTOMER_ROLE_NAME, pivot, user.updated)
               ^^^^^^^^^^^^^^^^^^^^^^^^^^^^^^^^^^^^^^^^^^^^^^^^^^^^^^^^^^^^^^^^^^^^^^^^^^^^^^^^^^^^^^^^^
  File "/Users/virender/Desktop/DriveKraft-Backend/app/Contract/Response/getUserRoleResponse.py", line 7, in __init__
    self.pivot = Pivot(**pivot) if pivot else None
                 ^^^^^^^^^^^^^^
TypeError: app.Contract.Response.getUserRoleResponse.Pivot() argument after ** must be a mapping, not Pivot
2024-01-08 00:17:27,842 - app - ERROR - Exception on /api/role [GET]
Traceback (most recent call last):
  File "/Users/virender/Desktop/DriveKraft-Backend/venv/lib/python3.11/site-packages/flask/app.py", line 1455, in wsgi_app
    response = self.full_dispatch_request()
               ^^^^^^^^^^^^^^^^^^^^^^^^^^^^
  File "/Users/virender/Desktop/DriveKraft-Backend/venv/lib/python3.11/site-packages/flask/app.py", line 869, in full_dispatch_request
    rv = self.handle_user_exception(e)
         ^^^^^^^^^^^^^^^^^^^^^^^^^^^^^
  File "/Users/virender/Desktop/DriveKraft-Backend/venv/lib/python3.11/site-packages/flask/app.py", line 867, in full_dispatch_request
    rv = self.dispatch_request()
         ^^^^^^^^^^^^^^^^^^^^^^^
  File "/Users/virender/Desktop/DriveKraft-Backend/venv/lib/python3.11/site-packages/flask/app.py", line 852, in dispatch_request
    return self.ensure_sync(self.view_functions[rule.endpoint])(**view_args)
           ^^^^^^^^^^^^^^^^^^^^^^^^^^^^^^^^^^^^^^^^^^^^^^^^^^^^^^^^^^^^^^^^^
  File "/Users/virender/Desktop/DriveKraft-Backend/app/util.py", line 18, in wrapper
    raise e
  File "/Users/virender/Desktop/DriveKraft-Backend/app/util.py", line 12, in wrapper
    result = func(*args, **kwargs)
             ^^^^^^^^^^^^^^^^^^^^^
  File "/Users/virender/Desktop/DriveKraft-Backend/app/authenticate.py", line 16, in wrapper
    return func(*args, **kwargs)
           ^^^^^^^^^^^^^^^^^^^^^
  File "/Users/virender/Desktop/DriveKraft-Backend/app/util.py", line 36, in wrapper
    return func(*args, **kwargs)
           ^^^^^^^^^^^^^^^^^^^^^
  File "/Users/virender/Desktop/DriveKraft-Backend/app/Routes/roleRoutes.py", line 15, in getRole
    response = roleService.getUserRole().__dict__
               ^^^^^^^^^^^^^^^^^^^^^^^^^
  File "/Users/virender/Desktop/DriveKraft-Backend/app/Services/roleService.py", line 14, in getUserRole
    response = Role(user.created, user.id, CUSTOMER_ROLE_LABEL, CUSTOMER_ROLE_NAME, pivot, user.updated)
               ^^^^^^^^^^^^^^^^^^^^^^^^^^^^^^^^^^^^^^^^^^^^^^^^^^^^^^^^^^^^^^^^^^^^^^^^^^^^^^^^^^^^^^^^^
  File "/Users/virender/Desktop/DriveKraft-Backend/app/Contract/Response/getUserRoleResponse.py", line 7, in __init__
    self.pivot = Pivot(pivot) if pivot else None
                 ^^^^^^^^^^^^
TypeError: Pivot.__init__() missing 1 required positional argument: 'user_id'
2024-01-08 00:17:50,569 - app - ERROR - Exception on /api/role [GET]
Traceback (most recent call last):
  File "/Users/virender/Desktop/DriveKraft-Backend/venv/lib/python3.11/site-packages/flask/app.py", line 1455, in wsgi_app
    response = self.full_dispatch_request()
               ^^^^^^^^^^^^^^^^^^^^^^^^^^^^
  File "/Users/virender/Desktop/DriveKraft-Backend/venv/lib/python3.11/site-packages/flask/app.py", line 869, in full_dispatch_request
    rv = self.handle_user_exception(e)
         ^^^^^^^^^^^^^^^^^^^^^^^^^^^^^
  File "/Users/virender/Desktop/DriveKraft-Backend/venv/lib/python3.11/site-packages/flask/app.py", line 867, in full_dispatch_request
    rv = self.dispatch_request()
         ^^^^^^^^^^^^^^^^^^^^^^^
  File "/Users/virender/Desktop/DriveKraft-Backend/venv/lib/python3.11/site-packages/flask/app.py", line 852, in dispatch_request
    return self.ensure_sync(self.view_functions[rule.endpoint])(**view_args)
           ^^^^^^^^^^^^^^^^^^^^^^^^^^^^^^^^^^^^^^^^^^^^^^^^^^^^^^^^^^^^^^^^^
  File "/Users/virender/Desktop/DriveKraft-Backend/app/util.py", line 18, in wrapper
    raise e
  File "/Users/virender/Desktop/DriveKraft-Backend/app/util.py", line 12, in wrapper
    result = func(*args, **kwargs)
             ^^^^^^^^^^^^^^^^^^^^^
  File "/Users/virender/Desktop/DriveKraft-Backend/app/authenticate.py", line 16, in wrapper
    return func(*args, **kwargs)
           ^^^^^^^^^^^^^^^^^^^^^
  File "/Users/virender/Desktop/DriveKraft-Backend/app/util.py", line 36, in wrapper
    return func(*args, **kwargs)
           ^^^^^^^^^^^^^^^^^^^^^
  File "/Users/virender/Desktop/DriveKraft-Backend/app/Routes/roleRoutes.py", line 15, in getRole
    response = roleService.getUserRole().__dict__
               ^^^^^^^^^^^^^^^^^^^^^^^^^
  File "/Users/virender/Desktop/DriveKraft-Backend/app/Services/roleService.py", line 14, in getUserRole
    response = Role(user.created, user.id, CUSTOMER_ROLE_LABEL, CUSTOMER_ROLE_NAME, pivot, user.updated)
               ^^^^^^^^^^^^^^^^^^^^^^^^^^^^^^^^^^^^^^^^^^^^^^^^^^^^^^^^^^^^^^^^^^^^^^^^^^^^^^^^^^^^^^^^^
  File "/Users/virender/Desktop/DriveKraft-Backend/app/Contract/Response/getUserRoleResponse.py", line 7, in __init__
    self.pivot = Pivot(**pivot) if pivot else None
                 ^^^^^^^^^^^^^^
TypeError: app.Contract.Response.getUserRoleResponse.Pivot() argument after ** must be a mapping, not Pivot
2024-01-08 22:14:21,929 - app - ERROR - Exception on /api/role [GET]
Traceback (most recent call last):
  File "/Users/virender/Desktop/DriveKraft-Backend/venv/lib/python3.11/site-packages/flask/app.py", line 1455, in wsgi_app
    response = self.full_dispatch_request()
               ^^^^^^^^^^^^^^^^^^^^^^^^^^^^
  File "/Users/virender/Desktop/DriveKraft-Backend/venv/lib/python3.11/site-packages/flask/app.py", line 869, in full_dispatch_request
    rv = self.handle_user_exception(e)
         ^^^^^^^^^^^^^^^^^^^^^^^^^^^^^
  File "/Users/virender/Desktop/DriveKraft-Backend/venv/lib/python3.11/site-packages/flask/app.py", line 867, in full_dispatch_request
    rv = self.dispatch_request()
         ^^^^^^^^^^^^^^^^^^^^^^^
  File "/Users/virender/Desktop/DriveKraft-Backend/venv/lib/python3.11/site-packages/flask/app.py", line 852, in dispatch_request
    return self.ensure_sync(self.view_functions[rule.endpoint])(**view_args)
           ^^^^^^^^^^^^^^^^^^^^^^^^^^^^^^^^^^^^^^^^^^^^^^^^^^^^^^^^^^^^^^^^^
  File "/Users/virender/Desktop/DriveKraft-Backend/app/util.py", line 18, in wrapper
    raise e
  File "/Users/virender/Desktop/DriveKraft-Backend/app/util.py", line 12, in wrapper
    result = func(*args, **kwargs)
             ^^^^^^^^^^^^^^^^^^^^^
  File "/Users/virender/Desktop/DriveKraft-Backend/app/authenticate.py", line 16, in wrapper
    return func(*args, **kwargs)
           ^^^^^^^^^^^^^^^^^^^^^
  File "/Users/virender/Desktop/DriveKraft-Backend/app/util.py", line 36, in wrapper
    return func(*args, **kwargs)
           ^^^^^^^^^^^^^^^^^^^^^
  File "/Users/virender/Desktop/DriveKraft-Backend/app/Routes/roleRoutes.py", line 16, in getRole
    return jsonify(response)
           ^^^^^^^^^^^^^^^^^
  File "/Users/virender/Desktop/DriveKraft-Backend/venv/lib/python3.11/site-packages/flask/json/__init__.py", line 170, in jsonify
    return current_app.json.response(*args, **kwargs)
           ^^^^^^^^^^^^^^^^^^^^^^^^^^^^^^^^^^^^^^^^^^
  File "/Users/virender/Desktop/DriveKraft-Backend/venv/lib/python3.11/site-packages/flask/json/provider.py", line 215, in response
    f"{self.dumps(obj, **dump_args)}\n", mimetype=self.mimetype
       ^^^^^^^^^^^^^^^^^^^^^^^^^^^^
  File "/Users/virender/Desktop/DriveKraft-Backend/venv/lib/python3.11/site-packages/flask/json/provider.py", line 180, in dumps
    return json.dumps(obj, **kwargs)
           ^^^^^^^^^^^^^^^^^^^^^^^^^
  File "/usr/local/Cellar/python@3.11/3.11.6_1/Frameworks/Python.framework/Versions/3.11/lib/python3.11/json/__init__.py", line 238, in dumps
    **kw).encode(obj)
          ^^^^^^^^^^^
  File "/usr/local/Cellar/python@3.11/3.11.6_1/Frameworks/Python.framework/Versions/3.11/lib/python3.11/json/encoder.py", line 200, in encode
    chunks = self.iterencode(o, _one_shot=True)
             ^^^^^^^^^^^^^^^^^^^^^^^^^^^^^^^^^^
  File "/usr/local/Cellar/python@3.11/3.11.6_1/Frameworks/Python.framework/Versions/3.11/lib/python3.11/json/encoder.py", line 258, in iterencode
    return _iterencode(o, 0)
           ^^^^^^^^^^^^^^^^^
  File "/Users/virender/Desktop/DriveKraft-Backend/venv/lib/python3.11/site-packages/flask/json/provider.py", line 120, in _default
    raise TypeError(f"Object of type {type(o).__name__} is not JSON serializable")
TypeError: Object of type Pivot is not JSON serializable
2024-01-08 22:15:22,670 - app - ERROR - Exception on /api/role [GET]
Traceback (most recent call last):
  File "/Users/virender/Desktop/DriveKraft-Backend/venv/lib/python3.11/site-packages/flask/app.py", line 1455, in wsgi_app
    response = self.full_dispatch_request()
               ^^^^^^^^^^^^^^^^^^^^^^^^^^^^
  File "/Users/virender/Desktop/DriveKraft-Backend/venv/lib/python3.11/site-packages/flask/app.py", line 869, in full_dispatch_request
    rv = self.handle_user_exception(e)
         ^^^^^^^^^^^^^^^^^^^^^^^^^^^^^
  File "/Users/virender/Desktop/DriveKraft-Backend/venv/lib/python3.11/site-packages/flask/app.py", line 867, in full_dispatch_request
    rv = self.dispatch_request()
         ^^^^^^^^^^^^^^^^^^^^^^^
  File "/Users/virender/Desktop/DriveKraft-Backend/venv/lib/python3.11/site-packages/flask/app.py", line 852, in dispatch_request
    return self.ensure_sync(self.view_functions[rule.endpoint])(**view_args)
           ^^^^^^^^^^^^^^^^^^^^^^^^^^^^^^^^^^^^^^^^^^^^^^^^^^^^^^^^^^^^^^^^^
  File "/Users/virender/Desktop/DriveKraft-Backend/app/util.py", line 18, in wrapper
    raise e
  File "/Users/virender/Desktop/DriveKraft-Backend/app/util.py", line 12, in wrapper
    result = func(*args, **kwargs)
             ^^^^^^^^^^^^^^^^^^^^^
  File "/Users/virender/Desktop/DriveKraft-Backend/app/authenticate.py", line 16, in wrapper
    return func(*args, **kwargs)
           ^^^^^^^^^^^^^^^^^^^^^
  File "/Users/virender/Desktop/DriveKraft-Backend/app/util.py", line 36, in wrapper
    return func(*args, **kwargs)
           ^^^^^^^^^^^^^^^^^^^^^
  File "/Users/virender/Desktop/DriveKraft-Backend/app/Routes/roleRoutes.py", line 16, in getRole
    return jsonify(response)
           ^^^^^^^^^^^^^^^^^
  File "/Users/virender/Desktop/DriveKraft-Backend/venv/lib/python3.11/site-packages/flask/json/__init__.py", line 170, in jsonify
    return current_app.json.response(*args, **kwargs)
           ^^^^^^^^^^^^^^^^^^^^^^^^^^^^^^^^^^^^^^^^^^
  File "/Users/virender/Desktop/DriveKraft-Backend/venv/lib/python3.11/site-packages/flask/json/provider.py", line 215, in response
    f"{self.dumps(obj, **dump_args)}\n", mimetype=self.mimetype
       ^^^^^^^^^^^^^^^^^^^^^^^^^^^^
  File "/Users/virender/Desktop/DriveKraft-Backend/venv/lib/python3.11/site-packages/flask/json/provider.py", line 180, in dumps
    return json.dumps(obj, **kwargs)
           ^^^^^^^^^^^^^^^^^^^^^^^^^
  File "/usr/local/Cellar/python@3.11/3.11.6_1/Frameworks/Python.framework/Versions/3.11/lib/python3.11/json/__init__.py", line 238, in dumps
    **kw).encode(obj)
          ^^^^^^^^^^^
  File "/usr/local/Cellar/python@3.11/3.11.6_1/Frameworks/Python.framework/Versions/3.11/lib/python3.11/json/encoder.py", line 200, in encode
    chunks = self.iterencode(o, _one_shot=True)
             ^^^^^^^^^^^^^^^^^^^^^^^^^^^^^^^^^^
  File "/usr/local/Cellar/python@3.11/3.11.6_1/Frameworks/Python.framework/Versions/3.11/lib/python3.11/json/encoder.py", line 258, in iterencode
    return _iterencode(o, 0)
           ^^^^^^^^^^^^^^^^^
  File "/Users/virender/Desktop/DriveKraft-Backend/venv/lib/python3.11/site-packages/flask/json/provider.py", line 120, in _default
    raise TypeError(f"Object of type {type(o).__name__} is not JSON serializable")
TypeError: Object of type Pivot is not JSON serializable
2024-01-08 22:43:05,685 - app - ERROR - Exception on /api/check/user/busy [POST]
Traceback (most recent call last):
  File "/Users/virender/Desktop/DriveKraft-Backend/venv/lib/python3.11/site-packages/flask/app.py", line 1455, in wsgi_app
    response = self.full_dispatch_request()
               ^^^^^^^^^^^^^^^^^^^^^^^^^^^^
  File "/Users/virender/Desktop/DriveKraft-Backend/venv/lib/python3.11/site-packages/flask/app.py", line 869, in full_dispatch_request
    rv = self.handle_user_exception(e)
         ^^^^^^^^^^^^^^^^^^^^^^^^^^^^^
  File "/Users/virender/Desktop/DriveKraft-Backend/venv/lib/python3.11/site-packages/flask/app.py", line 867, in full_dispatch_request
    rv = self.dispatch_request()
         ^^^^^^^^^^^^^^^^^^^^^^^
  File "/Users/virender/Desktop/DriveKraft-Backend/venv/lib/python3.11/site-packages/flask/app.py", line 852, in dispatch_request
    return self.ensure_sync(self.view_functions[rule.endpoint])(**view_args)
           ^^^^^^^^^^^^^^^^^^^^^^^^^^^^^^^^^^^^^^^^^^^^^^^^^^^^^^^^^^^^^^^^^
  File "/Users/virender/Desktop/DriveKraft-Backend/app/util.py", line 18, in wrapper
    raise e
  File "/Users/virender/Desktop/DriveKraft-Backend/app/util.py", line 12, in wrapper
    result = func(*args, **kwargs)
             ^^^^^^^^^^^^^^^^^^^^^
  File "/Users/virender/Desktop/DriveKraft-Backend/app/authenticate.py", line 16, in wrapper
    return func(*args, **kwargs)
           ^^^^^^^^^^^^^^^^^^^^^
  File "/Users/virender/Desktop/DriveKraft-Backend/app/util.py", line 36, in wrapper
    return func(*args, **kwargs)
           ^^^^^^^^^^^^^^^^^^^^^
  File "/Users/virender/Desktop/DriveKraft-Backend/app/Routes/psychologistRoutes.py", line 24, in setPsychologistAsBusy
    requestData = setPsychologistBusyRequest.setPsychologistBusyRequest(**request.json_data)
                  ^^^^^^^^^^^^^^^^^^^^^^^^^^^^^^^^^^^^^^^^^^^^^^^^^^^^^^^^^^^^^^^^^^^^^^^^^^
TypeError: setPsychologistBusyRequest.__init__() got an unexpected keyword argument 'psychologist_id'
