2024-01-09 20:31:33,511 - app - ERROR - Exception on /api/role [GET]
Traceback (most recent call last):
  File "/Users/virender/Desktop/DriveKraft-Backend/venv/lib/python3.11/site-packages/flask/app.py", line 1455, in wsgi_app
    response = self.full_dispatch_request()
               ^^^^^^^^^^^^^^^^^^^^^^^^^^^^
  File "/Users/virender/Desktop/DriveKraft-Backend/venv/lib/python3.11/site-packages/flask/app.py", line 869, in full_dispatch_request
    rv = self.handle_user_exception(e)
         ^^^^^^^^^^^^^^^^^^^^^^^^^^^^^
  File "/Users/virender/Desktop/DriveKraft-Backend/venv/lib/python3.11/site-packages/flask/app.py", line 867, in full_dispatch_request
    rv = self.dispatch_request()
         ^^^^^^^^^^^^^^^^^^^^^^^
  File "/Users/virender/Desktop/DriveKraft-Backend/venv/lib/python3.11/site-packages/flask/app.py", line 852, in dispatch_request
    return self.ensure_sync(self.view_functions[rule.endpoint])(**view_args)
           ^^^^^^^^^^^^^^^^^^^^^^^^^^^^^^^^^^^^^^^^^^^^^^^^^^^^^^^^^^^^^^^^^
  File "/Users/virender/Desktop/DriveKraft-Backend/app/util.py", line 18, in wrapper
    raise e
  File "/Users/virender/Desktop/DriveKraft-Backend/app/util.py", line 12, in wrapper
    result = func(*args, **kwargs)
             ^^^^^^^^^^^^^^^^^^^^^
  File "/Users/virender/Desktop/DriveKraft-Backend/app/authenticate.py", line 16, in wrapper
    return func(*args, **kwargs)
           ^^^^^^^^^^^^^^^^^^^^^
  File "/Users/virender/Desktop/DriveKraft-Backend/app/util.py", line 36, in wrapper
    return func(*args, **kwargs)
           ^^^^^^^^^^^^^^^^^^^^^
  File "/Users/virender/Desktop/DriveKraft-Backend/app/Routes/roleRoutes.py", line 15, in getRole
    response = roleService.getUserRole().__dict__
               ^^^^^^^^^^^^^^^^^^^^^^^^^
  File "/Users/virender/Desktop/DriveKraft-Backend/app/Services/roleService.py", line 17, in getUserRole
    logging.info()
TypeError: info() missing 1 required positional argument: 'msg'
2024-01-09 20:31:54,829 - app - ERROR - Exception on /api/role [GET]
Traceback (most recent call last):
  File "/Users/virender/Desktop/DriveKraft-Backend/venv/lib/python3.11/site-packages/flask/app.py", line 1455, in wsgi_app
    response = self.full_dispatch_request()
               ^^^^^^^^^^^^^^^^^^^^^^^^^^^^
  File "/Users/virender/Desktop/DriveKraft-Backend/venv/lib/python3.11/site-packages/flask/app.py", line 869, in full_dispatch_request
    rv = self.handle_user_exception(e)
         ^^^^^^^^^^^^^^^^^^^^^^^^^^^^^
  File "/Users/virender/Desktop/DriveKraft-Backend/venv/lib/python3.11/site-packages/flask/app.py", line 867, in full_dispatch_request
    rv = self.dispatch_request()
         ^^^^^^^^^^^^^^^^^^^^^^^
  File "/Users/virender/Desktop/DriveKraft-Backend/venv/lib/python3.11/site-packages/flask/app.py", line 852, in dispatch_request
    return self.ensure_sync(self.view_functions[rule.endpoint])(**view_args)
           ^^^^^^^^^^^^^^^^^^^^^^^^^^^^^^^^^^^^^^^^^^^^^^^^^^^^^^^^^^^^^^^^^
  File "/Users/virender/Desktop/DriveKraft-Backend/app/util.py", line 18, in wrapper
    raise e
  File "/Users/virender/Desktop/DriveKraft-Backend/app/util.py", line 12, in wrapper
    result = func(*args, **kwargs)
             ^^^^^^^^^^^^^^^^^^^^^
  File "/Users/virender/Desktop/DriveKraft-Backend/app/authenticate.py", line 16, in wrapper
    return func(*args, **kwargs)
           ^^^^^^^^^^^^^^^^^^^^^
  File "/Users/virender/Desktop/DriveKraft-Backend/app/util.py", line 36, in wrapper
    return func(*args, **kwargs)
           ^^^^^^^^^^^^^^^^^^^^^
  File "/Users/virender/Desktop/DriveKraft-Backend/app/Routes/roleRoutes.py", line 16, in getRole
    return jsonify(response)
           ^^^^^^^^^^^^^^^^^
  File "/Users/virender/Desktop/DriveKraft-Backend/venv/lib/python3.11/site-packages/flask/json/__init__.py", line 170, in jsonify
    return current_app.json.response(*args, **kwargs)
           ^^^^^^^^^^^^^^^^^^^^^^^^^^^^^^^^^^^^^^^^^^
  File "/Users/virender/Desktop/DriveKraft-Backend/venv/lib/python3.11/site-packages/flask/json/provider.py", line 215, in response
    f"{self.dumps(obj, **dump_args)}\n", mimetype=self.mimetype
       ^^^^^^^^^^^^^^^^^^^^^^^^^^^^
  File "/Users/virender/Desktop/DriveKraft-Backend/venv/lib/python3.11/site-packages/flask/json/provider.py", line 180, in dumps
    return json.dumps(obj, **kwargs)
           ^^^^^^^^^^^^^^^^^^^^^^^^^
  File "/usr/local/Cellar/python@3.11/3.11.6_1/Frameworks/Python.framework/Versions/3.11/lib/python3.11/json/__init__.py", line 238, in dumps
    **kw).encode(obj)
          ^^^^^^^^^^^
  File "/usr/local/Cellar/python@3.11/3.11.6_1/Frameworks/Python.framework/Versions/3.11/lib/python3.11/json/encoder.py", line 200, in encode
    chunks = self.iterencode(o, _one_shot=True)
             ^^^^^^^^^^^^^^^^^^^^^^^^^^^^^^^^^^
  File "/usr/local/Cellar/python@3.11/3.11.6_1/Frameworks/Python.framework/Versions/3.11/lib/python3.11/json/encoder.py", line 258, in iterencode
    return _iterencode(o, 0)
           ^^^^^^^^^^^^^^^^^
  File "/Users/virender/Desktop/DriveKraft-Backend/venv/lib/python3.11/site-packages/flask/json/provider.py", line 120, in _default
    raise TypeError(f"Object of type {type(o).__name__} is not JSON serializable")
TypeError: Object of type Pivot is not JSON serializable
2024-01-09 21:37:57,330 - app - ERROR - Exception on /api/user [GET]
Traceback (most recent call last):
  File "/Users/virender/Desktop/DriveKraft-Backend/venv/lib/python3.11/site-packages/flask/app.py", line 1455, in wsgi_app
    response = self.full_dispatch_request()
               ^^^^^^^^^^^^^^^^^^^^^^^^^^^^
  File "/Users/virender/Desktop/DriveKraft-Backend/venv/lib/python3.11/site-packages/flask/app.py", line 869, in full_dispatch_request
    rv = self.handle_user_exception(e)
         ^^^^^^^^^^^^^^^^^^^^^^^^^^^^^
  File "/Users/virender/Desktop/DriveKraft-Backend/venv/lib/python3.11/site-packages/flask/app.py", line 867, in full_dispatch_request
    rv = self.dispatch_request()
         ^^^^^^^^^^^^^^^^^^^^^^^
  File "/Users/virender/Desktop/DriveKraft-Backend/venv/lib/python3.11/site-packages/flask/app.py", line 852, in dispatch_request
    return self.ensure_sync(self.view_functions[rule.endpoint])(**view_args)
           ^^^^^^^^^^^^^^^^^^^^^^^^^^^^^^^^^^^^^^^^^^^^^^^^^^^^^^^^^^^^^^^^^
  File "/Users/virender/Desktop/DriveKraft-Backend/app/util.py", line 36, in wrapper
    return func(*args, **kwargs)
           ^^^^^^^^^^^^^^^^^^^^^
  File "/Users/virender/Desktop/DriveKraft-Backend/app/util.py", line 18, in wrapper
    raise e
  File "/Users/virender/Desktop/DriveKraft-Backend/app/util.py", line 12, in wrapper
    result = func(*args, **kwargs)
             ^^^^^^^^^^^^^^^^^^^^^
  File "/Users/virender/Desktop/DriveKraft-Backend/app/authenticate.py", line 16, in wrapper
    return func(*args, **kwargs)
           ^^^^^^^^^^^^^^^^^^^^^
  File "/Users/virender/Desktop/DriveKraft-Backend/app/Routes/userRoutes.py", line 28, in getUserDetails
    return jsonify(response)
           ^^^^^^^^^^^^^^^^^
  File "/Users/virender/Desktop/DriveKraft-Backend/venv/lib/python3.11/site-packages/flask/json/__init__.py", line 170, in jsonify
    return current_app.json.response(*args, **kwargs)
           ^^^^^^^^^^^^^^^^^^^^^^^^^^^^^^^^^^^^^^^^^^
  File "/Users/virender/Desktop/DriveKraft-Backend/venv/lib/python3.11/site-packages/flask/json/provider.py", line 215, in response
    f"{self.dumps(obj, **dump_args)}\n", mimetype=self.mimetype
       ^^^^^^^^^^^^^^^^^^^^^^^^^^^^
  File "/Users/virender/Desktop/DriveKraft-Backend/venv/lib/python3.11/site-packages/flask/json/provider.py", line 180, in dumps
    return json.dumps(obj, **kwargs)
           ^^^^^^^^^^^^^^^^^^^^^^^^^
  File "/usr/local/Cellar/python@3.11/3.11.6_1/Frameworks/Python.framework/Versions/3.11/lib/python3.11/json/__init__.py", line 238, in dumps
    **kw).encode(obj)
          ^^^^^^^^^^^
  File "/usr/local/Cellar/python@3.11/3.11.6_1/Frameworks/Python.framework/Versions/3.11/lib/python3.11/json/encoder.py", line 200, in encode
    chunks = self.iterencode(o, _one_shot=True)
             ^^^^^^^^^^^^^^^^^^^^^^^^^^^^^^^^^^
  File "/usr/local/Cellar/python@3.11/3.11.6_1/Frameworks/Python.framework/Versions/3.11/lib/python3.11/json/encoder.py", line 258, in iterencode
    return _iterencode(o, 0)
           ^^^^^^^^^^^^^^^^^
  File "/Users/virender/Desktop/DriveKraft-Backend/venv/lib/python3.11/site-packages/flask/json/provider.py", line 120, in _default
    raise TypeError(f"Object of type {type(o).__name__} is not JSON serializable")
TypeError: Object of type InstanceState is not JSON serializable
2024-01-09 21:38:30,337 - app - ERROR - Exception on /api/user [GET]
Traceback (most recent call last):
  File "/Users/virender/Desktop/DriveKraft-Backend/venv/lib/python3.11/site-packages/flask/app.py", line 1455, in wsgi_app
    response = self.full_dispatch_request()
               ^^^^^^^^^^^^^^^^^^^^^^^^^^^^
  File "/Users/virender/Desktop/DriveKraft-Backend/venv/lib/python3.11/site-packages/flask/app.py", line 869, in full_dispatch_request
    rv = self.handle_user_exception(e)
         ^^^^^^^^^^^^^^^^^^^^^^^^^^^^^
  File "/Users/virender/Desktop/DriveKraft-Backend/venv/lib/python3.11/site-packages/flask/app.py", line 867, in full_dispatch_request
    rv = self.dispatch_request()
         ^^^^^^^^^^^^^^^^^^^^^^^
  File "/Users/virender/Desktop/DriveKraft-Backend/venv/lib/python3.11/site-packages/flask/app.py", line 852, in dispatch_request
    return self.ensure_sync(self.view_functions[rule.endpoint])(**view_args)
           ^^^^^^^^^^^^^^^^^^^^^^^^^^^^^^^^^^^^^^^^^^^^^^^^^^^^^^^^^^^^^^^^^
  File "/Users/virender/Desktop/DriveKraft-Backend/app/util.py", line 36, in wrapper
    return func(*args, **kwargs)
           ^^^^^^^^^^^^^^^^^^^^^
  File "/Users/virender/Desktop/DriveKraft-Backend/app/util.py", line 18, in wrapper
    raise e
  File "/Users/virender/Desktop/DriveKraft-Backend/app/util.py", line 12, in wrapper
    result = func(*args, **kwargs)
             ^^^^^^^^^^^^^^^^^^^^^
  File "/Users/virender/Desktop/DriveKraft-Backend/app/authenticate.py", line 16, in wrapper
    return func(*args, **kwargs)
           ^^^^^^^^^^^^^^^^^^^^^
  File "/Users/virender/Desktop/DriveKraft-Backend/app/Routes/userRoutes.py", line 28, in getUserDetails
    return jsonify(response)
           ^^^^^^^^^^^^^^^^^
  File "/Users/virender/Desktop/DriveKraft-Backend/venv/lib/python3.11/site-packages/flask/json/__init__.py", line 170, in jsonify
    return current_app.json.response(*args, **kwargs)
           ^^^^^^^^^^^^^^^^^^^^^^^^^^^^^^^^^^^^^^^^^^
  File "/Users/virender/Desktop/DriveKraft-Backend/venv/lib/python3.11/site-packages/flask/json/provider.py", line 215, in response
    f"{self.dumps(obj, **dump_args)}\n", mimetype=self.mimetype
       ^^^^^^^^^^^^^^^^^^^^^^^^^^^^
  File "/Users/virender/Desktop/DriveKraft-Backend/venv/lib/python3.11/site-packages/flask/json/provider.py", line 180, in dumps
    return json.dumps(obj, **kwargs)
           ^^^^^^^^^^^^^^^^^^^^^^^^^
  File "/usr/local/Cellar/python@3.11/3.11.6_1/Frameworks/Python.framework/Versions/3.11/lib/python3.11/json/__init__.py", line 238, in dumps
    **kw).encode(obj)
          ^^^^^^^^^^^
  File "/usr/local/Cellar/python@3.11/3.11.6_1/Frameworks/Python.framework/Versions/3.11/lib/python3.11/json/encoder.py", line 200, in encode
    chunks = self.iterencode(o, _one_shot=True)
             ^^^^^^^^^^^^^^^^^^^^^^^^^^^^^^^^^^
  File "/usr/local/Cellar/python@3.11/3.11.6_1/Frameworks/Python.framework/Versions/3.11/lib/python3.11/json/encoder.py", line 258, in iterencode
    return _iterencode(o, 0)
           ^^^^^^^^^^^^^^^^^
  File "/Users/virender/Desktop/DriveKraft-Backend/venv/lib/python3.11/site-packages/flask/json/provider.py", line 120, in _default
    raise TypeError(f"Object of type {type(o).__name__} is not JSON serializable")
TypeError: Object of type InstanceState is not JSON serializable
2024-01-09 21:39:54,274 - app - ERROR - Exception on /api/check/user/bal [GET]
Traceback (most recent call last):
  File "/Users/virender/Desktop/DriveKraft-Backend/venv/lib/python3.11/site-packages/flask/app.py", line 1455, in wsgi_app
    response = self.full_dispatch_request()
               ^^^^^^^^^^^^^^^^^^^^^^^^^^^^
  File "/Users/virender/Desktop/DriveKraft-Backend/venv/lib/python3.11/site-packages/flask/app.py", line 869, in full_dispatch_request
    rv = self.handle_user_exception(e)
         ^^^^^^^^^^^^^^^^^^^^^^^^^^^^^
  File "/Users/virender/Desktop/DriveKraft-Backend/venv/lib/python3.11/site-packages/flask/app.py", line 867, in full_dispatch_request
    rv = self.dispatch_request()
         ^^^^^^^^^^^^^^^^^^^^^^^
  File "/Users/virender/Desktop/DriveKraft-Backend/venv/lib/python3.11/site-packages/flask/app.py", line 852, in dispatch_request
    return self.ensure_sync(self.view_functions[rule.endpoint])(**view_args)
           ^^^^^^^^^^^^^^^^^^^^^^^^^^^^^^^^^^^^^^^^^^^^^^^^^^^^^^^^^^^^^^^^^
  File "/Users/virender/Desktop/DriveKraft-Backend/app/util.py", line 36, in wrapper
    return func(*args, **kwargs)
           ^^^^^^^^^^^^^^^^^^^^^
  File "/Users/virender/Desktop/DriveKraft-Backend/app/util.py", line 18, in wrapper
    raise e
  File "/Users/virender/Desktop/DriveKraft-Backend/app/util.py", line 12, in wrapper
    result = func(*args, **kwargs)
             ^^^^^^^^^^^^^^^^^^^^^
  File "/Users/virender/Desktop/DriveKraft-Backend/app/authenticate.py", line 16, in wrapper
    return func(*args, **kwargs)
           ^^^^^^^^^^^^^^^^^^^^^
  File "/Users/virender/Desktop/DriveKraft-Backend/app/Routes/userRoutes.py", line 35, in fetchUserRoleDetails
    response = userService.getUserBalance().__dict__
               ^^^^^^^^^^^^^^^^^^^^^^^^^^^^^^^^^^^^^
AttributeError: 'NoneType' object has no attribute '__dict__'
2024-01-09 22:14:48,410 - app - ERROR - Exception on /api/check/user/bal [GET]
Traceback (most recent call last):
  File "/Users/virender/Desktop/DriveKraft-Backend/app/util.py", line 12, in wrapper
    result = func(*args, **kwargs)
             ^^^^^^^^^^^^^^^^^^^^^
  File "/Users/virender/Desktop/DriveKraft-Backend/app/authenticate.py", line 16, in wrapper
    return func(*args, **kwargs)
           ^^^^^^^^^^^^^^^^^^^^^
  File "/Users/virender/Desktop/DriveKraft-Backend/app/Routes/userRoutes.py", line 35, in fetchUserBalanceDetails
    response = userService.getUserBalance().__dict__
               ^^^^^^^^^^^^^^^^^^^^^^^^^^^^
  File "/Users/virender/Desktop/DriveKraft-Backend/app/Services/userService.py", line 58, in getUserBalance
    user = getUserDetails()
           ^^^^^^^^^^^^^^^^
  File "/Users/virender/Desktop/DriveKraft-Backend/app/Services/userService.py", line 97, in getUserDetails
    return getUserByToken(g.tokenValue)
           ^^^^^^^^^^^^^^^^^^^^^^^^^^^^
  File "/Users/virender/Desktop/DriveKraft-Backend/venv/lib/python3.11/site-packages/flask_caching/__init__.py", line 872, in decorated_function
    rv = self._call_fn(f, *args, **kwargs)
         ^^^^^^^^^^^^^^^^^^^^^^^^^^^^^^^^^
  File "/Users/virender/Desktop/DriveKraft-Backend/venv/lib/python3.11/site-packages/flask_caching/__init__.py", line 175, in _call_fn
    return ensure_sync(fn)(*args, **kwargs)
           ^^^^^^^^^^^^^^^^^^^^^^^^^^^^^^^^
  File "/Users/virender/Desktop/DriveKraft-Backend/app/Services/userService.py", line 93, in getUserByToken
    return userDao.getUserById(token.userId)
           ^^^^^^^^^^^^^^^^^^^^^^^^^^^^^^^^^
  File "/Users/virender/Desktop/DriveKraft-Backend/app/Models/DAO/userDao.py", line 51, in getUserById
    user = session.query(User).filter_by(id=userId).one()
           ^^^^^^^^^^^^^^^^^^^^^^^^^^^^^^^^^^^^^^^^^^^^^^
  File "/Users/virender/Desktop/DriveKraft-Backend/venv/lib/python3.11/site-packages/sqlalchemy/orm/query.py", line 2798, in one
    return self._iter().one()  # type: ignore
           ^^^^^^^^^^^^^^^^^^
  File "/Users/virender/Desktop/DriveKraft-Backend/venv/lib/python3.11/site-packages/sqlalchemy/engine/result.py", line 1827, in one
    return self._only_one_row(
           ^^^^^^^^^^^^^^^^^^^
  File "/Users/virender/Desktop/DriveKraft-Backend/venv/lib/python3.11/site-packages/sqlalchemy/engine/result.py", line 757, in _only_one_row
    row: Optional[_InterimRowType[Any]] = onerow(hard_close=True)
                                          ^^^^^^^^^^^^^^^^^^^^^^^
  File "/Users/virender/Desktop/DriveKraft-Backend/venv/lib/python3.11/site-packages/sqlalchemy/engine/result.py", line 1690, in _fetchone_impl
    return self._real_result._fetchone_impl(hard_close=hard_close)
           ^^^^^^^^^^^^^^^^^^^^^^^^^^^^^^^^^^^^^^^^^^^^^^^^^^^^^^^
  File "/Users/virender/Desktop/DriveKraft-Backend/venv/lib/python3.11/site-packages/sqlalchemy/engine/result.py", line 2282, in _fetchone_impl
    row = next(self.iterator, _NO_ROW)
          ^^^^^^^^^^^^^^^^^^^^^^^^^^^^
  File "/Users/virender/Desktop/DriveKraft-Backend/venv/lib/python3.11/site-packages/sqlalchemy/orm/loading.py", line 219, in chunks
    rows = [proc(row) for row in fetch]
           ^^^^^^^^^^^^^^^^^^^^^^^^^^^^
  File "/Users/virender/Desktop/DriveKraft-Backend/venv/lib/python3.11/site-packages/sqlalchemy/orm/loading.py", line 219, in <listcomp>
    rows = [proc(row) for row in fetch]
            ^^^^^^^^^
  File "/Users/virender/Desktop/DriveKraft-Backend/venv/lib/python3.11/site-packages/sqlalchemy/orm/loading.py", line 1124, in _instance
    _populate_full(
  File "/Users/virender/Desktop/DriveKraft-Backend/venv/lib/python3.11/site-packages/sqlalchemy/orm/loading.py", line 1320, in _populate_full
    dict_[key] = getter(row)
    ~~~~~^^^^^
TypeError: 'method' object does not support item assignment

During handling of the above exception, another exception occurred:

Traceback (most recent call last):
  File "/Users/virender/Desktop/DriveKraft-Backend/venv/lib/python3.11/site-packages/flask/app.py", line 1455, in wsgi_app
    response = self.full_dispatch_request()
               ^^^^^^^^^^^^^^^^^^^^^^^^^^^^
  File "/Users/virender/Desktop/DriveKraft-Backend/venv/lib/python3.11/site-packages/flask/app.py", line 869, in full_dispatch_request
    rv = self.handle_user_exception(e)
         ^^^^^^^^^^^^^^^^^^^^^^^^^^^^^
  File "/Users/virender/Desktop/DriveKraft-Backend/venv/lib/python3.11/site-packages/flask/app.py", line 867, in full_dispatch_request
    rv = self.dispatch_request()
         ^^^^^^^^^^^^^^^^^^^^^^^
  File "/Users/virender/Desktop/DriveKraft-Backend/venv/lib/python3.11/site-packages/flask/app.py", line 852, in dispatch_request
    return self.ensure_sync(self.view_functions[rule.endpoint])(**view_args)
           ^^^^^^^^^^^^^^^^^^^^^^^^^^^^^^^^^^^^^^^^^^^^^^^^^^^^^^^^^^^^^^^^^
  File "/Users/virender/Desktop/DriveKraft-Backend/app/util.py", line 36, in wrapper
    return func(*args, **kwargs)
           ^^^^^^^^^^^^^^^^^^^^^
  File "/Users/virender/Desktop/DriveKraft-Backend/app/util.py", line 17, in wrapper
    g.session.rollback()
  File "/Users/virender/Desktop/DriveKraft-Backend/venv/lib/python3.11/site-packages/sqlalchemy/orm/session.py", line 1931, in rollback
    self._transaction.rollback(_to_root=True)
  File "<string>", line 2, in rollback
  File "/Users/virender/Desktop/DriveKraft-Backend/venv/lib/python3.11/site-packages/sqlalchemy/orm/state_changes.py", line 139, in _go
    ret_value = fn(self, *arg, **kw)
                ^^^^^^^^^^^^^^^^^^^^
  File "/Users/virender/Desktop/DriveKraft-Backend/venv/lib/python3.11/site-packages/sqlalchemy/orm/session.py", line 1311, in rollback
    transaction._restore_snapshot(
  File "/Users/virender/Desktop/DriveKraft-Backend/venv/lib/python3.11/site-packages/sqlalchemy/orm/session.py", line 1080, in _restore_snapshot
    s._expire(s.dict, self.session.identity_map._modified)
  File "/Users/virender/Desktop/DriveKraft-Backend/venv/lib/python3.11/site-packages/sqlalchemy/orm/state.py", line 732, in _expire
    for k in self.manager._collection_impl_keys.intersection(dict_):
             ^^^^^^^^^^^^^^^^^^^^^^^^^^^^^^^^^^^^^^^^^^^^^^^^^^^^^^
TypeError: 'method' object is not iterable
2024-01-09 22:16:00,767 - app - ERROR - Exception on /api/check/user/bal [GET]
Traceback (most recent call last):
  File "/Users/virender/Desktop/DriveKraft-Backend/venv/lib/python3.11/site-packages/flask/app.py", line 1455, in wsgi_app
    response = self.full_dispatch_request()
               ^^^^^^^^^^^^^^^^^^^^^^^^^^^^
  File "/Users/virender/Desktop/DriveKraft-Backend/venv/lib/python3.11/site-packages/flask/app.py", line 869, in full_dispatch_request
    rv = self.handle_user_exception(e)
         ^^^^^^^^^^^^^^^^^^^^^^^^^^^^^
  File "/Users/virender/Desktop/DriveKraft-Backend/venv/lib/python3.11/site-packages/flask/app.py", line 867, in full_dispatch_request
    rv = self.dispatch_request()
         ^^^^^^^^^^^^^^^^^^^^^^^
  File "/Users/virender/Desktop/DriveKraft-Backend/venv/lib/python3.11/site-packages/flask/app.py", line 852, in dispatch_request
    return self.ensure_sync(self.view_functions[rule.endpoint])(**view_args)
           ^^^^^^^^^^^^^^^^^^^^^^^^^^^^^^^^^^^^^^^^^^^^^^^^^^^^^^^^^^^^^^^^^
  File "/Users/virender/Desktop/DriveKraft-Backend/app/util.py", line 36, in wrapper
    return func(*args, **kwargs)
           ^^^^^^^^^^^^^^^^^^^^^
  File "/Users/virender/Desktop/DriveKraft-Backend/app/util.py", line 18, in wrapper
    raise e
  File "/Users/virender/Desktop/DriveKraft-Backend/app/util.py", line 12, in wrapper
    result = func(*args, **kwargs)
             ^^^^^^^^^^^^^^^^^^^^^
  File "/Users/virender/Desktop/DriveKraft-Backend/app/authenticate.py", line 16, in wrapper
    return func(*args, **kwargs)
           ^^^^^^^^^^^^^^^^^^^^^
  File "/Users/virender/Desktop/DriveKraft-Backend/app/Routes/userRoutes.py", line 35, in fetchUserBalanceDetails
    response = userService.getUserBalance().__dict__
               ^^^^^^^^^^^^^^^^^^^^^^^^^^^^
  File "/Users/virender/Desktop/DriveKraft-Backend/app/Services/userService.py", line 59, in getUserBalance
    response = userBalanceResponse(successful=True , balance=user.balance)
                                                             ^^^^^^^^^^^^
AttributeError: 'dict' object has no attribute 'balance'
2024-01-09 22:16:18,251 - app - ERROR - Exception on /api/user [GET]
Traceback (most recent call last):
  File "/Users/virender/Desktop/DriveKraft-Backend/venv/lib/python3.11/site-packages/flask/app.py", line 1455, in wsgi_app
    response = self.full_dispatch_request()
               ^^^^^^^^^^^^^^^^^^^^^^^^^^^^
  File "/Users/virender/Desktop/DriveKraft-Backend/venv/lib/python3.11/site-packages/flask/app.py", line 869, in full_dispatch_request
    rv = self.handle_user_exception(e)
         ^^^^^^^^^^^^^^^^^^^^^^^^^^^^^
  File "/Users/virender/Desktop/DriveKraft-Backend/venv/lib/python3.11/site-packages/flask/app.py", line 867, in full_dispatch_request
    rv = self.dispatch_request()
         ^^^^^^^^^^^^^^^^^^^^^^^
  File "/Users/virender/Desktop/DriveKraft-Backend/venv/lib/python3.11/site-packages/flask/app.py", line 852, in dispatch_request
    return self.ensure_sync(self.view_functions[rule.endpoint])(**view_args)
           ^^^^^^^^^^^^^^^^^^^^^^^^^^^^^^^^^^^^^^^^^^^^^^^^^^^^^^^^^^^^^^^^^
  File "/Users/virender/Desktop/DriveKraft-Backend/app/util.py", line 36, in wrapper
    return func(*args, **kwargs)
           ^^^^^^^^^^^^^^^^^^^^^
  File "/Users/virender/Desktop/DriveKraft-Backend/app/util.py", line 18, in wrapper
    raise e
  File "/Users/virender/Desktop/DriveKraft-Backend/app/util.py", line 12, in wrapper
    result = func(*args, **kwargs)
             ^^^^^^^^^^^^^^^^^^^^^
  File "/Users/virender/Desktop/DriveKraft-Backend/app/authenticate.py", line 16, in wrapper
    return func(*args, **kwargs)
           ^^^^^^^^^^^^^^^^^^^^^
  File "/Users/virender/Desktop/DriveKraft-Backend/app/Routes/userRoutes.py", line 27, in getUserDetails
    response = userService.getUserDetails().__dict__
               ^^^^^^^^^^^^^^^^^^^^^^^^^^^^^^^^^^^^^
AttributeError: 'dict' object has no attribute '__dict__'
2024-01-09 22:17:37,610 - app - ERROR - Exception on /api/user [GET]
Traceback (most recent call last):
  File "/Users/virender/Desktop/DriveKraft-Backend/venv/lib/python3.11/site-packages/flask/app.py", line 1455, in wsgi_app
    response = self.full_dispatch_request()
               ^^^^^^^^^^^^^^^^^^^^^^^^^^^^
  File "/Users/virender/Desktop/DriveKraft-Backend/venv/lib/python3.11/site-packages/flask/app.py", line 869, in full_dispatch_request
    rv = self.handle_user_exception(e)
         ^^^^^^^^^^^^^^^^^^^^^^^^^^^^^
  File "/Users/virender/Desktop/DriveKraft-Backend/venv/lib/python3.11/site-packages/flask/app.py", line 867, in full_dispatch_request
    rv = self.dispatch_request()
         ^^^^^^^^^^^^^^^^^^^^^^^
  File "/Users/virender/Desktop/DriveKraft-Backend/venv/lib/python3.11/site-packages/flask/app.py", line 852, in dispatch_request
    return self.ensure_sync(self.view_functions[rule.endpoint])(**view_args)
           ^^^^^^^^^^^^^^^^^^^^^^^^^^^^^^^^^^^^^^^^^^^^^^^^^^^^^^^^^^^^^^^^^
  File "/Users/virender/Desktop/DriveKraft-Backend/app/util.py", line 36, in wrapper
    return func(*args, **kwargs)
           ^^^^^^^^^^^^^^^^^^^^^
  File "/Users/virender/Desktop/DriveKraft-Backend/app/util.py", line 18, in wrapper
    raise e
  File "/Users/virender/Desktop/DriveKraft-Backend/app/util.py", line 12, in wrapper
    result = func(*args, **kwargs)
             ^^^^^^^^^^^^^^^^^^^^^
  File "/Users/virender/Desktop/DriveKraft-Backend/app/authenticate.py", line 16, in wrapper
    return func(*args, **kwargs)
           ^^^^^^^^^^^^^^^^^^^^^
  File "/Users/virender/Desktop/DriveKraft-Backend/app/Routes/userRoutes.py", line 27, in getUserDetails
    response = userService.getUserDetails().__dict__
               ^^^^^^^^^^^^^^^^^^^^^^^^^^^^
  File "/Users/virender/Desktop/DriveKraft-Backend/app/Services/userService.py", line 98, in getUserDetails
    return user.as_dict()
           ^^^^^^^^^^^^
AttributeError: 'User' object has no attribute 'as_dict'
2024-01-09 22:17:40,454 - app - ERROR - Exception on /api/check/user/bal [GET]
Traceback (most recent call last):
  File "/Users/virender/Desktop/DriveKraft-Backend/venv/lib/python3.11/site-packages/flask/app.py", line 1455, in wsgi_app
    response = self.full_dispatch_request()
               ^^^^^^^^^^^^^^^^^^^^^^^^^^^^
  File "/Users/virender/Desktop/DriveKraft-Backend/venv/lib/python3.11/site-packages/flask/app.py", line 869, in full_dispatch_request
    rv = self.handle_user_exception(e)
         ^^^^^^^^^^^^^^^^^^^^^^^^^^^^^
  File "/Users/virender/Desktop/DriveKraft-Backend/venv/lib/python3.11/site-packages/flask/app.py", line 867, in full_dispatch_request
    rv = self.dispatch_request()
         ^^^^^^^^^^^^^^^^^^^^^^^
  File "/Users/virender/Desktop/DriveKraft-Backend/venv/lib/python3.11/site-packages/flask/app.py", line 852, in dispatch_request
    return self.ensure_sync(self.view_functions[rule.endpoint])(**view_args)
           ^^^^^^^^^^^^^^^^^^^^^^^^^^^^^^^^^^^^^^^^^^^^^^^^^^^^^^^^^^^^^^^^^
  File "/Users/virender/Desktop/DriveKraft-Backend/app/util.py", line 36, in wrapper
    return func(*args, **kwargs)
           ^^^^^^^^^^^^^^^^^^^^^
  File "/Users/virender/Desktop/DriveKraft-Backend/app/util.py", line 18, in wrapper
    raise e
  File "/Users/virender/Desktop/DriveKraft-Backend/app/util.py", line 12, in wrapper
    result = func(*args, **kwargs)
             ^^^^^^^^^^^^^^^^^^^^^
  File "/Users/virender/Desktop/DriveKraft-Backend/app/authenticate.py", line 16, in wrapper
    return func(*args, **kwargs)
           ^^^^^^^^^^^^^^^^^^^^^
  File "/Users/virender/Desktop/DriveKraft-Backend/app/Routes/userRoutes.py", line 35, in fetchUserBalanceDetails
    response = userService.getUserBalance().__dict__
               ^^^^^^^^^^^^^^^^^^^^^^^^^^^^
  File "/Users/virender/Desktop/DriveKraft-Backend/app/Services/userService.py", line 58, in getUserBalance
    user = getUserDetails()
           ^^^^^^^^^^^^^^^^
  File "/Users/virender/Desktop/DriveKraft-Backend/app/Services/userService.py", line 98, in getUserDetails
    return user.as_dict()
           ^^^^^^^^^^^^
AttributeError: 'User' object has no attribute 'as_dict'
2024-01-09 22:18:04,024 - app - ERROR - Exception on /api/check/user/bal [GET]
Traceback (most recent call last):
  File "/Users/virender/Desktop/DriveKraft-Backend/venv/lib/python3.11/site-packages/flask/app.py", line 1455, in wsgi_app
    response = self.full_dispatch_request()
               ^^^^^^^^^^^^^^^^^^^^^^^^^^^^
  File "/Users/virender/Desktop/DriveKraft-Backend/venv/lib/python3.11/site-packages/flask/app.py", line 869, in full_dispatch_request
    rv = self.handle_user_exception(e)
         ^^^^^^^^^^^^^^^^^^^^^^^^^^^^^
  File "/Users/virender/Desktop/DriveKraft-Backend/venv/lib/python3.11/site-packages/flask/app.py", line 867, in full_dispatch_request
    rv = self.dispatch_request()
         ^^^^^^^^^^^^^^^^^^^^^^^
  File "/Users/virender/Desktop/DriveKraft-Backend/venv/lib/python3.11/site-packages/flask/app.py", line 852, in dispatch_request
    return self.ensure_sync(self.view_functions[rule.endpoint])(**view_args)
           ^^^^^^^^^^^^^^^^^^^^^^^^^^^^^^^^^^^^^^^^^^^^^^^^^^^^^^^^^^^^^^^^^
  File "/Users/virender/Desktop/DriveKraft-Backend/app/util.py", line 36, in wrapper
    return func(*args, **kwargs)
           ^^^^^^^^^^^^^^^^^^^^^
  File "/Users/virender/Desktop/DriveKraft-Backend/app/util.py", line 18, in wrapper
    raise e
  File "/Users/virender/Desktop/DriveKraft-Backend/app/util.py", line 12, in wrapper
    result = func(*args, **kwargs)
             ^^^^^^^^^^^^^^^^^^^^^
  File "/Users/virender/Desktop/DriveKraft-Backend/app/authenticate.py", line 16, in wrapper
    return func(*args, **kwargs)
           ^^^^^^^^^^^^^^^^^^^^^
  File "/Users/virender/Desktop/DriveKraft-Backend/app/Routes/userRoutes.py", line 35, in fetchUserBalanceDetails
    response = userService.getUserBalance().__dict__
               ^^^^^^^^^^^^^^^^^^^^^^^^^^^^
  File "/Users/virender/Desktop/DriveKraft-Backend/app/Services/userService.py", line 58, in getUserBalance
    user = getUserDetails()
           ^^^^^^^^^^^^^^^^
  File "/Users/virender/Desktop/DriveKraft-Backend/app/Services/userService.py", line 98, in getUserDetails
    return user
           ^^^^^
AttributeError: 'User' object has no attribute 'as_dict'
2024-01-09 22:18:12,143 - app - ERROR - Exception on /api/user [GET]
Traceback (most recent call last):
  File "/Users/virender/Desktop/DriveKraft-Backend/venv/lib/python3.11/site-packages/flask/app.py", line 1455, in wsgi_app
    response = self.full_dispatch_request()
               ^^^^^^^^^^^^^^^^^^^^^^^^^^^^
  File "/Users/virender/Desktop/DriveKraft-Backend/venv/lib/python3.11/site-packages/flask/app.py", line 870, in full_dispatch_request
    return self.finalize_request(rv)
           ^^^^^^^^^^^^^^^^^^^^^^^^^
  File "/Users/virender/Desktop/DriveKraft-Backend/venv/lib/python3.11/site-packages/flask/app.py", line 889, in finalize_request
    response = self.make_response(rv)
               ^^^^^^^^^^^^^^^^^^^^^^
  File "/Users/virender/Desktop/DriveKraft-Backend/venv/lib/python3.11/site-packages/flask/app.py", line 1180, in make_response
    rv = self.json.response(rv)
         ^^^^^^^^^^^^^^^^^^^^^^
  File "/Users/virender/Desktop/DriveKraft-Backend/venv/lib/python3.11/site-packages/flask/json/provider.py", line 215, in response
    f"{self.dumps(obj, **dump_args)}\n", mimetype=self.mimetype
       ^^^^^^^^^^^^^^^^^^^^^^^^^^^^
  File "/Users/virender/Desktop/DriveKraft-Backend/venv/lib/python3.11/site-packages/flask/json/provider.py", line 180, in dumps
    return json.dumps(obj, **kwargs)
           ^^^^^^^^^^^^^^^^^^^^^^^^^
  File "/usr/local/Cellar/python@3.11/3.11.6_1/Frameworks/Python.framework/Versions/3.11/lib/python3.11/json/__init__.py", line 238, in dumps
    **kw).encode(obj)
          ^^^^^^^^^^^
  File "/usr/local/Cellar/python@3.11/3.11.6_1/Frameworks/Python.framework/Versions/3.11/lib/python3.11/json/encoder.py", line 200, in encode
    chunks = self.iterencode(o, _one_shot=True)
             ^^^^^^^^^^^^^^^^^^^^^^^^^^^^^^^^^^
  File "/usr/local/Cellar/python@3.11/3.11.6_1/Frameworks/Python.framework/Versions/3.11/lib/python3.11/json/encoder.py", line 258, in iterencode
    return _iterencode(o, 0)
           ^^^^^^^^^^^^^^^^^
  File "/Users/virender/Desktop/DriveKraft-Backend/venv/lib/python3.11/site-packages/flask/json/provider.py", line 120, in _default
    raise TypeError(f"Object of type {type(o).__name__} is not JSON serializable")
TypeError: Object of type InstanceState is not JSON serializable
2024-01-09 22:18:31,499 - app - ERROR - Exception on /api/user [GET]
Traceback (most recent call last):
  File "/Users/virender/Desktop/DriveKraft-Backend/venv/lib/python3.11/site-packages/flask/app.py", line 1455, in wsgi_app
    response = self.full_dispatch_request()
               ^^^^^^^^^^^^^^^^^^^^^^^^^^^^
  File "/Users/virender/Desktop/DriveKraft-Backend/venv/lib/python3.11/site-packages/flask/app.py", line 870, in full_dispatch_request
    return self.finalize_request(rv)
           ^^^^^^^^^^^^^^^^^^^^^^^^^
  File "/Users/virender/Desktop/DriveKraft-Backend/venv/lib/python3.11/site-packages/flask/app.py", line 889, in finalize_request
    response = self.make_response(rv)
               ^^^^^^^^^^^^^^^^^^^^^^
  File "/Users/virender/Desktop/DriveKraft-Backend/venv/lib/python3.11/site-packages/flask/app.py", line 1180, in make_response
    rv = self.json.response(rv)
         ^^^^^^^^^^^^^^^^^^^^^^
  File "/Users/virender/Desktop/DriveKraft-Backend/venv/lib/python3.11/site-packages/flask/json/provider.py", line 215, in response
    f"{self.dumps(obj, **dump_args)}\n", mimetype=self.mimetype
       ^^^^^^^^^^^^^^^^^^^^^^^^^^^^
  File "/Users/virender/Desktop/DriveKraft-Backend/venv/lib/python3.11/site-packages/flask/json/provider.py", line 180, in dumps
    return json.dumps(obj, **kwargs)
           ^^^^^^^^^^^^^^^^^^^^^^^^^
  File "/usr/local/Cellar/python@3.11/3.11.6_1/Frameworks/Python.framework/Versions/3.11/lib/python3.11/json/__init__.py", line 238, in dumps
    **kw).encode(obj)
          ^^^^^^^^^^^
  File "/usr/local/Cellar/python@3.11/3.11.6_1/Frameworks/Python.framework/Versions/3.11/lib/python3.11/json/encoder.py", line 200, in encode
    chunks = self.iterencode(o, _one_shot=True)
             ^^^^^^^^^^^^^^^^^^^^^^^^^^^^^^^^^^
  File "/usr/local/Cellar/python@3.11/3.11.6_1/Frameworks/Python.framework/Versions/3.11/lib/python3.11/json/encoder.py", line 258, in iterencode
    return _iterencode(o, 0)
           ^^^^^^^^^^^^^^^^^
  File "/Users/virender/Desktop/DriveKraft-Backend/venv/lib/python3.11/site-packages/flask/json/provider.py", line 120, in _default
    raise TypeError(f"Object of type {type(o).__name__} is not JSON serializable")
TypeError: Object of type InstanceState is not JSON serializable
2024-01-09 22:20:43,556 - app - ERROR - Exception on /api/username/check [POST]
Traceback (most recent call last):
  File "/Users/virender/Desktop/DriveKraft-Backend/venv/lib/python3.11/site-packages/flask/app.py", line 1455, in wsgi_app
    response = self.full_dispatch_request()
               ^^^^^^^^^^^^^^^^^^^^^^^^^^^^
  File "/Users/virender/Desktop/DriveKraft-Backend/venv/lib/python3.11/site-packages/flask/app.py", line 869, in full_dispatch_request
    rv = self.handle_user_exception(e)
         ^^^^^^^^^^^^^^^^^^^^^^^^^^^^^
  File "/Users/virender/Desktop/DriveKraft-Backend/venv/lib/python3.11/site-packages/flask/app.py", line 867, in full_dispatch_request
    rv = self.dispatch_request()
         ^^^^^^^^^^^^^^^^^^^^^^^
  File "/Users/virender/Desktop/DriveKraft-Backend/venv/lib/python3.11/site-packages/flask/app.py", line 852, in dispatch_request
    return self.ensure_sync(self.view_functions[rule.endpoint])(**view_args)
           ^^^^^^^^^^^^^^^^^^^^^^^^^^^^^^^^^^^^^^^^^^^^^^^^^^^^^^^^^^^^^^^^^
  File "/Users/virender/Desktop/DriveKraft-Backend/app/util.py", line 36, in wrapper
    return func(*args, **kwargs)
           ^^^^^^^^^^^^^^^^^^^^^
  File "/Users/virender/Desktop/DriveKraft-Backend/app/util.py", line 18, in wrapper
    raise e
  File "/Users/virender/Desktop/DriveKraft-Backend/app/util.py", line 12, in wrapper
    result = func(*args, **kwargs)
             ^^^^^^^^^^^^^^^^^^^^^
  File "/Users/virender/Desktop/DriveKraft-Backend/app/authenticate.py", line 16, in wrapper
    return func(*args, **kwargs)
           ^^^^^^^^^^^^^^^^^^^^^
  File "/Users/virender/Desktop/DriveKraft-Backend/app/Routes/userRoutes.py", line 43, in checkForUsername
    requestData = checkUsernameRequest.CheckUsernameRequest(**request.json_data)
                  ^^^^^^^^^^^^^^^^^^^^^^^^^^^^^^^^^^^^^^^^^^^^^^^^^^^^^^^^^^^^^^
TypeError: app.Contract.Request.checkUsernameRequest.CheckUsernameRequest() argument after ** must be a mapping, not NoneType
2024-01-09 22:21:57,633 - app - ERROR - Exception on /api/username/check/confirm [POST]
Traceback (most recent call last):
  File "/Users/virender/Desktop/DriveKraft-Backend/venv/lib/python3.11/site-packages/flask/app.py", line 1455, in wsgi_app
    response = self.full_dispatch_request()
               ^^^^^^^^^^^^^^^^^^^^^^^^^^^^
  File "/Users/virender/Desktop/DriveKraft-Backend/venv/lib/python3.11/site-packages/flask/app.py", line 869, in full_dispatch_request
    rv = self.handle_user_exception(e)
         ^^^^^^^^^^^^^^^^^^^^^^^^^^^^^
  File "/Users/virender/Desktop/DriveKraft-Backend/venv/lib/python3.11/site-packages/flask/app.py", line 867, in full_dispatch_request
    rv = self.dispatch_request()
         ^^^^^^^^^^^^^^^^^^^^^^^
  File "/Users/virender/Desktop/DriveKraft-Backend/venv/lib/python3.11/site-packages/flask/app.py", line 852, in dispatch_request
    return self.ensure_sync(self.view_functions[rule.endpoint])(**view_args)
           ^^^^^^^^^^^^^^^^^^^^^^^^^^^^^^^^^^^^^^^^^^^^^^^^^^^^^^^^^^^^^^^^^
  File "/Users/virender/Desktop/DriveKraft-Backend/app/util.py", line 36, in wrapper
    return func(*args, **kwargs)
           ^^^^^^^^^^^^^^^^^^^^^
  File "/Users/virender/Desktop/DriveKraft-Backend/app/util.py", line 18, in wrapper
    raise e
  File "/Users/virender/Desktop/DriveKraft-Backend/app/util.py", line 12, in wrapper
    result = func(*args, **kwargs)
             ^^^^^^^^^^^^^^^^^^^^^
  File "/Users/virender/Desktop/DriveKraft-Backend/app/authenticate.py", line 16, in wrapper
    return func(*args, **kwargs)
           ^^^^^^^^^^^^^^^^^^^^^
  File "/Users/virender/Desktop/DriveKraft-Backend/app/Routes/userRoutes.py", line 53, in confirmUsername
    response = userService.confirmUsername(requestConfirm).__dict__
               ^^^^^^^^^^^^^^^^^^^^^^^^^^^^^^^^^^^^^^^^^^^
  File "/Users/virender/Desktop/DriveKraft-Backend/app/Services/userService.py", line 45, in confirmUsername
    result = userDao.assignUsername(request.username)
             ^^^^^^^^^^^^^^^^^^^^^^^^^^^^^^^^^^^^^^^^
TypeError: assignUsername() missing 1 required positional argument: 'userId'
2024-01-09 22:28:55,819 - app - ERROR - Exception on /api/username/check/confirm [POST]
Traceback (most recent call last):
  File "/Users/virender/Desktop/DriveKraft-Backend/venv/lib/python3.11/site-packages/flask/app.py", line 1455, in wsgi_app
    response = self.full_dispatch_request()
               ^^^^^^^^^^^^^^^^^^^^^^^^^^^^
  File "/Users/virender/Desktop/DriveKraft-Backend/venv/lib/python3.11/site-packages/flask/app.py", line 869, in full_dispatch_request
    rv = self.handle_user_exception(e)
         ^^^^^^^^^^^^^^^^^^^^^^^^^^^^^
  File "/Users/virender/Desktop/DriveKraft-Backend/venv/lib/python3.11/site-packages/flask/app.py", line 867, in full_dispatch_request
    rv = self.dispatch_request()
         ^^^^^^^^^^^^^^^^^^^^^^^
  File "/Users/virender/Desktop/DriveKraft-Backend/venv/lib/python3.11/site-packages/flask/app.py", line 852, in dispatch_request
    return self.ensure_sync(self.view_functions[rule.endpoint])(**view_args)
           ^^^^^^^^^^^^^^^^^^^^^^^^^^^^^^^^^^^^^^^^^^^^^^^^^^^^^^^^^^^^^^^^^
  File "/Users/virender/Desktop/DriveKraft-Backend/app/util.py", line 36, in wrapper
    return func(*args, **kwargs)
           ^^^^^^^^^^^^^^^^^^^^^
  File "/Users/virender/Desktop/DriveKraft-Backend/app/util.py", line 18, in wrapper
    raise e
  File "/Users/virender/Desktop/DriveKraft-Backend/app/util.py", line 12, in wrapper
    result = func(*args, **kwargs)
             ^^^^^^^^^^^^^^^^^^^^^
  File "/Users/virender/Desktop/DriveKraft-Backend/app/authenticate.py", line 16, in wrapper
    return func(*args, **kwargs)
           ^^^^^^^^^^^^^^^^^^^^^
  File "/Users/virender/Desktop/DriveKraft-Backend/app/Routes/userRoutes.py", line 53, in confirmUsername
    response = userService.confirmUsername(requestConfirm).__dict__
               ^^^^^^^^^^^^^^^^^^^^^^^^^^^^^^^^^^^^^^^^^^^
  File "/Users/virender/Desktop/DriveKraft-Backend/app/Services/userService.py", line 46, in confirmUsername
    result = userDao.assignUsername(request.username,user.id)
             ^^^^^^^^^^^^^^^^^^^^^^^^^^^^^^^^^^^^^^^^^^^^^^^^
  File "/Users/virender/Desktop/DriveKraft-Backend/app/Models/DAO/userDao.py", line 32, in assignUsername
    print(user.id)
          ^^^^^^^
AttributeError: 'Query' object has no attribute 'id'
2024-01-09 22:29:11,642 - app - ERROR - Exception on /api/username/check/confirm [POST]
Traceback (most recent call last):
  File "/Users/virender/Desktop/DriveKraft-Backend/venv/lib/python3.11/site-packages/flask/app.py", line 1455, in wsgi_app
    response = self.full_dispatch_request()
               ^^^^^^^^^^^^^^^^^^^^^^^^^^^^
  File "/Users/virender/Desktop/DriveKraft-Backend/venv/lib/python3.11/site-packages/flask/app.py", line 869, in full_dispatch_request
    rv = self.handle_user_exception(e)
         ^^^^^^^^^^^^^^^^^^^^^^^^^^^^^
  File "/Users/virender/Desktop/DriveKraft-Backend/venv/lib/python3.11/site-packages/flask/app.py", line 867, in full_dispatch_request
    rv = self.dispatch_request()
         ^^^^^^^^^^^^^^^^^^^^^^^
  File "/Users/virender/Desktop/DriveKraft-Backend/venv/lib/python3.11/site-packages/flask/app.py", line 852, in dispatch_request
    return self.ensure_sync(self.view_functions[rule.endpoint])(**view_args)
           ^^^^^^^^^^^^^^^^^^^^^^^^^^^^^^^^^^^^^^^^^^^^^^^^^^^^^^^^^^^^^^^^^
  File "/Users/virender/Desktop/DriveKraft-Backend/app/util.py", line 36, in wrapper
    return func(*args, **kwargs)
           ^^^^^^^^^^^^^^^^^^^^^
  File "/Users/virender/Desktop/DriveKraft-Backend/app/util.py", line 18, in wrapper
    raise e
  File "/Users/virender/Desktop/DriveKraft-Backend/app/util.py", line 12, in wrapper
    result = func(*args, **kwargs)
             ^^^^^^^^^^^^^^^^^^^^^
  File "/Users/virender/Desktop/DriveKraft-Backend/app/authenticate.py", line 16, in wrapper
    return func(*args, **kwargs)
           ^^^^^^^^^^^^^^^^^^^^^
  File "/Users/virender/Desktop/DriveKraft-Backend/app/Routes/userRoutes.py", line 53, in confirmUsername
    response = userService.confirmUsername(requestConfirm).__dict__
               ^^^^^^^^^^^^^^^^^^^^^^^^^^^^^^^^^^^^^^^^^^^
  File "/Users/virender/Desktop/DriveKraft-Backend/app/Services/userService.py", line 46, in confirmUsername
    result = userDao.assignUsername(request.username,user.id)
             ^^^^^^^^^^^^^^^^^^^^^^^^^^^^^^^^^^^^^^^^^^^^^^^^
  File "/Users/virender/Desktop/DriveKraft-Backend/app/Models/DAO/userDao.py", line 32, in assignUsername
    print(user)
          ^^^^^^
AttributeError: 'Query' object has no attribute 'id'
