2024-02-03 05:41:16,366 - app - ERROR - Exception on /api/order/placed [POST]
Traceback (most recent call last):
  File "/home/DriveKraft/.local/lib/python3.10/site-packages/flask/app.py", line 2525, in wsgi_app
    response = self.full_dispatch_request()
  File "/home/DriveKraft/.local/lib/python3.10/site-packages/flask/app.py", line 1822, in full_dispatch_request
    rv = self.handle_user_exception(e)
  File "/home/DriveKraft/.local/lib/python3.10/site-packages/flask/app.py", line 1820, in full_dispatch_request
    rv = self.dispatch_request()
  File "/home/DriveKraft/.local/lib/python3.10/site-packages/flask/app.py", line 1796, in dispatch_request
    return self.ensure_sync(self.view_functions[rule.endpoint])(**view_args)
  File "/home/DriveKraft/drivekraft-app-backend/./app/util.py", line 21, in wrapper
    raise e
  File "/home/DriveKraft/drivekraft-app-backend/./app/util.py", line 15, in wrapper
    result = func(*args, **kwargs)
  File "/home/DriveKraft/drivekraft-app-backend/./app/util.py", line 43, in wrapper
    return func(*args, **kwargs)
  File "/home/DriveKraft/drivekraft-app-backend/./app/authenticate.py", line 16, in wrapper
    return func(*args, **kwargs)
  File "/home/DriveKraft/drivekraft-app-backend/./app/Routes/paymentRoutes.py", line 27, in placeOrder
    response = paymentService.placeOrder(request.json_data).__dict__
  File "/home/DriveKraft/drivekraft-app-backend/./app/Services/paymentService.py", line 63, in placeOrder
    response = placeRazorpayOrderResponse(transaction_id=transactional.orderId,user_credits=user.balance,
AttributeError: 'Transaction' object has no attribute 'orderId'
2024-02-03 07:06:55,606 - app - ERROR - Exception on /api/session/request/fetch [GET]
Traceback (most recent call last):
  File "/usr/local/lib/python3.10/site-packages/sqlalchemy/engine/base.py", line 3280, in _wrap_pool_connect
    return fn()
  File "/usr/local/lib/python3.10/site-packages/sqlalchemy/pool/base.py", line 310, in connect
    return _ConnectionFairy._checkout(self)
  File "/usr/local/lib/python3.10/site-packages/sqlalchemy/pool/base.py", line 901, in _checkout
    result = pool._dialect.do_ping(fairy.dbapi_connection)
  File "/usr/local/lib/python3.10/site-packages/sqlalchemy/dialects/mysql/mysqldb.py", line 183, in do_ping
    dbapi_connection.ping(False)
MySQLdb._exceptions.OperationalError: (4031, 'The client was disconnected by the server because of inactivity. See wait_timeout and interactive_timeout for configuring this behavior.')

The above exception was the direct cause of the following exception:

Traceback (most recent call last):
  File "/home/DriveKraft/.local/lib/python3.10/site-packages/flask/app.py", line 2525, in wsgi_app
    response = self.full_dispatch_request()
  File "/home/DriveKraft/.local/lib/python3.10/site-packages/flask/app.py", line 1822, in full_dispatch_request
    rv = self.handle_user_exception(e)
  File "/home/DriveKraft/.local/lib/python3.10/site-packages/flask/app.py", line 1820, in full_dispatch_request
    rv = self.dispatch_request()
  File "/home/DriveKraft/.local/lib/python3.10/site-packages/flask/app.py", line 1796, in dispatch_request
    return self.ensure_sync(self.view_functions[rule.endpoint])(**view_args)
  File "/home/DriveKraft/drivekraft-app-backend/./app/util.py", line 21, in wrapper
    raise e
  File "/home/DriveKraft/drivekraft-app-backend/./app/util.py", line 15, in wrapper
    result = func(*args, **kwargs)
  File "/home/DriveKraft/drivekraft-app-backend/./app/util.py", line 43, in wrapper
    return func(*args, **kwargs)
  File "/home/DriveKraft/drivekraft-app-backend/./app/authenticate.py", line 14, in wrapper
    if verify_token(tokenValue):
  File "/home/DriveKraft/drivekraft-app-backend/./app/authenticate.py", line 25, in verify_token
    token = getToken(tokenValue=tokenValue)
  File "/home/DriveKraft/.local/lib/python3.10/site-packages/flask_caching/__init__.py", line 872, in decorated_function
    rv = self._call_fn(f, *args, **kwargs)
  File "/home/DriveKraft/.local/lib/python3.10/site-packages/flask_caching/__init__.py", line 175, in _call_fn
    return ensure_sync(fn)(*args, **kwargs)
  File "/home/DriveKraft/drivekraft-app-backend/./app/Models/DAO/tokenDAO.py", line 28, in getToken
    and_(Token.value == tokenValue, Token.created >= now - timedelta(hours=24))).one()
  File "/usr/local/lib/python3.10/site-packages/sqlalchemy/orm/query.py", line 2865, in one
    return self._iter().one()
  File "/usr/local/lib/python3.10/site-packages/sqlalchemy/orm/query.py", line 2903, in _iter
    result = self.session.execute(
  File "/usr/local/lib/python3.10/site-packages/sqlalchemy/orm/session.py", line 1695, in execute
    conn = self._connection_for_bind(bind)
  File "/usr/local/lib/python3.10/site-packages/sqlalchemy/orm/session.py", line 1536, in _connection_for_bind
    return self._transaction._connection_for_bind(
  File "/usr/local/lib/python3.10/site-packages/sqlalchemy/orm/session.py", line 747, in _connection_for_bind
    conn = bind.connect()
  File "/usr/local/lib/python3.10/site-packages/sqlalchemy/engine/base.py", line 3234, in connect
    return self._connection_cls(self, close_with_result=close_with_result)
  File "/usr/local/lib/python3.10/site-packages/sqlalchemy/engine/base.py", line 96, in __init__
    else engine.raw_connection()
  File "/usr/local/lib/python3.10/site-packages/sqlalchemy/engine/base.py", line 3313, in raw_connection
    return self._wrap_pool_connect(self.pool.connect, _connection)
  File "/usr/local/lib/python3.10/site-packages/sqlalchemy/engine/base.py", line 3283, in _wrap_pool_connect
    Connection._handle_dbapi_exception_noconnection(
  File "/usr/local/lib/python3.10/site-packages/sqlalchemy/engine/base.py", line 2117, in _handle_dbapi_exception_noconnection
    util.raise_(
  File "/usr/local/lib/python3.10/site-packages/sqlalchemy/util/compat.py", line 207, in raise_
    raise exception
  File "/usr/local/lib/python3.10/site-packages/sqlalchemy/engine/base.py", line 3280, in _wrap_pool_connect
    return fn()
  File "/usr/local/lib/python3.10/site-packages/sqlalchemy/pool/base.py", line 310, in connect
    return _ConnectionFairy._checkout(self)
  File "/usr/local/lib/python3.10/site-packages/sqlalchemy/pool/base.py", line 901, in _checkout
    result = pool._dialect.do_ping(fairy.dbapi_connection)
  File "/usr/local/lib/python3.10/site-packages/sqlalchemy/dialects/mysql/mysqldb.py", line 183, in do_ping
    dbapi_connection.ping(False)
sqlalchemy.exc.OperationalError: (MySQLdb._exceptions.OperationalError) (4031, 'The client was disconnected by the server because of inactivity. See wait_timeout and interactive_timeout for configuring this behavior.')
(Background on this error at: https://sqlalche.me/e/14/e3q8)
2024-02-03 07:07:39,735 - app - ERROR - Exception on /api/order/placed [POST]
Traceback (most recent call last):
  File "/home/DriveKraft/.local/lib/python3.10/site-packages/flask/app.py", line 2525, in wsgi_app
    response = self.full_dispatch_request()
  File "/home/DriveKraft/.local/lib/python3.10/site-packages/flask/app.py", line 1822, in full_dispatch_request
    rv = self.handle_user_exception(e)
  File "/home/DriveKraft/.local/lib/python3.10/site-packages/flask/app.py", line 1820, in full_dispatch_request
    rv = self.dispatch_request()
  File "/home/DriveKraft/.local/lib/python3.10/site-packages/flask/app.py", line 1796, in dispatch_request
    return self.ensure_sync(self.view_functions[rule.endpoint])(**view_args)
  File "/home/DriveKraft/drivekraft-app-backend/./app/util.py", line 21, in wrapper
    raise e
  File "/home/DriveKraft/drivekraft-app-backend/./app/util.py", line 15, in wrapper
    result = func(*args, **kwargs)
  File "/home/DriveKraft/drivekraft-app-backend/./app/util.py", line 43, in wrapper
    return func(*args, **kwargs)
  File "/home/DriveKraft/drivekraft-app-backend/./app/authenticate.py", line 16, in wrapper
    return func(*args, **kwargs)
  File "/home/DriveKraft/drivekraft-app-backend/./app/Routes/paymentRoutes.py", line 27, in placeOrder
    response = paymentService.placeOrder(request.json_data).__dict__
  File "/home/DriveKraft/drivekraft-app-backend/./app/Services/paymentService.py", line 63, in placeOrder
    response = placeRazorpayOrderResponse(transaction_id=transactional.orderId,user_credits=user.balance,
AttributeError: 'Transaction' object has no attribute 'orderId'
2024-02-03 07:23:54,541 - app - ERROR - Exception on /api/order/placed [POST]
Traceback (most recent call last):
  File "/home/DriveKraft/.local/lib/python3.10/site-packages/flask/app.py", line 2525, in wsgi_app
    response = self.full_dispatch_request()
  File "/home/DriveKraft/.local/lib/python3.10/site-packages/flask/app.py", line 1822, in full_dispatch_request
    rv = self.handle_user_exception(e)
  File "/home/DriveKraft/.local/lib/python3.10/site-packages/flask/app.py", line 1820, in full_dispatch_request
    rv = self.dispatch_request()
  File "/home/DriveKraft/.local/lib/python3.10/site-packages/flask/app.py", line 1796, in dispatch_request
    return self.ensure_sync(self.view_functions[rule.endpoint])(**view_args)
  File "/home/DriveKraft/drivekraft-app-backend/./app/util.py", line 21, in wrapper
    raise e
  File "/home/DriveKraft/drivekraft-app-backend/./app/util.py", line 15, in wrapper
    result = func(*args, **kwargs)
  File "/home/DriveKraft/drivekraft-app-backend/./app/util.py", line 43, in wrapper
    return func(*args, **kwargs)
  File "/home/DriveKraft/drivekraft-app-backend/./app/authenticate.py", line 16, in wrapper
    return func(*args, **kwargs)
  File "/home/DriveKraft/drivekraft-app-backend/./app/Routes/paymentRoutes.py", line 27, in placeOrder
    response = paymentService.placeOrder(request.json_data).__dict__
  File "/home/DriveKraft/drivekraft-app-backend/./app/Services/paymentService.py", line 43, in placeOrder
    transactional = paymentDao.getTransactionaByTransId(request['transaction_id'])
  File "/home/DriveKraft/drivekraft-app-backend/./app/Models/DAO/paymentDao.py", line 25, in getTransactionaByTransId
    transaction = session.query(Transaction).filter_by(transactionId=transactionId).one()
  File "/usr/local/lib/python3.10/site-packages/sqlalchemy/orm/query.py", line 2865, in one
    return self._iter().one()
  File "/usr/local/lib/python3.10/site-packages/sqlalchemy/engine/result.py", line 1417, in one
    return self._only_one_row(
  File "/usr/local/lib/python3.10/site-packages/sqlalchemy/engine/result.py", line 614, in _only_one_row
    raise exc.MultipleResultsFound(
sqlalchemy.exc.MultipleResultsFound: Multiple rows were found when exactly one was required
2024-02-03 07:29:01,337 - app - ERROR - Exception on /api/order/placed [POST]
Traceback (most recent call last):
  File "/home/DriveKraft/.local/lib/python3.10/site-packages/flask/app.py", line 2525, in wsgi_app
    response = self.full_dispatch_request()
  File "/home/DriveKraft/.local/lib/python3.10/site-packages/flask/app.py", line 1822, in full_dispatch_request
    rv = self.handle_user_exception(e)
  File "/home/DriveKraft/.local/lib/python3.10/site-packages/flask/app.py", line 1820, in full_dispatch_request
    rv = self.dispatch_request()
  File "/home/DriveKraft/.local/lib/python3.10/site-packages/flask/app.py", line 1796, in dispatch_request
    return self.ensure_sync(self.view_functions[rule.endpoint])(**view_args)
  File "/home/DriveKraft/drivekraft-app-backend/./app/util.py", line 21, in wrapper
    raise e
  File "/home/DriveKraft/drivekraft-app-backend/./app/util.py", line 15, in wrapper
    result = func(*args, **kwargs)
  File "/home/DriveKraft/drivekraft-app-backend/./app/util.py", line 43, in wrapper
    return func(*args, **kwargs)
  File "/home/DriveKraft/drivekraft-app-backend/./app/authenticate.py", line 16, in wrapper
    return func(*args, **kwargs)
  File "/home/DriveKraft/drivekraft-app-backend/./app/Routes/paymentRoutes.py", line 27, in placeOrder
    response = paymentService.placeOrder(request.json_data).__dict__
  File "/home/DriveKraft/drivekraft-app-backend/./app/Services/paymentService.py", line 51, in placeOrder
    paymentDao.updateTransaction(razorpayOrderRequest = request, cost=cost)
  File "/home/DriveKraft/drivekraft-app-backend/./app/Models/DAO/paymentDao.py", line 53, in updateTransaction
    transaction = session.query(Transaction).filter_by(transactionId=razorpayOrderRequest.transaction_id)
AttributeError: 'dict' object has no attribute 'transaction_id'
2024-02-03 08:32:29,700 - app - ERROR - Exception on /api/check/user/bal [GET]
Traceback (most recent call last):
  File "/usr/local/lib/python3.10/site-packages/sqlalchemy/engine/base.py", line 3280, in _wrap_pool_connect
    return fn()
  File "/usr/local/lib/python3.10/site-packages/sqlalchemy/pool/base.py", line 310, in connect
    return _ConnectionFairy._checkout(self)
  File "/usr/local/lib/python3.10/site-packages/sqlalchemy/pool/base.py", line 901, in _checkout
    result = pool._dialect.do_ping(fairy.dbapi_connection)
  File "/usr/local/lib/python3.10/site-packages/sqlalchemy/dialects/mysql/mysqldb.py", line 183, in do_ping
    dbapi_connection.ping(False)
MySQLdb._exceptions.OperationalError: (4031, 'The client was disconnected by the server because of inactivity. See wait_timeout and interactive_timeout for configuring this behavior.')

The above exception was the direct cause of the following exception:

Traceback (most recent call last):
  File "/home/DriveKraft/.local/lib/python3.10/site-packages/flask/app.py", line 2525, in wsgi_app
    response = self.full_dispatch_request()
  File "/home/DriveKraft/.local/lib/python3.10/site-packages/flask/app.py", line 1822, in full_dispatch_request
    rv = self.handle_user_exception(e)
  File "/home/DriveKraft/.local/lib/python3.10/site-packages/flask/app.py", line 1820, in full_dispatch_request
    rv = self.dispatch_request()
  File "/home/DriveKraft/.local/lib/python3.10/site-packages/flask/app.py", line 1796, in dispatch_request
    return self.ensure_sync(self.view_functions[rule.endpoint])(**view_args)
  File "/home/DriveKraft/drivekraft-app-backend/./app/util.py", line 43, in wrapper
    return func(*args, **kwargs)
  File "/home/DriveKraft/drivekraft-app-backend/./app/util.py", line 21, in wrapper
    raise e
  File "/home/DriveKraft/drivekraft-app-backend/./app/util.py", line 15, in wrapper
    result = func(*args, **kwargs)
  File "/home/DriveKraft/drivekraft-app-backend/./app/authenticate.py", line 14, in wrapper
    if verify_token(tokenValue):
  File "/home/DriveKraft/drivekraft-app-backend/./app/authenticate.py", line 25, in verify_token
    token = getToken(tokenValue=tokenValue)
  File "/home/DriveKraft/.local/lib/python3.10/site-packages/flask_caching/__init__.py", line 872, in decorated_function
    rv = self._call_fn(f, *args, **kwargs)
  File "/home/DriveKraft/.local/lib/python3.10/site-packages/flask_caching/__init__.py", line 175, in _call_fn
    return ensure_sync(fn)(*args, **kwargs)
  File "/home/DriveKraft/drivekraft-app-backend/./app/Models/DAO/tokenDAO.py", line 28, in getToken
    and_(Token.value == tokenValue, Token.created >= now - timedelta(hours=24))).one()
  File "/usr/local/lib/python3.10/site-packages/sqlalchemy/orm/query.py", line 2865, in one
    return self._iter().one()
  File "/usr/local/lib/python3.10/site-packages/sqlalchemy/orm/query.py", line 2903, in _iter
    result = self.session.execute(
  File "/usr/local/lib/python3.10/site-packages/sqlalchemy/orm/session.py", line 1695, in execute
    conn = self._connection_for_bind(bind)
  File "/usr/local/lib/python3.10/site-packages/sqlalchemy/orm/session.py", line 1536, in _connection_for_bind
    return self._transaction._connection_for_bind(
  File "/usr/local/lib/python3.10/site-packages/sqlalchemy/orm/session.py", line 747, in _connection_for_bind
    conn = bind.connect()
  File "/usr/local/lib/python3.10/site-packages/sqlalchemy/engine/base.py", line 3234, in connect
    return self._connection_cls(self, close_with_result=close_with_result)
  File "/usr/local/lib/python3.10/site-packages/sqlalchemy/engine/base.py", line 96, in __init__
    else engine.raw_connection()
  File "/usr/local/lib/python3.10/site-packages/sqlalchemy/engine/base.py", line 3313, in raw_connection
    return self._wrap_pool_connect(self.pool.connect, _connection)
  File "/usr/local/lib/python3.10/site-packages/sqlalchemy/engine/base.py", line 3283, in _wrap_pool_connect
    Connection._handle_dbapi_exception_noconnection(
  File "/usr/local/lib/python3.10/site-packages/sqlalchemy/engine/base.py", line 2117, in _handle_dbapi_exception_noconnection
    util.raise_(
  File "/usr/local/lib/python3.10/site-packages/sqlalchemy/util/compat.py", line 207, in raise_
    raise exception
  File "/usr/local/lib/python3.10/site-packages/sqlalchemy/engine/base.py", line 3280, in _wrap_pool_connect
    return fn()
  File "/usr/local/lib/python3.10/site-packages/sqlalchemy/pool/base.py", line 310, in connect
    return _ConnectionFairy._checkout(self)
  File "/usr/local/lib/python3.10/site-packages/sqlalchemy/pool/base.py", line 901, in _checkout
    result = pool._dialect.do_ping(fairy.dbapi_connection)
  File "/usr/local/lib/python3.10/site-packages/sqlalchemy/dialects/mysql/mysqldb.py", line 183, in do_ping
    dbapi_connection.ping(False)
sqlalchemy.exc.OperationalError: (MySQLdb._exceptions.OperationalError) (4031, 'The client was disconnected by the server because of inactivity. See wait_timeout and interactive_timeout for configuring this behavior.')
(Background on this error at: https://sqlalche.me/e/14/e3q8)
2024-02-03 12:09:22,556 - app - ERROR - Exception on /api/role [GET]
Traceback (most recent call last):
  File "/usr/local/lib/python3.10/site-packages/sqlalchemy/engine/base.py", line 3280, in _wrap_pool_connect
    return fn()
  File "/usr/local/lib/python3.10/site-packages/sqlalchemy/pool/base.py", line 310, in connect
    return _ConnectionFairy._checkout(self)
  File "/usr/local/lib/python3.10/site-packages/sqlalchemy/pool/base.py", line 901, in _checkout
    result = pool._dialect.do_ping(fairy.dbapi_connection)
  File "/usr/local/lib/python3.10/site-packages/sqlalchemy/dialects/mysql/mysqldb.py", line 183, in do_ping
    dbapi_connection.ping(False)
MySQLdb._exceptions.OperationalError: (4031, 'The client was disconnected by the server because of inactivity. See wait_timeout and interactive_timeout for configuring this behavior.')

The above exception was the direct cause of the following exception:

Traceback (most recent call last):
  File "/home/DriveKraft/.local/lib/python3.10/site-packages/flask/app.py", line 2525, in wsgi_app
    response = self.full_dispatch_request()
  File "/home/DriveKraft/.local/lib/python3.10/site-packages/flask/app.py", line 1822, in full_dispatch_request
    rv = self.handle_user_exception(e)
  File "/home/DriveKraft/.local/lib/python3.10/site-packages/flask/app.py", line 1820, in full_dispatch_request
    rv = self.dispatch_request()
  File "/home/DriveKraft/.local/lib/python3.10/site-packages/flask/app.py", line 1796, in dispatch_request
    return self.ensure_sync(self.view_functions[rule.endpoint])(**view_args)
  File "/home/DriveKraft/drivekraft-app-backend/./app/util.py", line 21, in wrapper
    raise e
  File "/home/DriveKraft/drivekraft-app-backend/./app/util.py", line 15, in wrapper
    result = func(*args, **kwargs)
  File "/home/DriveKraft/drivekraft-app-backend/./app/authenticate.py", line 14, in wrapper
    if verify_token(tokenValue):
  File "/home/DriveKraft/drivekraft-app-backend/./app/authenticate.py", line 25, in verify_token
    token = getToken(tokenValue=tokenValue)
  File "/home/DriveKraft/.local/lib/python3.10/site-packages/flask_caching/__init__.py", line 872, in decorated_function
    rv = self._call_fn(f, *args, **kwargs)
  File "/home/DriveKraft/.local/lib/python3.10/site-packages/flask_caching/__init__.py", line 175, in _call_fn
    return ensure_sync(fn)(*args, **kwargs)
  File "/home/DriveKraft/drivekraft-app-backend/./app/Models/DAO/tokenDAO.py", line 28, in getToken
    and_(Token.value == tokenValue, Token.created >= now - timedelta(hours=24))).one()
  File "/usr/local/lib/python3.10/site-packages/sqlalchemy/orm/query.py", line 2865, in one
    return self._iter().one()
  File "/usr/local/lib/python3.10/site-packages/sqlalchemy/orm/query.py", line 2903, in _iter
    result = self.session.execute(
  File "/usr/local/lib/python3.10/site-packages/sqlalchemy/orm/session.py", line 1695, in execute
    conn = self._connection_for_bind(bind)
  File "/usr/local/lib/python3.10/site-packages/sqlalchemy/orm/session.py", line 1536, in _connection_for_bind
    return self._transaction._connection_for_bind(
  File "/usr/local/lib/python3.10/site-packages/sqlalchemy/orm/session.py", line 747, in _connection_for_bind
    conn = bind.connect()
  File "/usr/local/lib/python3.10/site-packages/sqlalchemy/engine/base.py", line 3234, in connect
    return self._connection_cls(self, close_with_result=close_with_result)
  File "/usr/local/lib/python3.10/site-packages/sqlalchemy/engine/base.py", line 96, in __init__
    else engine.raw_connection()
  File "/usr/local/lib/python3.10/site-packages/sqlalchemy/engine/base.py", line 3313, in raw_connection
    return self._wrap_pool_connect(self.pool.connect, _connection)
  File "/usr/local/lib/python3.10/site-packages/sqlalchemy/engine/base.py", line 3283, in _wrap_pool_connect
    Connection._handle_dbapi_exception_noconnection(
  File "/usr/local/lib/python3.10/site-packages/sqlalchemy/engine/base.py", line 2117, in _handle_dbapi_exception_noconnection
    util.raise_(
  File "/usr/local/lib/python3.10/site-packages/sqlalchemy/util/compat.py", line 207, in raise_
    raise exception
  File "/usr/local/lib/python3.10/site-packages/sqlalchemy/engine/base.py", line 3280, in _wrap_pool_connect
    return fn()
  File "/usr/local/lib/python3.10/site-packages/sqlalchemy/pool/base.py", line 310, in connect
    return _ConnectionFairy._checkout(self)
  File "/usr/local/lib/python3.10/site-packages/sqlalchemy/pool/base.py", line 901, in _checkout
    result = pool._dialect.do_ping(fairy.dbapi_connection)
  File "/usr/local/lib/python3.10/site-packages/sqlalchemy/dialects/mysql/mysqldb.py", line 183, in do_ping
    dbapi_connection.ping(False)
sqlalchemy.exc.OperationalError: (MySQLdb._exceptions.OperationalError) (4031, 'The client was disconnected by the server because of inactivity. See wait_timeout and interactive_timeout for configuring this behavior.')
(Background on this error at: https://sqlalche.me/e/14/e3q8)
2024-02-03 12:09:24,318 - app - ERROR - Exception on /api/role [GET]
Traceback (most recent call last):
  File "/usr/local/lib/python3.10/site-packages/sqlalchemy/engine/base.py", line 3280, in _wrap_pool_connect
    return fn()
  File "/usr/local/lib/python3.10/site-packages/sqlalchemy/pool/base.py", line 310, in connect
    return _ConnectionFairy._checkout(self)
  File "/usr/local/lib/python3.10/site-packages/sqlalchemy/pool/base.py", line 901, in _checkout
    result = pool._dialect.do_ping(fairy.dbapi_connection)
  File "/usr/local/lib/python3.10/site-packages/sqlalchemy/dialects/mysql/mysqldb.py", line 183, in do_ping
    dbapi_connection.ping(False)
MySQLdb._exceptions.OperationalError: (4031, 'The client was disconnected by the server because of inactivity. See wait_timeout and interactive_timeout for configuring this behavior.')

The above exception was the direct cause of the following exception:

Traceback (most recent call last):
  File "/home/DriveKraft/.local/lib/python3.10/site-packages/flask/app.py", line 2525, in wsgi_app
    response = self.full_dispatch_request()
  File "/home/DriveKraft/.local/lib/python3.10/site-packages/flask/app.py", line 1822, in full_dispatch_request
    rv = self.handle_user_exception(e)
  File "/home/DriveKraft/.local/lib/python3.10/site-packages/flask/app.py", line 1820, in full_dispatch_request
    rv = self.dispatch_request()
  File "/home/DriveKraft/.local/lib/python3.10/site-packages/flask/app.py", line 1796, in dispatch_request
    return self.ensure_sync(self.view_functions[rule.endpoint])(**view_args)
  File "/home/DriveKraft/drivekraft-app-backend/./app/util.py", line 21, in wrapper
    raise e
  File "/home/DriveKraft/drivekraft-app-backend/./app/util.py", line 15, in wrapper
    result = func(*args, **kwargs)
  File "/home/DriveKraft/drivekraft-app-backend/./app/authenticate.py", line 14, in wrapper
    if verify_token(tokenValue):
  File "/home/DriveKraft/drivekraft-app-backend/./app/authenticate.py", line 25, in verify_token
    token = getToken(tokenValue=tokenValue)
  File "/home/DriveKraft/.local/lib/python3.10/site-packages/flask_caching/__init__.py", line 872, in decorated_function
    rv = self._call_fn(f, *args, **kwargs)
  File "/home/DriveKraft/.local/lib/python3.10/site-packages/flask_caching/__init__.py", line 175, in _call_fn
    return ensure_sync(fn)(*args, **kwargs)
  File "/home/DriveKraft/drivekraft-app-backend/./app/Models/DAO/tokenDAO.py", line 28, in getToken
    and_(Token.value == tokenValue, Token.created >= now - timedelta(hours=24))).one()
  File "/usr/local/lib/python3.10/site-packages/sqlalchemy/orm/query.py", line 2865, in one
    return self._iter().one()
  File "/usr/local/lib/python3.10/site-packages/sqlalchemy/orm/query.py", line 2903, in _iter
    result = self.session.execute(
  File "/usr/local/lib/python3.10/site-packages/sqlalchemy/orm/session.py", line 1695, in execute
    conn = self._connection_for_bind(bind)
  File "/usr/local/lib/python3.10/site-packages/sqlalchemy/orm/session.py", line 1536, in _connection_for_bind
    return self._transaction._connection_for_bind(
  File "/usr/local/lib/python3.10/site-packages/sqlalchemy/orm/session.py", line 747, in _connection_for_bind
    conn = bind.connect()
  File "/usr/local/lib/python3.10/site-packages/sqlalchemy/engine/base.py", line 3234, in connect
    return self._connection_cls(self, close_with_result=close_with_result)
  File "/usr/local/lib/python3.10/site-packages/sqlalchemy/engine/base.py", line 96, in __init__
    else engine.raw_connection()
  File "/usr/local/lib/python3.10/site-packages/sqlalchemy/engine/base.py", line 3313, in raw_connection
    return self._wrap_pool_connect(self.pool.connect, _connection)
  File "/usr/local/lib/python3.10/site-packages/sqlalchemy/engine/base.py", line 3283, in _wrap_pool_connect
    Connection._handle_dbapi_exception_noconnection(
  File "/usr/local/lib/python3.10/site-packages/sqlalchemy/engine/base.py", line 2117, in _handle_dbapi_exception_noconnection
    util.raise_(
  File "/usr/local/lib/python3.10/site-packages/sqlalchemy/util/compat.py", line 207, in raise_
    raise exception
  File "/usr/local/lib/python3.10/site-packages/sqlalchemy/engine/base.py", line 3280, in _wrap_pool_connect
    return fn()
  File "/usr/local/lib/python3.10/site-packages/sqlalchemy/pool/base.py", line 310, in connect
    return _ConnectionFairy._checkout(self)
  File "/usr/local/lib/python3.10/site-packages/sqlalchemy/pool/base.py", line 901, in _checkout
    result = pool._dialect.do_ping(fairy.dbapi_connection)
  File "/usr/local/lib/python3.10/site-packages/sqlalchemy/dialects/mysql/mysqldb.py", line 183, in do_ping
    dbapi_connection.ping(False)
sqlalchemy.exc.OperationalError: (MySQLdb._exceptions.OperationalError) (4031, 'The client was disconnected by the server because of inactivity. See wait_timeout and interactive_timeout for configuring this behavior.')
(Background on this error at: https://sqlalche.me/e/14/e3q8)
2024-02-03 12:36:50,353 - app - ERROR - Exception on /api/users/status/busy [POST]
Traceback (most recent call last):
  File "/usr/local/lib/python3.10/site-packages/sqlalchemy/engine/base.py", line 3280, in _wrap_pool_connect
    return fn()
  File "/usr/local/lib/python3.10/site-packages/sqlalchemy/pool/base.py", line 310, in connect
    return _ConnectionFairy._checkout(self)
  File "/usr/local/lib/python3.10/site-packages/sqlalchemy/pool/base.py", line 901, in _checkout
    result = pool._dialect.do_ping(fairy.dbapi_connection)
  File "/usr/local/lib/python3.10/site-packages/sqlalchemy/dialects/mysql/mysqldb.py", line 183, in do_ping
    dbapi_connection.ping(False)
MySQLdb._exceptions.OperationalError: (4031, 'The client was disconnected by the server because of inactivity. See wait_timeout and interactive_timeout for configuring this behavior.')

The above exception was the direct cause of the following exception:

Traceback (most recent call last):
  File "/home/DriveKraft/.local/lib/python3.10/site-packages/flask/app.py", line 2525, in wsgi_app
    response = self.full_dispatch_request()
  File "/home/DriveKraft/.local/lib/python3.10/site-packages/flask/app.py", line 1822, in full_dispatch_request
    rv = self.handle_user_exception(e)
  File "/home/DriveKraft/.local/lib/python3.10/site-packages/flask/app.py", line 1820, in full_dispatch_request
    rv = self.dispatch_request()
  File "/home/DriveKraft/.local/lib/python3.10/site-packages/flask/app.py", line 1796, in dispatch_request
    return self.ensure_sync(self.view_functions[rule.endpoint])(**view_args)
  File "/home/DriveKraft/drivekraft-app-backend/./app/util.py", line 21, in wrapper
    raise e
  File "/home/DriveKraft/drivekraft-app-backend/./app/util.py", line 15, in wrapper
    result = func(*args, **kwargs)
  File "/home/DriveKraft/drivekraft-app-backend/./app/authenticate.py", line 16, in wrapper
    return func(*args, **kwargs)
  File "/home/DriveKraft/drivekraft-app-backend/./app/util.py", line 43, in wrapper
    return func(*args, **kwargs)
  File "/home/DriveKraft/drivekraft-app-backend/./app/Routes/psychologistRoutes.py", line 30, in setPsychologistAsBusy
    response = psychologistService.setPsychologistBusy(requestData).__dict__
  File "/home/DriveKraft/drivekraft-app-backend/./app/Services/psychologistService.py", line 22, in setPsychologistBusy
    user = getUserDetails()
  File "/home/DriveKraft/drivekraft-app-backend/./app/Services/userService.py", line 100, in getUserDetails
    user = getUserByToken(g.tokenValue)
  File "/home/DriveKraft/drivekraft-app-backend/./app/Services/userService.py", line 96, in getUserByToken
    return userDao.getUserById(token.userId)
  File "/home/DriveKraft/drivekraft-app-backend/./app/Models/DAO/userDao.py", line 54, in getUserById
    user = session.query(User).filter_by(id=userId).one()
  File "/usr/local/lib/python3.10/site-packages/sqlalchemy/orm/query.py", line 2865, in one
    return self._iter().one()
  File "/usr/local/lib/python3.10/site-packages/sqlalchemy/orm/query.py", line 2903, in _iter
    result = self.session.execute(
  File "/usr/local/lib/python3.10/site-packages/sqlalchemy/orm/session.py", line 1695, in execute
    conn = self._connection_for_bind(bind)
  File "/usr/local/lib/python3.10/site-packages/sqlalchemy/orm/session.py", line 1536, in _connection_for_bind
    return self._transaction._connection_for_bind(
  File "/usr/local/lib/python3.10/site-packages/sqlalchemy/orm/session.py", line 747, in _connection_for_bind
    conn = bind.connect()
  File "/usr/local/lib/python3.10/site-packages/sqlalchemy/engine/base.py", line 3234, in connect
    return self._connection_cls(self, close_with_result=close_with_result)
  File "/usr/local/lib/python3.10/site-packages/sqlalchemy/engine/base.py", line 96, in __init__
    else engine.raw_connection()
  File "/usr/local/lib/python3.10/site-packages/sqlalchemy/engine/base.py", line 3313, in raw_connection
    return self._wrap_pool_connect(self.pool.connect, _connection)
  File "/usr/local/lib/python3.10/site-packages/sqlalchemy/engine/base.py", line 3283, in _wrap_pool_connect
    Connection._handle_dbapi_exception_noconnection(
  File "/usr/local/lib/python3.10/site-packages/sqlalchemy/engine/base.py", line 2117, in _handle_dbapi_exception_noconnection
    util.raise_(
  File "/usr/local/lib/python3.10/site-packages/sqlalchemy/util/compat.py", line 207, in raise_
    raise exception
  File "/usr/local/lib/python3.10/site-packages/sqlalchemy/engine/base.py", line 3280, in _wrap_pool_connect
    return fn()
  File "/usr/local/lib/python3.10/site-packages/sqlalchemy/pool/base.py", line 310, in connect
    return _ConnectionFairy._checkout(self)
  File "/usr/local/lib/python3.10/site-packages/sqlalchemy/pool/base.py", line 901, in _checkout
    result = pool._dialect.do_ping(fairy.dbapi_connection)
  File "/usr/local/lib/python3.10/site-packages/sqlalchemy/dialects/mysql/mysqldb.py", line 183, in do_ping
    dbapi_connection.ping(False)
sqlalchemy.exc.OperationalError: (MySQLdb._exceptions.OperationalError) (4031, 'The client was disconnected by the server because of inactivity. See wait_timeout and interactive_timeout for configuring this behavior.')
(Background on this error at: https://sqlalche.me/e/14/e3q8)
2024-02-03 12:36:50,788 - app - ERROR - Exception on /api/users/status/busy [POST]
Traceback (most recent call last):
  File "/usr/local/lib/python3.10/site-packages/sqlalchemy/engine/base.py", line 3280, in _wrap_pool_connect
    return fn()
  File "/usr/local/lib/python3.10/site-packages/sqlalchemy/pool/base.py", line 310, in connect
    return _ConnectionFairy._checkout(self)
  File "/usr/local/lib/python3.10/site-packages/sqlalchemy/pool/base.py", line 901, in _checkout
    result = pool._dialect.do_ping(fairy.dbapi_connection)
  File "/usr/local/lib/python3.10/site-packages/sqlalchemy/dialects/mysql/mysqldb.py", line 183, in do_ping
    dbapi_connection.ping(False)
MySQLdb._exceptions.OperationalError: (4031, 'The client was disconnected by the server because of inactivity. See wait_timeout and interactive_timeout for configuring this behavior.')

The above exception was the direct cause of the following exception:

Traceback (most recent call last):
  File "/home/DriveKraft/.local/lib/python3.10/site-packages/flask/app.py", line 2525, in wsgi_app
    response = self.full_dispatch_request()
  File "/home/DriveKraft/.local/lib/python3.10/site-packages/flask/app.py", line 1822, in full_dispatch_request
    rv = self.handle_user_exception(e)
  File "/home/DriveKraft/.local/lib/python3.10/site-packages/flask/app.py", line 1820, in full_dispatch_request
    rv = self.dispatch_request()
  File "/home/DriveKraft/.local/lib/python3.10/site-packages/flask/app.py", line 1796, in dispatch_request
    return self.ensure_sync(self.view_functions[rule.endpoint])(**view_args)
  File "/home/DriveKraft/drivekraft-app-backend/./app/util.py", line 21, in wrapper
    raise e
  File "/home/DriveKraft/drivekraft-app-backend/./app/util.py", line 15, in wrapper
    result = func(*args, **kwargs)
  File "/home/DriveKraft/drivekraft-app-backend/./app/authenticate.py", line 16, in wrapper
    return func(*args, **kwargs)
  File "/home/DriveKraft/drivekraft-app-backend/./app/util.py", line 43, in wrapper
    return func(*args, **kwargs)
  File "/home/DriveKraft/drivekraft-app-backend/./app/Routes/psychologistRoutes.py", line 30, in setPsychologistAsBusy
    response = psychologistService.setPsychologistBusy(requestData).__dict__
  File "/home/DriveKraft/drivekraft-app-backend/./app/Services/psychologistService.py", line 22, in setPsychologistBusy
    user = getUserDetails()
  File "/home/DriveKraft/drivekraft-app-backend/./app/Services/userService.py", line 100, in getUserDetails
    user = getUserByToken(g.tokenValue)
  File "/home/DriveKraft/drivekraft-app-backend/./app/Services/userService.py", line 96, in getUserByToken
    return userDao.getUserById(token.userId)
  File "/home/DriveKraft/drivekraft-app-backend/./app/Models/DAO/userDao.py", line 54, in getUserById
    user = session.query(User).filter_by(id=userId).one()
  File "/usr/local/lib/python3.10/site-packages/sqlalchemy/orm/query.py", line 2865, in one
    return self._iter().one()
  File "/usr/local/lib/python3.10/site-packages/sqlalchemy/orm/query.py", line 2903, in _iter
    result = self.session.execute(
  File "/usr/local/lib/python3.10/site-packages/sqlalchemy/orm/session.py", line 1695, in execute
    conn = self._connection_for_bind(bind)
  File "/usr/local/lib/python3.10/site-packages/sqlalchemy/orm/session.py", line 1536, in _connection_for_bind
    return self._transaction._connection_for_bind(
  File "/usr/local/lib/python3.10/site-packages/sqlalchemy/orm/session.py", line 747, in _connection_for_bind
    conn = bind.connect()
  File "/usr/local/lib/python3.10/site-packages/sqlalchemy/engine/base.py", line 3234, in connect
    return self._connection_cls(self, close_with_result=close_with_result)
  File "/usr/local/lib/python3.10/site-packages/sqlalchemy/engine/base.py", line 96, in __init__
    else engine.raw_connection()
  File "/usr/local/lib/python3.10/site-packages/sqlalchemy/engine/base.py", line 3313, in raw_connection
    return self._wrap_pool_connect(self.pool.connect, _connection)
  File "/usr/local/lib/python3.10/site-packages/sqlalchemy/engine/base.py", line 3283, in _wrap_pool_connect
    Connection._handle_dbapi_exception_noconnection(
  File "/usr/local/lib/python3.10/site-packages/sqlalchemy/engine/base.py", line 2117, in _handle_dbapi_exception_noconnection
    util.raise_(
  File "/usr/local/lib/python3.10/site-packages/sqlalchemy/util/compat.py", line 207, in raise_
    raise exception
  File "/usr/local/lib/python3.10/site-packages/sqlalchemy/engine/base.py", line 3280, in _wrap_pool_connect
    return fn()
  File "/usr/local/lib/python3.10/site-packages/sqlalchemy/pool/base.py", line 310, in connect
    return _ConnectionFairy._checkout(self)
  File "/usr/local/lib/python3.10/site-packages/sqlalchemy/pool/base.py", line 901, in _checkout
    result = pool._dialect.do_ping(fairy.dbapi_connection)
  File "/usr/local/lib/python3.10/site-packages/sqlalchemy/dialects/mysql/mysqldb.py", line 183, in do_ping
    dbapi_connection.ping(False)
sqlalchemy.exc.OperationalError: (MySQLdb._exceptions.OperationalError) (4031, 'The client was disconnected by the server because of inactivity. See wait_timeout and interactive_timeout for configuring this behavior.')
(Background on this error at: https://sqlalche.me/e/14/e3q8)
2024-02-03 15:57:31,759 - app - ERROR - Exception on /api/session/book/request/verify [POST]
Traceback (most recent call last):
  File "/home/DriveKraft/.local/lib/python3.10/site-packages/flask/app.py", line 2525, in wsgi_app
    response = self.full_dispatch_request()
  File "/home/DriveKraft/.local/lib/python3.10/site-packages/flask/app.py", line 1822, in full_dispatch_request
    rv = self.handle_user_exception(e)
  File "/home/DriveKraft/.local/lib/python3.10/site-packages/flask/app.py", line 1820, in full_dispatch_request
    rv = self.dispatch_request()
  File "/home/DriveKraft/.local/lib/python3.10/site-packages/flask/app.py", line 1796, in dispatch_request
    return self.ensure_sync(self.view_functions[rule.endpoint])(**view_args)
  File "/home/DriveKraft/drivekraft-app-backend/./app/util.py", line 21, in wrapper
    raise e
  File "/home/DriveKraft/drivekraft-app-backend/./app/util.py", line 15, in wrapper
    result = func(*args, **kwargs)
  File "/home/DriveKraft/drivekraft-app-backend/./app/util.py", line 43, in wrapper
    return func(*args, **kwargs)
  File "/home/DriveKraft/drivekraft-app-backend/./app/authenticate.py", line 16, in wrapper
    return func(*args, **kwargs)
  File "/home/DriveKraft/drivekraft-app-backend/./app/Routes/sessionRoutes.py", line 37, in verifySessionRequestFun
    response = sessionService.verifySessionRequest(sessionVerifyRequest).__dict__
  File "/home/DriveKraft/drivekraft-app-backend/./app/Services/sessionService.py", line 50, in verifySessionRequest
    verifiedSessionRequestId= sessionDao.findSessionRequestById(request.session_request_id)
  File "/home/DriveKraft/drivekraft-app-backend/./app/Models/DAO/sessionDao.py", line 42, in findSessionRequestById
    verifiedSessionRequest = session.query(SessionRequest).filter(and_(SessionRequest.id==sessionId,SessionRequest.sessionRequestStatusId==2)).one()
  File "/usr/local/lib/python3.10/site-packages/sqlalchemy/orm/query.py", line 2865, in one
    return self._iter().one()
  File "/usr/local/lib/python3.10/site-packages/sqlalchemy/engine/result.py", line 1417, in one
    return self._only_one_row(
  File "/usr/local/lib/python3.10/site-packages/sqlalchemy/engine/result.py", line 562, in _only_one_row
    raise exc.NoResultFound(
sqlalchemy.exc.NoResultFound: No row was found when one was required
2024-02-03 15:57:37,765 - app - ERROR - Exception on /api/session/book/request/verify [POST]
Traceback (most recent call last):
  File "/home/DriveKraft/.local/lib/python3.10/site-packages/flask/app.py", line 2525, in wsgi_app
    response = self.full_dispatch_request()
  File "/home/DriveKraft/.local/lib/python3.10/site-packages/flask/app.py", line 1822, in full_dispatch_request
    rv = self.handle_user_exception(e)
  File "/home/DriveKraft/.local/lib/python3.10/site-packages/flask/app.py", line 1820, in full_dispatch_request
    rv = self.dispatch_request()
  File "/home/DriveKraft/.local/lib/python3.10/site-packages/flask/app.py", line 1796, in dispatch_request
    return self.ensure_sync(self.view_functions[rule.endpoint])(**view_args)
  File "/home/DriveKraft/drivekraft-app-backend/./app/util.py", line 21, in wrapper
    raise e
  File "/home/DriveKraft/drivekraft-app-backend/./app/util.py", line 15, in wrapper
    result = func(*args, **kwargs)
  File "/home/DriveKraft/drivekraft-app-backend/./app/util.py", line 43, in wrapper
    return func(*args, **kwargs)
  File "/home/DriveKraft/drivekraft-app-backend/./app/authenticate.py", line 16, in wrapper
    return func(*args, **kwargs)
  File "/home/DriveKraft/drivekraft-app-backend/./app/Routes/sessionRoutes.py", line 37, in verifySessionRequestFun
    response = sessionService.verifySessionRequest(sessionVerifyRequest).__dict__
  File "/home/DriveKraft/drivekraft-app-backend/./app/Services/sessionService.py", line 50, in verifySessionRequest
    verifiedSessionRequestId= sessionDao.findSessionRequestById(request.session_request_id)
  File "/home/DriveKraft/drivekraft-app-backend/./app/Models/DAO/sessionDao.py", line 42, in findSessionRequestById
    verifiedSessionRequest = session.query(SessionRequest).filter(and_(SessionRequest.id==sessionId,SessionRequest.sessionRequestStatusId==2)).one()
  File "/usr/local/lib/python3.10/site-packages/sqlalchemy/orm/query.py", line 2865, in one
    return self._iter().one()
  File "/usr/local/lib/python3.10/site-packages/sqlalchemy/engine/result.py", line 1417, in one
    return self._only_one_row(
  File "/usr/local/lib/python3.10/site-packages/sqlalchemy/engine/result.py", line 562, in _only_one_row
    raise exc.NoResultFound(
sqlalchemy.exc.NoResultFound: No row was found when one was required
2024-02-03 15:59:42,918 - app - ERROR - Exception on /api/session/book/request/verify [POST]
Traceback (most recent call last):
  File "/home/DriveKraft/.local/lib/python3.10/site-packages/flask/app.py", line 2525, in wsgi_app
    response = self.full_dispatch_request()
  File "/home/DriveKraft/.local/lib/python3.10/site-packages/flask/app.py", line 1822, in full_dispatch_request
    rv = self.handle_user_exception(e)
  File "/home/DriveKraft/.local/lib/python3.10/site-packages/flask/app.py", line 1820, in full_dispatch_request
    rv = self.dispatch_request()
  File "/home/DriveKraft/.local/lib/python3.10/site-packages/flask/app.py", line 1796, in dispatch_request
    return self.ensure_sync(self.view_functions[rule.endpoint])(**view_args)
  File "/home/DriveKraft/drivekraft-app-backend/./app/util.py", line 21, in wrapper
    raise e
  File "/home/DriveKraft/drivekraft-app-backend/./app/util.py", line 15, in wrapper
    result = func(*args, **kwargs)
  File "/home/DriveKraft/drivekraft-app-backend/./app/util.py", line 43, in wrapper
    return func(*args, **kwargs)
  File "/home/DriveKraft/drivekraft-app-backend/./app/authenticate.py", line 16, in wrapper
    return func(*args, **kwargs)
  File "/home/DriveKraft/drivekraft-app-backend/./app/Routes/sessionRoutes.py", line 37, in verifySessionRequestFun
    response = sessionService.verifySessionRequest(sessionVerifyRequest).__dict__
  File "/home/DriveKraft/drivekraft-app-backend/./app/Services/sessionService.py", line 50, in verifySessionRequest
    verifiedSessionRequestId= sessionDao.findSessionRequestById(request.session_request_id)
  File "/home/DriveKraft/drivekraft-app-backend/./app/Models/DAO/sessionDao.py", line 42, in findSessionRequestById
    verifiedSessionRequest = session.query(SessionRequest).filter(and_(SessionRequest.id==sessionId,SessionRequest.sessionRequestStatusId==2)).one()
  File "/usr/local/lib/python3.10/site-packages/sqlalchemy/orm/query.py", line 2865, in one
    return self._iter().one()
  File "/usr/local/lib/python3.10/site-packages/sqlalchemy/engine/result.py", line 1417, in one
    return self._only_one_row(
  File "/usr/local/lib/python3.10/site-packages/sqlalchemy/engine/result.py", line 562, in _only_one_row
    raise exc.NoResultFound(
sqlalchemy.exc.NoResultFound: No row was found when one was required
2024-02-03 19:33:42,827 - app - ERROR - Exception on /api/users/status/busy [POST]
Traceback (most recent call last):
  File "/usr/local/lib/python3.10/site-packages/sqlalchemy/engine/base.py", line 3280, in _wrap_pool_connect
    return fn()
  File "/usr/local/lib/python3.10/site-packages/sqlalchemy/pool/base.py", line 310, in connect
    return _ConnectionFairy._checkout(self)
  File "/usr/local/lib/python3.10/site-packages/sqlalchemy/pool/base.py", line 901, in _checkout
    result = pool._dialect.do_ping(fairy.dbapi_connection)
  File "/usr/local/lib/python3.10/site-packages/sqlalchemy/dialects/mysql/mysqldb.py", line 183, in do_ping
    dbapi_connection.ping(False)
MySQLdb._exceptions.OperationalError: (4031, 'The client was disconnected by the server because of inactivity. See wait_timeout and interactive_timeout for configuring this behavior.')

The above exception was the direct cause of the following exception:

Traceback (most recent call last):
  File "/home/DriveKraft/.local/lib/python3.10/site-packages/flask/app.py", line 2525, in wsgi_app
    response = self.full_dispatch_request()
  File "/home/DriveKraft/.local/lib/python3.10/site-packages/flask/app.py", line 1822, in full_dispatch_request
    rv = self.handle_user_exception(e)
  File "/home/DriveKraft/.local/lib/python3.10/site-packages/flask/app.py", line 1820, in full_dispatch_request
    rv = self.dispatch_request()
  File "/home/DriveKraft/.local/lib/python3.10/site-packages/flask/app.py", line 1796, in dispatch_request
    return self.ensure_sync(self.view_functions[rule.endpoint])(**view_args)
  File "/home/DriveKraft/drivekraft-app-backend/./app/util.py", line 21, in wrapper
    raise e
  File "/home/DriveKraft/drivekraft-app-backend/./app/util.py", line 15, in wrapper
    result = func(*args, **kwargs)
  File "/home/DriveKraft/drivekraft-app-backend/./app/authenticate.py", line 14, in wrapper
    if verify_token(tokenValue):
  File "/home/DriveKraft/drivekraft-app-backend/./app/authenticate.py", line 25, in verify_token
    token = getToken(tokenValue=tokenValue)
  File "/home/DriveKraft/.local/lib/python3.10/site-packages/flask_caching/__init__.py", line 872, in decorated_function
    rv = self._call_fn(f, *args, **kwargs)
  File "/home/DriveKraft/.local/lib/python3.10/site-packages/flask_caching/__init__.py", line 175, in _call_fn
    return ensure_sync(fn)(*args, **kwargs)
  File "/home/DriveKraft/drivekraft-app-backend/./app/Models/DAO/tokenDAO.py", line 28, in getToken
    and_(Token.value == tokenValue, Token.created >= now - timedelta(hours=24))).one()
  File "/usr/local/lib/python3.10/site-packages/sqlalchemy/orm/query.py", line 2865, in one
    return self._iter().one()
  File "/usr/local/lib/python3.10/site-packages/sqlalchemy/orm/query.py", line 2903, in _iter
    result = self.session.execute(
  File "/usr/local/lib/python3.10/site-packages/sqlalchemy/orm/session.py", line 1695, in execute
    conn = self._connection_for_bind(bind)
  File "/usr/local/lib/python3.10/site-packages/sqlalchemy/orm/session.py", line 1536, in _connection_for_bind
    return self._transaction._connection_for_bind(
  File "/usr/local/lib/python3.10/site-packages/sqlalchemy/orm/session.py", line 747, in _connection_for_bind
    conn = bind.connect()
  File "/usr/local/lib/python3.10/site-packages/sqlalchemy/engine/base.py", line 3234, in connect
    return self._connection_cls(self, close_with_result=close_with_result)
  File "/usr/local/lib/python3.10/site-packages/sqlalchemy/engine/base.py", line 96, in __init__
    else engine.raw_connection()
  File "/usr/local/lib/python3.10/site-packages/sqlalchemy/engine/base.py", line 3313, in raw_connection
    return self._wrap_pool_connect(self.pool.connect, _connection)
  File "/usr/local/lib/python3.10/site-packages/sqlalchemy/engine/base.py", line 3283, in _wrap_pool_connect
    Connection._handle_dbapi_exception_noconnection(
  File "/usr/local/lib/python3.10/site-packages/sqlalchemy/engine/base.py", line 2117, in _handle_dbapi_exception_noconnection
    util.raise_(
  File "/usr/local/lib/python3.10/site-packages/sqlalchemy/util/compat.py", line 207, in raise_
    raise exception
  File "/usr/local/lib/python3.10/site-packages/sqlalchemy/engine/base.py", line 3280, in _wrap_pool_connect
    return fn()
  File "/usr/local/lib/python3.10/site-packages/sqlalchemy/pool/base.py", line 310, in connect
    return _ConnectionFairy._checkout(self)
  File "/usr/local/lib/python3.10/site-packages/sqlalchemy/pool/base.py", line 901, in _checkout
    result = pool._dialect.do_ping(fairy.dbapi_connection)
  File "/usr/local/lib/python3.10/site-packages/sqlalchemy/dialects/mysql/mysqldb.py", line 183, in do_ping
    dbapi_connection.ping(False)
sqlalchemy.exc.OperationalError: (MySQLdb._exceptions.OperationalError) (4031, 'The client was disconnected by the server because of inactivity. See wait_timeout and interactive_timeout for configuring this behavior.')
(Background on this error at: https://sqlalche.me/e/14/e3q8)
2024-02-03 20:24:41,101 - app - ERROR - Exception on /api/session/request/confirm [POST]
Traceback (most recent call last):
  File "/home/DriveKraft/.local/lib/python3.10/site-packages/flask/app.py", line 2525, in wsgi_app
    response = self.full_dispatch_request()
  File "/home/DriveKraft/.local/lib/python3.10/site-packages/flask/app.py", line 1822, in full_dispatch_request
    rv = self.handle_user_exception(e)
  File "/home/DriveKraft/.local/lib/python3.10/site-packages/flask/app.py", line 1820, in full_dispatch_request
    rv = self.dispatch_request()
  File "/home/DriveKraft/.local/lib/python3.10/site-packages/flask/app.py", line 1796, in dispatch_request
    return self.ensure_sync(self.view_functions[rule.endpoint])(**view_args)
  File "/home/DriveKraft/drivekraft-app-backend/./app/util.py", line 21, in wrapper
    raise e
  File "/home/DriveKraft/drivekraft-app-backend/./app/util.py", line 15, in wrapper
    result = func(*args, **kwargs)
  File "/home/DriveKraft/drivekraft-app-backend/./app/util.py", line 43, in wrapper
    return func(*args, **kwargs)
  File "/home/DriveKraft/drivekraft-app-backend/./app/authenticate.py", line 16, in wrapper
    return func(*args, **kwargs)
  File "/home/DriveKraft/drivekraft-app-backend/./app/Routes/sessionRoutes.py", line 56, in confirmSessionRequestFun
    response = sessionService.confirmSessionRequest(sessionConfirmRequest).__dict__
  File "/home/DriveKraft/drivekraft-app-backend/./app/Services/sessionService.py", line 91, in confirmSessionRequest
    if sessionDao.isExpiredOrCancelled(request.session_request_id):
  File "/home/DriveKraft/drivekraft-app-backend/./app/Models/DAO/sessionDao.py", line 81, in isExpiredOrCancelled
    sessionStatus = session.query(SessionRequest).filter(and_(SessionRequest.id==sessionRequestId,SessionRequest.sessionRequestStatusId==1,SessionRequest.expired >now)).one()
  File "/usr/local/lib/python3.10/site-packages/sqlalchemy/orm/query.py", line 2865, in one
    return self._iter().one()
  File "/usr/local/lib/python3.10/site-packages/sqlalchemy/engine/result.py", line 1417, in one
    return self._only_one_row(
  File "/usr/local/lib/python3.10/site-packages/sqlalchemy/engine/result.py", line 562, in _only_one_row
    raise exc.NoResultFound(
sqlalchemy.exc.NoResultFound: No row was found when one was required
2024-02-03 20:38:14,720 - app - ERROR - Exception on /api/psychologists [GET]
Traceback (most recent call last):
  File "/home/DriveKraft/.local/lib/python3.10/site-packages/flask/app.py", line 2525, in wsgi_app
    response = self.full_dispatch_request()
  File "/home/DriveKraft/.local/lib/python3.10/site-packages/flask/app.py", line 1822, in full_dispatch_request
    rv = self.handle_user_exception(e)
  File "/home/DriveKraft/.local/lib/python3.10/site-packages/flask/app.py", line 1820, in full_dispatch_request
    rv = self.dispatch_request()
  File "/home/DriveKraft/.local/lib/python3.10/site-packages/flask/app.py", line 1796, in dispatch_request
    return self.ensure_sync(self.view_functions[rule.endpoint])(**view_args)
  File "/home/DriveKraft/drivekraft-app-backend/./app/util.py", line 21, in wrapper
    raise e
  File "/home/DriveKraft/drivekraft-app-backend/./app/util.py", line 15, in wrapper
    result = func(*args, **kwargs)
  File "/home/DriveKraft/drivekraft-app-backend/./app/util.py", line 43, in wrapper
    return func(*args, **kwargs)
  File "/home/DriveKraft/drivekraft-app-backend/./app/Routes/psychologistRoutes.py", line 20, in getAllPsychologist
    response = psychologistService.getAllPsychologist()
  File "/home/DriveKraft/drivekraft-app-backend/./app/Services/psychologistService.py", line 17, in getAllPsychologist
    response = psychologistDao.getAllPsychologist()
  File "/home/DriveKraft/drivekraft-app-backend/./app/Models/DAO/psychologistDao.py", line 16, in getAllPsychologist
    result_list = [
  File "/home/DriveKraft/drivekraft-app-backend/./app/Models/DAO/psychologistDao.py", line 19, in <listcomp>
    'firebase_email': data.firebaseEmail,'firebase_password': data.firebase_password } # hack to fix data user issue
AttributeError: 'PsychologistData' object has no attribute 'firebase_password'
2024-02-03 21:21:10,158 - app - ERROR - Exception on /api/users/status/busy [POST]
Traceback (most recent call last):
  File "/usr/local/lib/python3.10/site-packages/sqlalchemy/engine/base.py", line 3280, in _wrap_pool_connect
    return fn()
  File "/usr/local/lib/python3.10/site-packages/sqlalchemy/pool/base.py", line 310, in connect
    return _ConnectionFairy._checkout(self)
  File "/usr/local/lib/python3.10/site-packages/sqlalchemy/pool/base.py", line 901, in _checkout
    result = pool._dialect.do_ping(fairy.dbapi_connection)
  File "/usr/local/lib/python3.10/site-packages/sqlalchemy/dialects/mysql/mysqldb.py", line 183, in do_ping
    dbapi_connection.ping(False)
MySQLdb._exceptions.OperationalError: (4031, 'The client was disconnected by the server because of inactivity. See wait_timeout and interactive_timeout for configuring this behavior.')

The above exception was the direct cause of the following exception:

Traceback (most recent call last):
  File "/home/DriveKraft/.local/lib/python3.10/site-packages/flask/app.py", line 2525, in wsgi_app
    response = self.full_dispatch_request()
  File "/home/DriveKraft/.local/lib/python3.10/site-packages/flask/app.py", line 1822, in full_dispatch_request
    rv = self.handle_user_exception(e)
  File "/home/DriveKraft/.local/lib/python3.10/site-packages/flask/app.py", line 1820, in full_dispatch_request
    rv = self.dispatch_request()
  File "/home/DriveKraft/.local/lib/python3.10/site-packages/flask/app.py", line 1796, in dispatch_request
    return self.ensure_sync(self.view_functions[rule.endpoint])(**view_args)
  File "/home/DriveKraft/drivekraft-app-backend/./app/util.py", line 21, in wrapper
    raise e
  File "/home/DriveKraft/drivekraft-app-backend/./app/util.py", line 15, in wrapper
    result = func(*args, **kwargs)
  File "/home/DriveKraft/drivekraft-app-backend/./app/authenticate.py", line 14, in wrapper
    if verify_token(tokenValue):
  File "/home/DriveKraft/drivekraft-app-backend/./app/authenticate.py", line 25, in verify_token
    token = getToken(tokenValue=tokenValue)
  File "/home/DriveKraft/.local/lib/python3.10/site-packages/flask_caching/__init__.py", line 872, in decorated_function
    rv = self._call_fn(f, *args, **kwargs)
  File "/home/DriveKraft/.local/lib/python3.10/site-packages/flask_caching/__init__.py", line 175, in _call_fn
    return ensure_sync(fn)(*args, **kwargs)
  File "/home/DriveKraft/drivekraft-app-backend/./app/Models/DAO/tokenDAO.py", line 28, in getToken
    and_(Token.value == tokenValue, Token.created >= now - timedelta(hours=24))).one()
  File "/usr/local/lib/python3.10/site-packages/sqlalchemy/orm/query.py", line 2865, in one
    return self._iter().one()
  File "/usr/local/lib/python3.10/site-packages/sqlalchemy/orm/query.py", line 2903, in _iter
    result = self.session.execute(
  File "/usr/local/lib/python3.10/site-packages/sqlalchemy/orm/session.py", line 1695, in execute
    conn = self._connection_for_bind(bind)
  File "/usr/local/lib/python3.10/site-packages/sqlalchemy/orm/session.py", line 1536, in _connection_for_bind
    return self._transaction._connection_for_bind(
  File "/usr/local/lib/python3.10/site-packages/sqlalchemy/orm/session.py", line 747, in _connection_for_bind
    conn = bind.connect()
  File "/usr/local/lib/python3.10/site-packages/sqlalchemy/engine/base.py", line 3234, in connect
    return self._connection_cls(self, close_with_result=close_with_result)
  File "/usr/local/lib/python3.10/site-packages/sqlalchemy/engine/base.py", line 96, in __init__
    else engine.raw_connection()
  File "/usr/local/lib/python3.10/site-packages/sqlalchemy/engine/base.py", line 3313, in raw_connection
    return self._wrap_pool_connect(self.pool.connect, _connection)
  File "/usr/local/lib/python3.10/site-packages/sqlalchemy/engine/base.py", line 3283, in _wrap_pool_connect
    Connection._handle_dbapi_exception_noconnection(
  File "/usr/local/lib/python3.10/site-packages/sqlalchemy/engine/base.py", line 2117, in _handle_dbapi_exception_noconnection
    util.raise_(
  File "/usr/local/lib/python3.10/site-packages/sqlalchemy/util/compat.py", line 207, in raise_
    raise exception
  File "/usr/local/lib/python3.10/site-packages/sqlalchemy/engine/base.py", line 3280, in _wrap_pool_connect
    return fn()
  File "/usr/local/lib/python3.10/site-packages/sqlalchemy/pool/base.py", line 310, in connect
    return _ConnectionFairy._checkout(self)
  File "/usr/local/lib/python3.10/site-packages/sqlalchemy/pool/base.py", line 901, in _checkout
    result = pool._dialect.do_ping(fairy.dbapi_connection)
  File "/usr/local/lib/python3.10/site-packages/sqlalchemy/dialects/mysql/mysqldb.py", line 183, in do_ping
    dbapi_connection.ping(False)
sqlalchemy.exc.OperationalError: (MySQLdb._exceptions.OperationalError) (4031, 'The client was disconnected by the server because of inactivity. See wait_timeout and interactive_timeout for configuring this behavior.')
(Background on this error at: https://sqlalche.me/e/14/e3q8)
2024-02-03 21:30:08,955 - app - ERROR - Exception on /api/role [GET]
Traceback (most recent call last):
  File "/usr/local/lib/python3.10/site-packages/sqlalchemy/engine/base.py", line 3280, in _wrap_pool_connect
    return fn()
  File "/usr/local/lib/python3.10/site-packages/sqlalchemy/pool/base.py", line 310, in connect
    return _ConnectionFairy._checkout(self)
  File "/usr/local/lib/python3.10/site-packages/sqlalchemy/pool/base.py", line 901, in _checkout
    result = pool._dialect.do_ping(fairy.dbapi_connection)
  File "/usr/local/lib/python3.10/site-packages/sqlalchemy/dialects/mysql/mysqldb.py", line 183, in do_ping
    dbapi_connection.ping(False)
MySQLdb._exceptions.OperationalError: (4031, 'The client was disconnected by the server because of inactivity. See wait_timeout and interactive_timeout for configuring this behavior.')

The above exception was the direct cause of the following exception:

Traceback (most recent call last):
  File "/home/DriveKraft/.local/lib/python3.10/site-packages/flask/app.py", line 2525, in wsgi_app
    response = self.full_dispatch_request()
  File "/home/DriveKraft/.local/lib/python3.10/site-packages/flask/app.py", line 1822, in full_dispatch_request
    rv = self.handle_user_exception(e)
  File "/home/DriveKraft/.local/lib/python3.10/site-packages/flask/app.py", line 1820, in full_dispatch_request
    rv = self.dispatch_request()
  File "/home/DriveKraft/.local/lib/python3.10/site-packages/flask/app.py", line 1796, in dispatch_request
    return self.ensure_sync(self.view_functions[rule.endpoint])(**view_args)
  File "/home/DriveKraft/drivekraft-app-backend/./app/util.py", line 21, in wrapper
    raise e
  File "/home/DriveKraft/drivekraft-app-backend/./app/util.py", line 15, in wrapper
    result = func(*args, **kwargs)
  File "/home/DriveKraft/drivekraft-app-backend/./app/authenticate.py", line 16, in wrapper
    return func(*args, **kwargs)
  File "/home/DriveKraft/drivekraft-app-backend/./app/util.py", line 43, in wrapper
    return func(*args, **kwargs)
  File "/home/DriveKraft/drivekraft-app-backend/./app/Routes/roleRoutes.py", line 15, in getRole
    response = roleService.getUserRole().to_dict()
  File "/home/DriveKraft/drivekraft-app-backend/./app/Services/roleService.py", line 9, in getUserRole
    user = userService.getUserDetails()
  File "/home/DriveKraft/drivekraft-app-backend/./app/Services/userService.py", line 100, in getUserDetails
    user = getUserByToken(g.tokenValue)
  File "/home/DriveKraft/drivekraft-app-backend/./app/Services/userService.py", line 96, in getUserByToken
    return userDao.getUserById(token.userId)
  File "/home/DriveKraft/drivekraft-app-backend/./app/Models/DAO/userDao.py", line 54, in getUserById
    user = session.query(User).filter_by(id=userId).one()
  File "/usr/local/lib/python3.10/site-packages/sqlalchemy/orm/query.py", line 2865, in one
    return self._iter().one()
  File "/usr/local/lib/python3.10/site-packages/sqlalchemy/orm/query.py", line 2903, in _iter
    result = self.session.execute(
  File "/usr/local/lib/python3.10/site-packages/sqlalchemy/orm/session.py", line 1695, in execute
    conn = self._connection_for_bind(bind)
  File "/usr/local/lib/python3.10/site-packages/sqlalchemy/orm/session.py", line 1536, in _connection_for_bind
    return self._transaction._connection_for_bind(
  File "/usr/local/lib/python3.10/site-packages/sqlalchemy/orm/session.py", line 747, in _connection_for_bind
    conn = bind.connect()
  File "/usr/local/lib/python3.10/site-packages/sqlalchemy/engine/base.py", line 3234, in connect
    return self._connection_cls(self, close_with_result=close_with_result)
  File "/usr/local/lib/python3.10/site-packages/sqlalchemy/engine/base.py", line 96, in __init__
    else engine.raw_connection()
  File "/usr/local/lib/python3.10/site-packages/sqlalchemy/engine/base.py", line 3313, in raw_connection
    return self._wrap_pool_connect(self.pool.connect, _connection)
  File "/usr/local/lib/python3.10/site-packages/sqlalchemy/engine/base.py", line 3283, in _wrap_pool_connect
    Connection._handle_dbapi_exception_noconnection(
  File "/usr/local/lib/python3.10/site-packages/sqlalchemy/engine/base.py", line 2117, in _handle_dbapi_exception_noconnection
    util.raise_(
  File "/usr/local/lib/python3.10/site-packages/sqlalchemy/util/compat.py", line 207, in raise_
    raise exception
  File "/usr/local/lib/python3.10/site-packages/sqlalchemy/engine/base.py", line 3280, in _wrap_pool_connect
    return fn()
  File "/usr/local/lib/python3.10/site-packages/sqlalchemy/pool/base.py", line 310, in connect
    return _ConnectionFairy._checkout(self)
  File "/usr/local/lib/python3.10/site-packages/sqlalchemy/pool/base.py", line 901, in _checkout
    result = pool._dialect.do_ping(fairy.dbapi_connection)
  File "/usr/local/lib/python3.10/site-packages/sqlalchemy/dialects/mysql/mysqldb.py", line 183, in do_ping
    dbapi_connection.ping(False)
sqlalchemy.exc.OperationalError: (MySQLdb._exceptions.OperationalError) (4031, 'The client was disconnected by the server because of inactivity. See wait_timeout and interactive_timeout for configuring this behavior.')
(Background on this error at: https://sqlalche.me/e/14/e3q8)
2024-02-03 21:30:29,589 - app - ERROR - Exception on /api/role [GET]
Traceback (most recent call last):
  File "/usr/local/lib/python3.10/site-packages/sqlalchemy/engine/base.py", line 3280, in _wrap_pool_connect
    return fn()
  File "/usr/local/lib/python3.10/site-packages/sqlalchemy/pool/base.py", line 310, in connect
    return _ConnectionFairy._checkout(self)
  File "/usr/local/lib/python3.10/site-packages/sqlalchemy/pool/base.py", line 901, in _checkout
    result = pool._dialect.do_ping(fairy.dbapi_connection)
  File "/usr/local/lib/python3.10/site-packages/sqlalchemy/dialects/mysql/mysqldb.py", line 183, in do_ping
    dbapi_connection.ping(False)
MySQLdb._exceptions.OperationalError: (4031, 'The client was disconnected by the server because of inactivity. See wait_timeout and interactive_timeout for configuring this behavior.')

The above exception was the direct cause of the following exception:

Traceback (most recent call last):
  File "/home/DriveKraft/.local/lib/python3.10/site-packages/flask/app.py", line 2525, in wsgi_app
    response = self.full_dispatch_request()
  File "/home/DriveKraft/.local/lib/python3.10/site-packages/flask/app.py", line 1822, in full_dispatch_request
    rv = self.handle_user_exception(e)
  File "/home/DriveKraft/.local/lib/python3.10/site-packages/flask/app.py", line 1820, in full_dispatch_request
    rv = self.dispatch_request()
  File "/home/DriveKraft/.local/lib/python3.10/site-packages/flask/app.py", line 1796, in dispatch_request
    return self.ensure_sync(self.view_functions[rule.endpoint])(**view_args)
  File "/home/DriveKraft/drivekraft-app-backend/./app/util.py", line 21, in wrapper
    raise e
  File "/home/DriveKraft/drivekraft-app-backend/./app/util.py", line 15, in wrapper
    result = func(*args, **kwargs)
  File "/home/DriveKraft/drivekraft-app-backend/./app/authenticate.py", line 16, in wrapper
    return func(*args, **kwargs)
  File "/home/DriveKraft/drivekraft-app-backend/./app/util.py", line 43, in wrapper
    return func(*args, **kwargs)
  File "/home/DriveKraft/drivekraft-app-backend/./app/Routes/roleRoutes.py", line 15, in getRole
    response = roleService.getUserRole().to_dict()
  File "/home/DriveKraft/drivekraft-app-backend/./app/Services/roleService.py", line 9, in getUserRole
    user = userService.getUserDetails()
  File "/home/DriveKraft/drivekraft-app-backend/./app/Services/userService.py", line 100, in getUserDetails
    user = getUserByToken(g.tokenValue)
  File "/home/DriveKraft/drivekraft-app-backend/./app/Services/userService.py", line 96, in getUserByToken
    return userDao.getUserById(token.userId)
  File "/home/DriveKraft/drivekraft-app-backend/./app/Models/DAO/userDao.py", line 54, in getUserById
    user = session.query(User).filter_by(id=userId).one()
  File "/usr/local/lib/python3.10/site-packages/sqlalchemy/orm/query.py", line 2865, in one
    return self._iter().one()
  File "/usr/local/lib/python3.10/site-packages/sqlalchemy/orm/query.py", line 2903, in _iter
    result = self.session.execute(
  File "/usr/local/lib/python3.10/site-packages/sqlalchemy/orm/session.py", line 1695, in execute
    conn = self._connection_for_bind(bind)
  File "/usr/local/lib/python3.10/site-packages/sqlalchemy/orm/session.py", line 1536, in _connection_for_bind
    return self._transaction._connection_for_bind(
  File "/usr/local/lib/python3.10/site-packages/sqlalchemy/orm/session.py", line 747, in _connection_for_bind
    conn = bind.connect()
  File "/usr/local/lib/python3.10/site-packages/sqlalchemy/engine/base.py", line 3234, in connect
    return self._connection_cls(self, close_with_result=close_with_result)
  File "/usr/local/lib/python3.10/site-packages/sqlalchemy/engine/base.py", line 96, in __init__
    else engine.raw_connection()
  File "/usr/local/lib/python3.10/site-packages/sqlalchemy/engine/base.py", line 3313, in raw_connection
    return self._wrap_pool_connect(self.pool.connect, _connection)
  File "/usr/local/lib/python3.10/site-packages/sqlalchemy/engine/base.py", line 3283, in _wrap_pool_connect
    Connection._handle_dbapi_exception_noconnection(
  File "/usr/local/lib/python3.10/site-packages/sqlalchemy/engine/base.py", line 2117, in _handle_dbapi_exception_noconnection
    util.raise_(
  File "/usr/local/lib/python3.10/site-packages/sqlalchemy/util/compat.py", line 207, in raise_
    raise exception
  File "/usr/local/lib/python3.10/site-packages/sqlalchemy/engine/base.py", line 3280, in _wrap_pool_connect
    return fn()
  File "/usr/local/lib/python3.10/site-packages/sqlalchemy/pool/base.py", line 310, in connect
    return _ConnectionFairy._checkout(self)
  File "/usr/local/lib/python3.10/site-packages/sqlalchemy/pool/base.py", line 901, in _checkout
    result = pool._dialect.do_ping(fairy.dbapi_connection)
  File "/usr/local/lib/python3.10/site-packages/sqlalchemy/dialects/mysql/mysqldb.py", line 183, in do_ping
    dbapi_connection.ping(False)
sqlalchemy.exc.OperationalError: (MySQLdb._exceptions.OperationalError) (4031, 'The client was disconnected by the server because of inactivity. See wait_timeout and interactive_timeout for configuring this behavior.')
(Background on this error at: https://sqlalche.me/e/14/e3q8)
2024-02-03 21:59:36,246 - app - ERROR - Exception on /api/login [POST]
Traceback (most recent call last):
  File "/usr/local/lib/python3.10/site-packages/sqlalchemy/engine/base.py", line 3280, in _wrap_pool_connect
    return fn()
  File "/usr/local/lib/python3.10/site-packages/sqlalchemy/pool/base.py", line 310, in connect
    return _ConnectionFairy._checkout(self)
  File "/usr/local/lib/python3.10/site-packages/sqlalchemy/pool/base.py", line 901, in _checkout
    result = pool._dialect.do_ping(fairy.dbapi_connection)
  File "/usr/local/lib/python3.10/site-packages/sqlalchemy/dialects/mysql/mysqldb.py", line 183, in do_ping
    dbapi_connection.ping(False)
MySQLdb._exceptions.OperationalError: (4031, 'The client was disconnected by the server because of inactivity. See wait_timeout and interactive_timeout for configuring this behavior.')

The above exception was the direct cause of the following exception:

Traceback (most recent call last):
  File "/home/DriveKraft/.local/lib/python3.10/site-packages/flask/app.py", line 2525, in wsgi_app
    response = self.full_dispatch_request()
  File "/home/DriveKraft/.local/lib/python3.10/site-packages/flask/app.py", line 1822, in full_dispatch_request
    rv = self.handle_user_exception(e)
  File "/home/DriveKraft/.local/lib/python3.10/site-packages/flask/app.py", line 1820, in full_dispatch_request
    rv = self.dispatch_request()
  File "/home/DriveKraft/.local/lib/python3.10/site-packages/flask/app.py", line 1796, in dispatch_request
    return self.ensure_sync(self.view_functions[rule.endpoint])(**view_args)
  File "/home/DriveKraft/drivekraft-app-backend/./app/util.py", line 21, in wrapper
    raise e
  File "/home/DriveKraft/drivekraft-app-backend/./app/util.py", line 15, in wrapper
    result = func(*args, **kwargs)
  File "/home/DriveKraft/drivekraft-app-backend/./app/util.py", line 43, in wrapper
    return func(*args, **kwargs)
  File "/home/DriveKraft/drivekraft-app-backend/./app/Routes/otpRoutes.py", line 29, in verifyOtp
    response = otpVerificationService.verifyOtp(otpVerifyRequest).__dict__
  File "/home/DriveKraft/drivekraft-app-backend/./app/Services/otpVerificationService.py", line 13, in verifyOtp
    user = userService.getUserByContact(request.mobile)
  File "/home/DriveKraft/drivekraft-app-backend/./app/Services/userService.py", line 84, in getUserByContact
    return userDao.getUserByContact(contactNumber)
  File "/home/DriveKraft/drivekraft-app-backend/./app/Models/DAO/userDao.py", line 45, in getUserByContact
    user = session.query(User).filter_by(contactNumber=contactNumber).one()
  File "/usr/local/lib/python3.10/site-packages/sqlalchemy/orm/query.py", line 2865, in one
    return self._iter().one()
  File "/usr/local/lib/python3.10/site-packages/sqlalchemy/orm/query.py", line 2903, in _iter
    result = self.session.execute(
  File "/usr/local/lib/python3.10/site-packages/sqlalchemy/orm/session.py", line 1695, in execute
    conn = self._connection_for_bind(bind)
  File "/usr/local/lib/python3.10/site-packages/sqlalchemy/orm/session.py", line 1536, in _connection_for_bind
    return self._transaction._connection_for_bind(
  File "/usr/local/lib/python3.10/site-packages/sqlalchemy/orm/session.py", line 747, in _connection_for_bind
    conn = bind.connect()
  File "/usr/local/lib/python3.10/site-packages/sqlalchemy/engine/base.py", line 3234, in connect
    return self._connection_cls(self, close_with_result=close_with_result)
  File "/usr/local/lib/python3.10/site-packages/sqlalchemy/engine/base.py", line 96, in __init__
    else engine.raw_connection()
  File "/usr/local/lib/python3.10/site-packages/sqlalchemy/engine/base.py", line 3313, in raw_connection
    return self._wrap_pool_connect(self.pool.connect, _connection)
  File "/usr/local/lib/python3.10/site-packages/sqlalchemy/engine/base.py", line 3283, in _wrap_pool_connect
    Connection._handle_dbapi_exception_noconnection(
  File "/usr/local/lib/python3.10/site-packages/sqlalchemy/engine/base.py", line 2117, in _handle_dbapi_exception_noconnection
    util.raise_(
  File "/usr/local/lib/python3.10/site-packages/sqlalchemy/util/compat.py", line 207, in raise_
    raise exception
  File "/usr/local/lib/python3.10/site-packages/sqlalchemy/engine/base.py", line 3280, in _wrap_pool_connect
    return fn()
  File "/usr/local/lib/python3.10/site-packages/sqlalchemy/pool/base.py", line 310, in connect
    return _ConnectionFairy._checkout(self)
  File "/usr/local/lib/python3.10/site-packages/sqlalchemy/pool/base.py", line 901, in _checkout
    result = pool._dialect.do_ping(fairy.dbapi_connection)
  File "/usr/local/lib/python3.10/site-packages/sqlalchemy/dialects/mysql/mysqldb.py", line 183, in do_ping
    dbapi_connection.ping(False)
sqlalchemy.exc.OperationalError: (MySQLdb._exceptions.OperationalError) (4031, 'The client was disconnected by the server because of inactivity. See wait_timeout and interactive_timeout for configuring this behavior.')
(Background on this error at: https://sqlalche.me/e/14/e3q8)
2024-02-03 22:06:00,413 - app - ERROR - Exception on /api/session/request/fetch [GET]
Traceback (most recent call last):
  File "/usr/local/lib/python3.10/site-packages/sqlalchemy/engine/base.py", line 3280, in _wrap_pool_connect
    return fn()
  File "/usr/local/lib/python3.10/site-packages/sqlalchemy/pool/base.py", line 310, in connect
    return _ConnectionFairy._checkout(self)
  File "/usr/local/lib/python3.10/site-packages/sqlalchemy/pool/base.py", line 901, in _checkout
    result = pool._dialect.do_ping(fairy.dbapi_connection)
  File "/usr/local/lib/python3.10/site-packages/sqlalchemy/dialects/mysql/mysqldb.py", line 183, in do_ping
    dbapi_connection.ping(False)
MySQLdb._exceptions.OperationalError: (4031, 'The client was disconnected by the server because of inactivity. See wait_timeout and interactive_timeout for configuring this behavior.')

The above exception was the direct cause of the following exception:

Traceback (most recent call last):
  File "/home/DriveKraft/.local/lib/python3.10/site-packages/flask/app.py", line 2525, in wsgi_app
    response = self.full_dispatch_request()
  File "/home/DriveKraft/.local/lib/python3.10/site-packages/flask/app.py", line 1822, in full_dispatch_request
    rv = self.handle_user_exception(e)
  File "/home/DriveKraft/.local/lib/python3.10/site-packages/flask/app.py", line 1820, in full_dispatch_request
    rv = self.dispatch_request()
  File "/home/DriveKraft/.local/lib/python3.10/site-packages/flask/app.py", line 1796, in dispatch_request
    return self.ensure_sync(self.view_functions[rule.endpoint])(**view_args)
  File "/home/DriveKraft/drivekraft-app-backend/./app/util.py", line 21, in wrapper
    raise e
  File "/home/DriveKraft/drivekraft-app-backend/./app/util.py", line 15, in wrapper
    result = func(*args, **kwargs)
  File "/home/DriveKraft/drivekraft-app-backend/./app/util.py", line 43, in wrapper
    return func(*args, **kwargs)
  File "/home/DriveKraft/drivekraft-app-backend/./app/authenticate.py", line 16, in wrapper
    return func(*args, **kwargs)
  File "/home/DriveKraft/drivekraft-app-backend/./app/Routes/sessionRoutes.py", line 47, in fetchSessionRequestFun
    response = sessionService.fetchSessionRequest().__dict__
  File "/home/DriveKraft/drivekraft-app-backend/./app/Services/sessionService.py", line 60, in fetchSessionRequest
    user = userService.getUserDetails()
  File "/home/DriveKraft/drivekraft-app-backend/./app/Services/userService.py", line 100, in getUserDetails
    user = getUserByToken(g.tokenValue)
  File "/home/DriveKraft/drivekraft-app-backend/./app/Services/userService.py", line 96, in getUserByToken
    return userDao.getUserById(token.userId)
  File "/home/DriveKraft/drivekraft-app-backend/./app/Models/DAO/userDao.py", line 54, in getUserById
    user = session.query(User).filter_by(id=userId).one()
  File "/usr/local/lib/python3.10/site-packages/sqlalchemy/orm/query.py", line 2865, in one
    return self._iter().one()
  File "/usr/local/lib/python3.10/site-packages/sqlalchemy/orm/query.py", line 2903, in _iter
    result = self.session.execute(
  File "/usr/local/lib/python3.10/site-packages/sqlalchemy/orm/session.py", line 1695, in execute
    conn = self._connection_for_bind(bind)
  File "/usr/local/lib/python3.10/site-packages/sqlalchemy/orm/session.py", line 1536, in _connection_for_bind
    return self._transaction._connection_for_bind(
  File "/usr/local/lib/python3.10/site-packages/sqlalchemy/orm/session.py", line 747, in _connection_for_bind
    conn = bind.connect()
  File "/usr/local/lib/python3.10/site-packages/sqlalchemy/engine/base.py", line 3234, in connect
    return self._connection_cls(self, close_with_result=close_with_result)
  File "/usr/local/lib/python3.10/site-packages/sqlalchemy/engine/base.py", line 96, in __init__
    else engine.raw_connection()
  File "/usr/local/lib/python3.10/site-packages/sqlalchemy/engine/base.py", line 3313, in raw_connection
    return self._wrap_pool_connect(self.pool.connect, _connection)
  File "/usr/local/lib/python3.10/site-packages/sqlalchemy/engine/base.py", line 3283, in _wrap_pool_connect
    Connection._handle_dbapi_exception_noconnection(
  File "/usr/local/lib/python3.10/site-packages/sqlalchemy/engine/base.py", line 2117, in _handle_dbapi_exception_noconnection
    util.raise_(
  File "/usr/local/lib/python3.10/site-packages/sqlalchemy/util/compat.py", line 207, in raise_
    raise exception
  File "/usr/local/lib/python3.10/site-packages/sqlalchemy/engine/base.py", line 3280, in _wrap_pool_connect
    return fn()
  File "/usr/local/lib/python3.10/site-packages/sqlalchemy/pool/base.py", line 310, in connect
    return _ConnectionFairy._checkout(self)
  File "/usr/local/lib/python3.10/site-packages/sqlalchemy/pool/base.py", line 901, in _checkout
    result = pool._dialect.do_ping(fairy.dbapi_connection)
  File "/usr/local/lib/python3.10/site-packages/sqlalchemy/dialects/mysql/mysqldb.py", line 183, in do_ping
    dbapi_connection.ping(False)
sqlalchemy.exc.OperationalError: (MySQLdb._exceptions.OperationalError) (4031, 'The client was disconnected by the server because of inactivity. See wait_timeout and interactive_timeout for configuring this behavior.')
(Background on this error at: https://sqlalche.me/e/14/e3q8)
2024-02-03 22:06:01,145 - app - ERROR - Exception on /api/users/status/busy [POST]
Traceback (most recent call last):
  File "/usr/local/lib/python3.10/site-packages/sqlalchemy/engine/base.py", line 3280, in _wrap_pool_connect
    return fn()
  File "/usr/local/lib/python3.10/site-packages/sqlalchemy/pool/base.py", line 310, in connect
    return _ConnectionFairy._checkout(self)
  File "/usr/local/lib/python3.10/site-packages/sqlalchemy/pool/base.py", line 901, in _checkout
    result = pool._dialect.do_ping(fairy.dbapi_connection)
  File "/usr/local/lib/python3.10/site-packages/sqlalchemy/dialects/mysql/mysqldb.py", line 183, in do_ping
    dbapi_connection.ping(False)
MySQLdb._exceptions.OperationalError: (4031, 'The client was disconnected by the server because of inactivity. See wait_timeout and interactive_timeout for configuring this behavior.')

The above exception was the direct cause of the following exception:

Traceback (most recent call last):
  File "/home/DriveKraft/.local/lib/python3.10/site-packages/flask/app.py", line 2525, in wsgi_app
    response = self.full_dispatch_request()
  File "/home/DriveKraft/.local/lib/python3.10/site-packages/flask/app.py", line 1822, in full_dispatch_request
    rv = self.handle_user_exception(e)
  File "/home/DriveKraft/.local/lib/python3.10/site-packages/flask/app.py", line 1820, in full_dispatch_request
    rv = self.dispatch_request()
  File "/home/DriveKraft/.local/lib/python3.10/site-packages/flask/app.py", line 1796, in dispatch_request
    return self.ensure_sync(self.view_functions[rule.endpoint])(**view_args)
  File "/home/DriveKraft/drivekraft-app-backend/./app/util.py", line 21, in wrapper
    raise e
  File "/home/DriveKraft/drivekraft-app-backend/./app/util.py", line 15, in wrapper
    result = func(*args, **kwargs)
  File "/home/DriveKraft/drivekraft-app-backend/./app/authenticate.py", line 16, in wrapper
    return func(*args, **kwargs)
  File "/home/DriveKraft/drivekraft-app-backend/./app/util.py", line 43, in wrapper
    return func(*args, **kwargs)
  File "/home/DriveKraft/drivekraft-app-backend/./app/Routes/psychologistRoutes.py", line 30, in setPsychologistAsBusy
    response = psychologistService.setPsychologistBusy(requestData).__dict__
  File "/home/DriveKraft/drivekraft-app-backend/./app/Services/psychologistService.py", line 22, in setPsychologistBusy
    user = getUserDetails()
  File "/home/DriveKraft/drivekraft-app-backend/./app/Services/userService.py", line 100, in getUserDetails
    user = getUserByToken(g.tokenValue)
  File "/home/DriveKraft/drivekraft-app-backend/./app/Services/userService.py", line 96, in getUserByToken
    return userDao.getUserById(token.userId)
  File "/home/DriveKraft/drivekraft-app-backend/./app/Models/DAO/userDao.py", line 54, in getUserById
    user = session.query(User).filter_by(id=userId).one()
  File "/usr/local/lib/python3.10/site-packages/sqlalchemy/orm/query.py", line 2865, in one
    return self._iter().one()
  File "/usr/local/lib/python3.10/site-packages/sqlalchemy/orm/query.py", line 2903, in _iter
    result = self.session.execute(
  File "/usr/local/lib/python3.10/site-packages/sqlalchemy/orm/session.py", line 1695, in execute
    conn = self._connection_for_bind(bind)
  File "/usr/local/lib/python3.10/site-packages/sqlalchemy/orm/session.py", line 1536, in _connection_for_bind
    return self._transaction._connection_for_bind(
  File "/usr/local/lib/python3.10/site-packages/sqlalchemy/orm/session.py", line 747, in _connection_for_bind
    conn = bind.connect()
  File "/usr/local/lib/python3.10/site-packages/sqlalchemy/engine/base.py", line 3234, in connect
    return self._connection_cls(self, close_with_result=close_with_result)
  File "/usr/local/lib/python3.10/site-packages/sqlalchemy/engine/base.py", line 96, in __init__
    else engine.raw_connection()
  File "/usr/local/lib/python3.10/site-packages/sqlalchemy/engine/base.py", line 3313, in raw_connection
    return self._wrap_pool_connect(self.pool.connect, _connection)
  File "/usr/local/lib/python3.10/site-packages/sqlalchemy/engine/base.py", line 3283, in _wrap_pool_connect
    Connection._handle_dbapi_exception_noconnection(
  File "/usr/local/lib/python3.10/site-packages/sqlalchemy/engine/base.py", line 2117, in _handle_dbapi_exception_noconnection
    util.raise_(
  File "/usr/local/lib/python3.10/site-packages/sqlalchemy/util/compat.py", line 207, in raise_
    raise exception
  File "/usr/local/lib/python3.10/site-packages/sqlalchemy/engine/base.py", line 3280, in _wrap_pool_connect
    return fn()
  File "/usr/local/lib/python3.10/site-packages/sqlalchemy/pool/base.py", line 310, in connect
    return _ConnectionFairy._checkout(self)
  File "/usr/local/lib/python3.10/site-packages/sqlalchemy/pool/base.py", line 901, in _checkout
    result = pool._dialect.do_ping(fairy.dbapi_connection)
  File "/usr/local/lib/python3.10/site-packages/sqlalchemy/dialects/mysql/mysqldb.py", line 183, in do_ping
    dbapi_connection.ping(False)
sqlalchemy.exc.OperationalError: (MySQLdb._exceptions.OperationalError) (4031, 'The client was disconnected by the server because of inactivity. See wait_timeout and interactive_timeout for configuring this behavior.')
(Background on this error at: https://sqlalche.me/e/14/e3q8)
2024-02-03 22:28:43,303 - app - ERROR - Exception on /api/session/request/fetch [GET]
Traceback (most recent call last):
  File "/usr/local/lib/python3.10/site-packages/sqlalchemy/engine/base.py", line 3280, in _wrap_pool_connect
    return fn()
  File "/usr/local/lib/python3.10/site-packages/sqlalchemy/pool/base.py", line 310, in connect
    return _ConnectionFairy._checkout(self)
  File "/usr/local/lib/python3.10/site-packages/sqlalchemy/pool/base.py", line 901, in _checkout
    result = pool._dialect.do_ping(fairy.dbapi_connection)
  File "/usr/local/lib/python3.10/site-packages/sqlalchemy/dialects/mysql/mysqldb.py", line 183, in do_ping
    dbapi_connection.ping(False)
MySQLdb._exceptions.OperationalError: (4031, 'The client was disconnected by the server because of inactivity. See wait_timeout and interactive_timeout for configuring this behavior.')

The above exception was the direct cause of the following exception:

Traceback (most recent call last):
  File "/home/DriveKraft/.local/lib/python3.10/site-packages/flask/app.py", line 2525, in wsgi_app
    response = self.full_dispatch_request()
  File "/home/DriveKraft/.local/lib/python3.10/site-packages/flask/app.py", line 1822, in full_dispatch_request
    rv = self.handle_user_exception(e)
  File "/home/DriveKraft/.local/lib/python3.10/site-packages/flask/app.py", line 1820, in full_dispatch_request
    rv = self.dispatch_request()
  File "/home/DriveKraft/.local/lib/python3.10/site-packages/flask/app.py", line 1796, in dispatch_request
    return self.ensure_sync(self.view_functions[rule.endpoint])(**view_args)
  File "/home/DriveKraft/drivekraft-app-backend/./app/util.py", line 21, in wrapper
    raise e
  File "/home/DriveKraft/drivekraft-app-backend/./app/util.py", line 15, in wrapper
    result = func(*args, **kwargs)
  File "/home/DriveKraft/drivekraft-app-backend/./app/util.py", line 43, in wrapper
    return func(*args, **kwargs)
  File "/home/DriveKraft/drivekraft-app-backend/./app/authenticate.py", line 14, in wrapper
    if verify_token(tokenValue):
  File "/home/DriveKraft/drivekraft-app-backend/./app/authenticate.py", line 25, in verify_token
    token = getToken(tokenValue=tokenValue)
  File "/home/DriveKraft/.local/lib/python3.10/site-packages/flask_caching/__init__.py", line 872, in decorated_function
    rv = self._call_fn(f, *args, **kwargs)
  File "/home/DriveKraft/.local/lib/python3.10/site-packages/flask_caching/__init__.py", line 175, in _call_fn
    return ensure_sync(fn)(*args, **kwargs)
  File "/home/DriveKraft/drivekraft-app-backend/./app/Models/DAO/tokenDAO.py", line 28, in getToken
    and_(Token.value == tokenValue, Token.created >= now - timedelta(hours=24))).one()
  File "/usr/local/lib/python3.10/site-packages/sqlalchemy/orm/query.py", line 2865, in one
    return self._iter().one()
  File "/usr/local/lib/python3.10/site-packages/sqlalchemy/orm/query.py", line 2903, in _iter
    result = self.session.execute(
  File "/usr/local/lib/python3.10/site-packages/sqlalchemy/orm/session.py", line 1695, in execute
    conn = self._connection_for_bind(bind)
  File "/usr/local/lib/python3.10/site-packages/sqlalchemy/orm/session.py", line 1536, in _connection_for_bind
    return self._transaction._connection_for_bind(
  File "/usr/local/lib/python3.10/site-packages/sqlalchemy/orm/session.py", line 747, in _connection_for_bind
    conn = bind.connect()
  File "/usr/local/lib/python3.10/site-packages/sqlalchemy/engine/base.py", line 3234, in connect
    return self._connection_cls(self, close_with_result=close_with_result)
  File "/usr/local/lib/python3.10/site-packages/sqlalchemy/engine/base.py", line 96, in __init__
    else engine.raw_connection()
  File "/usr/local/lib/python3.10/site-packages/sqlalchemy/engine/base.py", line 3313, in raw_connection
    return self._wrap_pool_connect(self.pool.connect, _connection)
  File "/usr/local/lib/python3.10/site-packages/sqlalchemy/engine/base.py", line 3283, in _wrap_pool_connect
    Connection._handle_dbapi_exception_noconnection(
  File "/usr/local/lib/python3.10/site-packages/sqlalchemy/engine/base.py", line 2117, in _handle_dbapi_exception_noconnection
    util.raise_(
  File "/usr/local/lib/python3.10/site-packages/sqlalchemy/util/compat.py", line 207, in raise_
    raise exception
  File "/usr/local/lib/python3.10/site-packages/sqlalchemy/engine/base.py", line 3280, in _wrap_pool_connect
    return fn()
  File "/usr/local/lib/python3.10/site-packages/sqlalchemy/pool/base.py", line 310, in connect
    return _ConnectionFairy._checkout(self)
  File "/usr/local/lib/python3.10/site-packages/sqlalchemy/pool/base.py", line 901, in _checkout
    result = pool._dialect.do_ping(fairy.dbapi_connection)
  File "/usr/local/lib/python3.10/site-packages/sqlalchemy/dialects/mysql/mysqldb.py", line 183, in do_ping
    dbapi_connection.ping(False)
sqlalchemy.exc.OperationalError: (MySQLdb._exceptions.OperationalError) (4031, 'The client was disconnected by the server because of inactivity. See wait_timeout and interactive_timeout for configuring this behavior.')
(Background on this error at: https://sqlalche.me/e/14/e3q8)
2024-02-03 22:28:44,740 - app - ERROR - Exception on /api/psychologists [GET]
Traceback (most recent call last):
  File "/usr/local/lib/python3.10/site-packages/sqlalchemy/engine/base.py", line 3280, in _wrap_pool_connect
    return fn()
  File "/usr/local/lib/python3.10/site-packages/sqlalchemy/pool/base.py", line 310, in connect
    return _ConnectionFairy._checkout(self)
  File "/usr/local/lib/python3.10/site-packages/sqlalchemy/pool/base.py", line 901, in _checkout
    result = pool._dialect.do_ping(fairy.dbapi_connection)
  File "/usr/local/lib/python3.10/site-packages/sqlalchemy/dialects/mysql/mysqldb.py", line 183, in do_ping
    dbapi_connection.ping(False)
MySQLdb._exceptions.OperationalError: (4031, 'The client was disconnected by the server because of inactivity. See wait_timeout and interactive_timeout for configuring this behavior.')

The above exception was the direct cause of the following exception:

Traceback (most recent call last):
  File "/home/DriveKraft/.local/lib/python3.10/site-packages/flask/app.py", line 2525, in wsgi_app
    response = self.full_dispatch_request()
  File "/home/DriveKraft/.local/lib/python3.10/site-packages/flask/app.py", line 1822, in full_dispatch_request
    rv = self.handle_user_exception(e)
  File "/home/DriveKraft/.local/lib/python3.10/site-packages/flask/app.py", line 1820, in full_dispatch_request
    rv = self.dispatch_request()
  File "/home/DriveKraft/.local/lib/python3.10/site-packages/flask/app.py", line 1796, in dispatch_request
    return self.ensure_sync(self.view_functions[rule.endpoint])(**view_args)
  File "/home/DriveKraft/drivekraft-app-backend/./app/util.py", line 21, in wrapper
    raise e
  File "/home/DriveKraft/drivekraft-app-backend/./app/util.py", line 15, in wrapper
    result = func(*args, **kwargs)
  File "/home/DriveKraft/drivekraft-app-backend/./app/util.py", line 43, in wrapper
    return func(*args, **kwargs)
  File "/home/DriveKraft/drivekraft-app-backend/./app/Routes/psychologistRoutes.py", line 20, in getAllPsychologist
    response = psychologistService.getAllPsychologist()
  File "/home/DriveKraft/drivekraft-app-backend/./app/Services/psychologistService.py", line 17, in getAllPsychologist
    response = psychologistDao.getAllPsychologist()
  File "/home/DriveKraft/drivekraft-app-backend/./app/Models/DAO/psychologistDao.py", line 14, in getAllPsychologist
    all()
  File "/usr/local/lib/python3.10/site-packages/sqlalchemy/orm/query.py", line 2768, in all
    return self._iter().all()
  File "/usr/local/lib/python3.10/site-packages/sqlalchemy/orm/query.py", line 2903, in _iter
    result = self.session.execute(
  File "/usr/local/lib/python3.10/site-packages/sqlalchemy/orm/session.py", line 1695, in execute
    conn = self._connection_for_bind(bind)
  File "/usr/local/lib/python3.10/site-packages/sqlalchemy/orm/session.py", line 1536, in _connection_for_bind
    return self._transaction._connection_for_bind(
  File "/usr/local/lib/python3.10/site-packages/sqlalchemy/orm/session.py", line 747, in _connection_for_bind
    conn = bind.connect()
  File "/usr/local/lib/python3.10/site-packages/sqlalchemy/engine/base.py", line 3234, in connect
    return self._connection_cls(self, close_with_result=close_with_result)
  File "/usr/local/lib/python3.10/site-packages/sqlalchemy/engine/base.py", line 96, in __init__
    else engine.raw_connection()
  File "/usr/local/lib/python3.10/site-packages/sqlalchemy/engine/base.py", line 3313, in raw_connection
    return self._wrap_pool_connect(self.pool.connect, _connection)
  File "/usr/local/lib/python3.10/site-packages/sqlalchemy/engine/base.py", line 3283, in _wrap_pool_connect
    Connection._handle_dbapi_exception_noconnection(
  File "/usr/local/lib/python3.10/site-packages/sqlalchemy/engine/base.py", line 2117, in _handle_dbapi_exception_noconnection
    util.raise_(
  File "/usr/local/lib/python3.10/site-packages/sqlalchemy/util/compat.py", line 207, in raise_
    raise exception
  File "/usr/local/lib/python3.10/site-packages/sqlalchemy/engine/base.py", line 3280, in _wrap_pool_connect
    return fn()
  File "/usr/local/lib/python3.10/site-packages/sqlalchemy/pool/base.py", line 310, in connect
    return _ConnectionFairy._checkout(self)
  File "/usr/local/lib/python3.10/site-packages/sqlalchemy/pool/base.py", line 901, in _checkout
    result = pool._dialect.do_ping(fairy.dbapi_connection)
  File "/usr/local/lib/python3.10/site-packages/sqlalchemy/dialects/mysql/mysqldb.py", line 183, in do_ping
    dbapi_connection.ping(False)
sqlalchemy.exc.OperationalError: (MySQLdb._exceptions.OperationalError) (4031, 'The client was disconnected by the server because of inactivity. See wait_timeout and interactive_timeout for configuring this behavior.')
(Background on this error at: https://sqlalche.me/e/14/e3q8)
2024-02-03 22:28:46,164 - app - ERROR - Exception on /api/user [GET]
Traceback (most recent call last):
  File "/usr/local/lib/python3.10/site-packages/sqlalchemy/engine/base.py", line 3280, in _wrap_pool_connect
    return fn()
  File "/usr/local/lib/python3.10/site-packages/sqlalchemy/pool/base.py", line 310, in connect
    return _ConnectionFairy._checkout(self)
  File "/usr/local/lib/python3.10/site-packages/sqlalchemy/pool/base.py", line 901, in _checkout
    result = pool._dialect.do_ping(fairy.dbapi_connection)
  File "/usr/local/lib/python3.10/site-packages/sqlalchemy/dialects/mysql/mysqldb.py", line 183, in do_ping
    dbapi_connection.ping(False)
MySQLdb._exceptions.OperationalError: (4031, 'The client was disconnected by the server because of inactivity. See wait_timeout and interactive_timeout for configuring this behavior.')

The above exception was the direct cause of the following exception:

Traceback (most recent call last):
  File "/home/DriveKraft/.local/lib/python3.10/site-packages/flask/app.py", line 2525, in wsgi_app
    response = self.full_dispatch_request()
  File "/home/DriveKraft/.local/lib/python3.10/site-packages/flask/app.py", line 1822, in full_dispatch_request
    rv = self.handle_user_exception(e)
  File "/home/DriveKraft/.local/lib/python3.10/site-packages/flask/app.py", line 1820, in full_dispatch_request
    rv = self.dispatch_request()
  File "/home/DriveKraft/.local/lib/python3.10/site-packages/flask/app.py", line 1796, in dispatch_request
    return self.ensure_sync(self.view_functions[rule.endpoint])(**view_args)
  File "/home/DriveKraft/drivekraft-app-backend/./app/util.py", line 43, in wrapper
    return func(*args, **kwargs)
  File "/home/DriveKraft/drivekraft-app-backend/./app/util.py", line 21, in wrapper
    raise e
  File "/home/DriveKraft/drivekraft-app-backend/./app/util.py", line 15, in wrapper
    result = func(*args, **kwargs)
  File "/home/DriveKraft/drivekraft-app-backend/./app/authenticate.py", line 14, in wrapper
    if verify_token(tokenValue):
  File "/home/DriveKraft/drivekraft-app-backend/./app/authenticate.py", line 25, in verify_token
    token = getToken(tokenValue=tokenValue)
  File "/home/DriveKraft/.local/lib/python3.10/site-packages/flask_caching/__init__.py", line 872, in decorated_function
    rv = self._call_fn(f, *args, **kwargs)
  File "/home/DriveKraft/.local/lib/python3.10/site-packages/flask_caching/__init__.py", line 175, in _call_fn
    return ensure_sync(fn)(*args, **kwargs)
  File "/home/DriveKraft/drivekraft-app-backend/./app/Models/DAO/tokenDAO.py", line 28, in getToken
    and_(Token.value == tokenValue, Token.created >= now - timedelta(hours=24))).one()
  File "/usr/local/lib/python3.10/site-packages/sqlalchemy/orm/query.py", line 2865, in one
    return self._iter().one()
  File "/usr/local/lib/python3.10/site-packages/sqlalchemy/orm/query.py", line 2903, in _iter
    result = self.session.execute(
  File "/usr/local/lib/python3.10/site-packages/sqlalchemy/orm/session.py", line 1695, in execute
    conn = self._connection_for_bind(bind)
  File "/usr/local/lib/python3.10/site-packages/sqlalchemy/orm/session.py", line 1536, in _connection_for_bind
    return self._transaction._connection_for_bind(
  File "/usr/local/lib/python3.10/site-packages/sqlalchemy/orm/session.py", line 747, in _connection_for_bind
    conn = bind.connect()
  File "/usr/local/lib/python3.10/site-packages/sqlalchemy/engine/base.py", line 3234, in connect
    return self._connection_cls(self, close_with_result=close_with_result)
  File "/usr/local/lib/python3.10/site-packages/sqlalchemy/engine/base.py", line 96, in __init__
    else engine.raw_connection()
  File "/usr/local/lib/python3.10/site-packages/sqlalchemy/engine/base.py", line 3313, in raw_connection
    return self._wrap_pool_connect(self.pool.connect, _connection)
  File "/usr/local/lib/python3.10/site-packages/sqlalchemy/engine/base.py", line 3283, in _wrap_pool_connect
    Connection._handle_dbapi_exception_noconnection(
  File "/usr/local/lib/python3.10/site-packages/sqlalchemy/engine/base.py", line 2117, in _handle_dbapi_exception_noconnection
    util.raise_(
  File "/usr/local/lib/python3.10/site-packages/sqlalchemy/util/compat.py", line 207, in raise_
    raise exception
  File "/usr/local/lib/python3.10/site-packages/sqlalchemy/engine/base.py", line 3280, in _wrap_pool_connect
    return fn()
  File "/usr/local/lib/python3.10/site-packages/sqlalchemy/pool/base.py", line 310, in connect
    return _ConnectionFairy._checkout(self)
  File "/usr/local/lib/python3.10/site-packages/sqlalchemy/pool/base.py", line 901, in _checkout
    result = pool._dialect.do_ping(fairy.dbapi_connection)
  File "/usr/local/lib/python3.10/site-packages/sqlalchemy/dialects/mysql/mysqldb.py", line 183, in do_ping
    dbapi_connection.ping(False)
sqlalchemy.exc.OperationalError: (MySQLdb._exceptions.OperationalError) (4031, 'The client was disconnected by the server because of inactivity. See wait_timeout and interactive_timeout for configuring this behavior.')
(Background on this error at: https://sqlalche.me/e/14/e3q8)
2024-02-03 22:43:05,591 - app - ERROR - Exception on /api/session/request/fetch [GET]
Traceback (most recent call last):
  File "/usr/local/lib/python3.10/site-packages/sqlalchemy/engine/base.py", line 3280, in _wrap_pool_connect
    return fn()
  File "/usr/local/lib/python3.10/site-packages/sqlalchemy/pool/base.py", line 310, in connect
    return _ConnectionFairy._checkout(self)
  File "/usr/local/lib/python3.10/site-packages/sqlalchemy/pool/base.py", line 901, in _checkout
    result = pool._dialect.do_ping(fairy.dbapi_connection)
  File "/usr/local/lib/python3.10/site-packages/sqlalchemy/dialects/mysql/mysqldb.py", line 183, in do_ping
    dbapi_connection.ping(False)
MySQLdb._exceptions.OperationalError: (4031, 'The client was disconnected by the server because of inactivity. See wait_timeout and interactive_timeout for configuring this behavior.')

The above exception was the direct cause of the following exception:

Traceback (most recent call last):
  File "/home/DriveKraft/.local/lib/python3.10/site-packages/flask/app.py", line 2525, in wsgi_app
    response = self.full_dispatch_request()
  File "/home/DriveKraft/.local/lib/python3.10/site-packages/flask/app.py", line 1822, in full_dispatch_request
    rv = self.handle_user_exception(e)
  File "/home/DriveKraft/.local/lib/python3.10/site-packages/flask/app.py", line 1820, in full_dispatch_request
    rv = self.dispatch_request()
  File "/home/DriveKraft/.local/lib/python3.10/site-packages/flask/app.py", line 1796, in dispatch_request
    return self.ensure_sync(self.view_functions[rule.endpoint])(**view_args)
  File "/home/DriveKraft/drivekraft-app-backend/./app/util.py", line 21, in wrapper
    raise e
  File "/home/DriveKraft/drivekraft-app-backend/./app/util.py", line 15, in wrapper
    result = func(*args, **kwargs)
  File "/home/DriveKraft/drivekraft-app-backend/./app/util.py", line 43, in wrapper
    return func(*args, **kwargs)
  File "/home/DriveKraft/drivekraft-app-backend/./app/authenticate.py", line 14, in wrapper
    if verify_token(tokenValue):
  File "/home/DriveKraft/drivekraft-app-backend/./app/authenticate.py", line 25, in verify_token
    token = getToken(tokenValue=tokenValue)
  File "/home/DriveKraft/.local/lib/python3.10/site-packages/flask_caching/__init__.py", line 872, in decorated_function
    rv = self._call_fn(f, *args, **kwargs)
  File "/home/DriveKraft/.local/lib/python3.10/site-packages/flask_caching/__init__.py", line 175, in _call_fn
    return ensure_sync(fn)(*args, **kwargs)
  File "/home/DriveKraft/drivekraft-app-backend/./app/Models/DAO/tokenDAO.py", line 28, in getToken
    and_(Token.value == tokenValue, Token.created >= now - timedelta(hours=24))).one()
  File "/usr/local/lib/python3.10/site-packages/sqlalchemy/orm/query.py", line 2865, in one
    return self._iter().one()
  File "/usr/local/lib/python3.10/site-packages/sqlalchemy/orm/query.py", line 2903, in _iter
    result = self.session.execute(
  File "/usr/local/lib/python3.10/site-packages/sqlalchemy/orm/session.py", line 1695, in execute
    conn = self._connection_for_bind(bind)
  File "/usr/local/lib/python3.10/site-packages/sqlalchemy/orm/session.py", line 1536, in _connection_for_bind
    return self._transaction._connection_for_bind(
  File "/usr/local/lib/python3.10/site-packages/sqlalchemy/orm/session.py", line 747, in _connection_for_bind
    conn = bind.connect()
  File "/usr/local/lib/python3.10/site-packages/sqlalchemy/engine/base.py", line 3234, in connect
    return self._connection_cls(self, close_with_result=close_with_result)
  File "/usr/local/lib/python3.10/site-packages/sqlalchemy/engine/base.py", line 96, in __init__
    else engine.raw_connection()
  File "/usr/local/lib/python3.10/site-packages/sqlalchemy/engine/base.py", line 3313, in raw_connection
    return self._wrap_pool_connect(self.pool.connect, _connection)
  File "/usr/local/lib/python3.10/site-packages/sqlalchemy/engine/base.py", line 3283, in _wrap_pool_connect
    Connection._handle_dbapi_exception_noconnection(
  File "/usr/local/lib/python3.10/site-packages/sqlalchemy/engine/base.py", line 2117, in _handle_dbapi_exception_noconnection
    util.raise_(
  File "/usr/local/lib/python3.10/site-packages/sqlalchemy/util/compat.py", line 207, in raise_
    raise exception
  File "/usr/local/lib/python3.10/site-packages/sqlalchemy/engine/base.py", line 3280, in _wrap_pool_connect
    return fn()
  File "/usr/local/lib/python3.10/site-packages/sqlalchemy/pool/base.py", line 310, in connect
    return _ConnectionFairy._checkout(self)
  File "/usr/local/lib/python3.10/site-packages/sqlalchemy/pool/base.py", line 901, in _checkout
    result = pool._dialect.do_ping(fairy.dbapi_connection)
  File "/usr/local/lib/python3.10/site-packages/sqlalchemy/dialects/mysql/mysqldb.py", line 183, in do_ping
    dbapi_connection.ping(False)
sqlalchemy.exc.OperationalError: (MySQLdb._exceptions.OperationalError) (4031, 'The client was disconnected by the server because of inactivity. See wait_timeout and interactive_timeout for configuring this behavior.')
(Background on this error at: https://sqlalche.me/e/14/e3q8)
2024-02-03 22:43:34,180 - app - ERROR - Exception on /api/session/request/fetch [GET]
Traceback (most recent call last):
  File "/usr/local/lib/python3.10/site-packages/sqlalchemy/engine/base.py", line 3280, in _wrap_pool_connect
    return fn()
  File "/usr/local/lib/python3.10/site-packages/sqlalchemy/pool/base.py", line 310, in connect
    return _ConnectionFairy._checkout(self)
  File "/usr/local/lib/python3.10/site-packages/sqlalchemy/pool/base.py", line 901, in _checkout
    result = pool._dialect.do_ping(fairy.dbapi_connection)
  File "/usr/local/lib/python3.10/site-packages/sqlalchemy/dialects/mysql/mysqldb.py", line 183, in do_ping
    dbapi_connection.ping(False)
MySQLdb._exceptions.OperationalError: (4031, 'The client was disconnected by the server because of inactivity. See wait_timeout and interactive_timeout for configuring this behavior.')

The above exception was the direct cause of the following exception:

Traceback (most recent call last):
  File "/home/DriveKraft/.local/lib/python3.10/site-packages/flask/app.py", line 2525, in wsgi_app
    response = self.full_dispatch_request()
  File "/home/DriveKraft/.local/lib/python3.10/site-packages/flask/app.py", line 1822, in full_dispatch_request
    rv = self.handle_user_exception(e)
  File "/home/DriveKraft/.local/lib/python3.10/site-packages/flask/app.py", line 1820, in full_dispatch_request
    rv = self.dispatch_request()
  File "/home/DriveKraft/.local/lib/python3.10/site-packages/flask/app.py", line 1796, in dispatch_request
    return self.ensure_sync(self.view_functions[rule.endpoint])(**view_args)
  File "/home/DriveKraft/drivekraft-app-backend/./app/util.py", line 21, in wrapper
    raise e
  File "/home/DriveKraft/drivekraft-app-backend/./app/util.py", line 15, in wrapper
    result = func(*args, **kwargs)
  File "/home/DriveKraft/drivekraft-app-backend/./app/util.py", line 43, in wrapper
    return func(*args, **kwargs)
  File "/home/DriveKraft/drivekraft-app-backend/./app/authenticate.py", line 16, in wrapper
    return func(*args, **kwargs)
  File "/home/DriveKraft/drivekraft-app-backend/./app/Routes/sessionRoutes.py", line 47, in fetchSessionRequestFun
    response = sessionService.fetchSessionRequest().__dict__
  File "/home/DriveKraft/drivekraft-app-backend/./app/Services/sessionService.py", line 60, in fetchSessionRequest
    user = userService.getUserDetails()
  File "/home/DriveKraft/drivekraft-app-backend/./app/Services/userService.py", line 100, in getUserDetails
    user = getUserByToken(g.tokenValue)
  File "/home/DriveKraft/drivekraft-app-backend/./app/Services/userService.py", line 96, in getUserByToken
    return userDao.getUserById(token.userId)
  File "/home/DriveKraft/drivekraft-app-backend/./app/Models/DAO/userDao.py", line 54, in getUserById
    user = session.query(User).filter_by(id=userId).one()
  File "/usr/local/lib/python3.10/site-packages/sqlalchemy/orm/query.py", line 2865, in one
    return self._iter().one()
  File "/usr/local/lib/python3.10/site-packages/sqlalchemy/orm/query.py", line 2903, in _iter
    result = self.session.execute(
  File "/usr/local/lib/python3.10/site-packages/sqlalchemy/orm/session.py", line 1695, in execute
    conn = self._connection_for_bind(bind)
  File "/usr/local/lib/python3.10/site-packages/sqlalchemy/orm/session.py", line 1536, in _connection_for_bind
    return self._transaction._connection_for_bind(
  File "/usr/local/lib/python3.10/site-packages/sqlalchemy/orm/session.py", line 747, in _connection_for_bind
    conn = bind.connect()
  File "/usr/local/lib/python3.10/site-packages/sqlalchemy/engine/base.py", line 3234, in connect
    return self._connection_cls(self, close_with_result=close_with_result)
  File "/usr/local/lib/python3.10/site-packages/sqlalchemy/engine/base.py", line 96, in __init__
    else engine.raw_connection()
  File "/usr/local/lib/python3.10/site-packages/sqlalchemy/engine/base.py", line 3313, in raw_connection
    return self._wrap_pool_connect(self.pool.connect, _connection)
  File "/usr/local/lib/python3.10/site-packages/sqlalchemy/engine/base.py", line 3283, in _wrap_pool_connect
    Connection._handle_dbapi_exception_noconnection(
  File "/usr/local/lib/python3.10/site-packages/sqlalchemy/engine/base.py", line 2117, in _handle_dbapi_exception_noconnection
    util.raise_(
  File "/usr/local/lib/python3.10/site-packages/sqlalchemy/util/compat.py", line 207, in raise_
    raise exception
  File "/usr/local/lib/python3.10/site-packages/sqlalchemy/engine/base.py", line 3280, in _wrap_pool_connect
    return fn()
  File "/usr/local/lib/python3.10/site-packages/sqlalchemy/pool/base.py", line 310, in connect
    return _ConnectionFairy._checkout(self)
  File "/usr/local/lib/python3.10/site-packages/sqlalchemy/pool/base.py", line 901, in _checkout
    result = pool._dialect.do_ping(fairy.dbapi_connection)
  File "/usr/local/lib/python3.10/site-packages/sqlalchemy/dialects/mysql/mysqldb.py", line 183, in do_ping
    dbapi_connection.ping(False)
sqlalchemy.exc.OperationalError: (MySQLdb._exceptions.OperationalError) (4031, 'The client was disconnected by the server because of inactivity. See wait_timeout and interactive_timeout for configuring this behavior.')
(Background on this error at: https://sqlalche.me/e/14/e3q8)
